Workbook

Sheet Lookup
A1: Pokemon Lookup (Singles / Doubles) | AB1: Garchomp
A2: Enter name → | B2: Garchomp | AB2: Mimikyu
AB3: Archaludon
A4: Field | B4: Singles | I4: Doubles | AB4: Metagross
A5: Rank | B5: =IFERROR(INDEX('Singles'!A:A,MATCH($B$2,'Singles'!$B:$B,0)),"—") | I5: =IFERROR(INDEX('Doubles'!A:A,MATCH($B$2,'Doubles'!$B:$B,0)),"—") | AB5: Hippowdon
A6: Moves | B6: =IFERROR(INDEX('Singles'!J:J,MATCH($B$2,'Singles'!$B:$B,0)),"—") | E6: =IFERROR(INDEX('Singles'!K:K,MATCH($B$2,'Singles'!$B:$B,0)),"—") | I6: =IFERROR(INDEX('Doubles'!J:J,MATCH($B$2,'Doubles'!$B:$B,0)),"—") | L6: =IFERROR(INDEX('Doubles'!K:K,MATCH($B$2,'Doubles'!$B:$B,0)),"—") | AB6: Primarina
A7: Items | B7: =IFERROR(INDEX('Singles'!L:L,MATCH($B$2,'Singles'!$B:$B,0)),"—") | E7: =IFERROR(INDEX('Singles'!M:M,MATCH($B$2,'Singles'!$B:$B,0)),"—") | I7: =IFERROR(INDEX('Doubles'!L:L,MATCH($B$2,'Doubles'!$B:$B,0)),"—") | L7: =IFERROR(INDEX('Doubles'!M:M,MATCH($B$2,'Doubles'!$B:$B,0)),"—") | AB7: Meowscarada
A8: Abilities | B8: =IFERROR(INDEX('Singles'!E:E,MATCH($B$2,'Singles'!$B:$B,0)),"—") | I8: =IFERROR(INDEX('Doubles'!E:E,MATCH($B$2,'Doubles'!$B:$B,0)),"—") | AB8: Gyarados
A9: Natures | B9: =IFERROR(INDEX('Singles'!N:N,MATCH($B$2,'Singles'!$B:$B,0)),"—") | E9: =IFERROR(INDEX('Singles'!O:O,MATCH($B$2,'Singles'!$B:$B,0)),"—") | I9: =IFERROR(INDEX('Doubles'!N:N,MATCH($B$2,'Doubles'!$B:$B,0)),"—") | L9: =IFERROR(INDEX('Doubles'!O:O,MATCH($B$2,'Doubles'!$B:$B,0)),"—") | AB9: Blaziken
A10: Spreads | B10: =IFERROR(INDEX('Singles'!P:P,MATCH($B$2,'Singles'!$B:$B,0)),"—") | E10: =IFERROR(INDEX('Singles'!Q:Q,MATCH($B$2,'Singles'!$B:$B,0)),"—") | I10: =IFERROR(INDEX('Doubles'!P:P,MATCH($B$2,'Doubles'!$B:$B,0)),"—") | L10: =IFERROR(INDEX('Doubles'!Q:Q,MATCH($B$2,'Doubles'!$B:$B,0)),"—") | AB10: Charizard
A11: Partners | B11: =IFERROR(INDEX('Singles'!R:R,MATCH($B$2,'Singles'!$B:$B,0)),"—") | E11: =IFERROR(INDEX('Singles'!S:S,MATCH($B$2,'Singles'!$B:$B,0)),"—") | I11: =IFERROR(INDEX('Doubles'!R:R,MATCH($B$2,'Doubles'!$B:$B,0)),"—") | L11: =IFERROR(INDEX('Doubles'!S:S,MATCH($B$2,'Doubles'!$B:$B,0)),"—") | AB11: Delphox
A12: This update | B12: =IFERROR(INDEX('Singles'!I:I,MATCH($B$2,'Singles'!$B:$B,0)),"—") | I12: =IFERROR(INDEX('Doubles'!I:I,MATCH($B$2,'Doubles'!$B:$B,0)),"—") | AB12: Greninja
AB13: Hydreigon
AB14: Corviknight
AB15: Ninetales-Alola
AB16: Dragonite
AB17: Gengar
AB18: Glimmora
AB19: Basculegion
AB20: Raichu
AB21: Samurott-Hisui
AB22: Rotom-Wash
AB23: Scizor
AB24: Skeledirge
... AB235: Watchog

Sheet Singles
A1: Rank | B1: Name | C1: Moves | D1: Items | E1: Abilities | F1: Natures | G1: Partners | H1: Spreads | I1: This update | J1: Moves·1 | K1: Moves·2 | L1: Items·1 | M1: Items·2 | N1: Natures·1 | O1: Natures·2 | P1: Spreads·1 | Q1: Spreads·2 | R1: Partners·1 | S1: Partners·2
A2: 1 | B2: Garchomp | C2: 1. Earthquake (99.6%) 2. Stealth Rock (48.4%) 3. Scale Shot (39.6%) 4. Outrage (34.9%) 5. Rock Tomb (29.4%) 6. Swords Dance (28.7%) 7. Dragon Tail (28.6%) 8. Spikes (19.1%) 9. Rock Slide (17.3%) 10. Poison Jab (13.1%) | D2: 1. Focus Sash (36.9%) 2. Sitrus Berry (24%) 3. Choice Scarf (22.6%) 4. Lum Berry (9.6%) 5. Life Orb (2.9%) 6. Garchompite (0.7%) 7. Leftovers (0.7%) 8. Haban Berry (0.6%) 9. Yache Berry (0.4%) 10. Roseli Berry (0.2%) | E2: 1. Rough Skin (99.5%) 2. Sand Veil (0.5%) | F2: 1. Jolly +S -C (48.3%) 2. Adamant +A -C (29.3%) 3. Impish +B -C (19.4%) 4. Careful +D -C (1.6%) 5. Naive +S -D (0.4%) 6. Bold +B -A (0.3%) 7. Naughty +A -D (0.2%) 8. Hasty +S -B (0.2%) 9. Modest +C -A (0.1%) 10. Brave +A -S (0.1%) | G2: 1. Mimikyu 2. Primarina 3. Metagross 4. Archaludon 5. Meowscarada 6. Gyarados 7. Charizard 8. Delphox 9. Blaziken 10. Greninja | H2: 1. H2/A32/B0/C0/D0/S32 (47.9%) 2. H0/A32/B2/C0/D0/S32 (9.7%) 3. H0/A32/B1/C0/D1/S32 (4.7%) 4. H32/A0/B32/C0/D0/S2 (4%) 5. H32/A0/B32/C0/D2/S0 (3.3%) 6. H0/A32/B0/C0/D2/S32 (2.7%) 7. H32/A0/B30/C0/D0/S4 (2%) 8. H0/A30/B4/C0/D0/S32 (1.4%) 9. H32/A0/B15/C0/D3/S16 (1.3%) 10. H32/A2/B32/C0/D0/S0 (1.1%) | I2: Moves/Fire Fang 13.2→0.0% (-13.2) Moves/Poison Jab 0.0→13.1% (+13.1) | J2: 1. Earthquake (99.6%) 2. Stealth Rock (48.4%) 3. Scale Shot (39.6%) 4. Outrage (34.9%) 5. Rock Tomb (29.4%) | K2: 6. Swords Dance (28.7%) 7. Dragon Tail (28.6%) 8. Spikes (19.1%) 9. Rock Slide (17.3%) 10. Poison Jab (13.1%) | L2: 1. Focus Sash (36.9%) 2. Sitrus Berry (24%) 3. Choice Scarf (22.6%) 4. Lum Berry (9.6%) 5. Life Orb (2.9%) | M2: 6. Garchompite (0.7%) 7. Leftovers (0.7%) 8. Haban Berry (0.6%) 9. Yache Berry (0.4%) 10. Roseli Berry (0.2%) | N2: 1. Jolly +S -C (48.3%) 2. Adamant +A -C (29.3%) 3. Impish +B -C (19.4%) 4. Careful +D -C (1.6%) 5. Naive +S -D (0.4%) | O2: 6. Bold +B -A (0.3%) 7. Naughty +A -D (0.2%) 8. Hasty +S -B (0.2%) 9. Modest +C -A (0.1%) 10. Brave +A -S (0.1%) | P2: 1. H2/A32/B0/C0/D0/S32 (47.9%) 2. H0/A32/B2/C0/D0/S32 (9.7%) 3. H0/A32/B1/C0/D1/S32 (4.7%) 4. H32/A0/B32/C0/D0/S2 (4%) 5. H32/A0/B32/C0/D2/S0 (3.3%) | Q2: 6. H0/A32/B0/C0/D2/S32 (2.7%) 7. H32/A0/B30/C0/D0/S4 (2%) 8. H0/A30/B4/C0/D0/S32 (1.4%) 9. H32/A0/B15/C0/D3/S16 (1.3%) 10. H32/A2/B32/C0/D0/S0 (1.1%) | R2: 1. Mimikyu 2. Primarina 3. Metagross 4. Archaludon 5. Meowscarada | S2: 6. Gyarados 7. Charizard 8. Delphox 9. Blaziken 10. Greninja
A3: 2 | B3: Mimikyu | C3: 1. Play Rough (98.4%) 2. Shadow Sneak (97.9%) 3. Swords Dance (85.4%) 4. Shadow Claw (69.9%) 5. Curse (13.8%) 6. Wood Hammer (11.5%) 7. Trick Room (7.8%) 8. Drain Punch (7.7%) 9. Will-O-Wisp (1.5%) 10. Destiny Bond (1.5%) | D3: 1. Life Orb (85.2%) 2. Scope Lens (5.4%) 3. Lum Berry (3.2%) 4. Spell Tag (2%) 5. Fairy Feather (0.8%) 6. Leftovers (0.6%) 7. Wide Lens (0.6%) 8. Bright Powder (0.4%) 9. Mental Herb (0.4%) 10. Sitrus Berry (0.3%) | E3: 1. Disguise (100%) | F3: 1. Adamant +A -C (82.8%) 2. Jolly +S -C (12.8%) 3. Brave +A -S (2.6%) 4. Impish +B -C (0.4%) 5. Relaxed +B -S (0.2%) 6. Careful +D -C (0.2%) 7. Lonely +A -B (0.2%) 8. Naughty +A -D (0.1%) 9. Timid +S -A (0.1%) 10. Sassy +D -S (0.1%) | G3: 1. Garchomp 2. Metagross 3. Archaludon 4. Hippowdon 5. Primarina 6. Greninja 7. Charizard 8. Gyarados 9. Delphox 10. Meowscarada | H3: 1. H1/A32/B1/C0/D0/S32 (24.6%) 2. H2/A32/B0/C0/D0/S32 (20.6%) 3. H29/A32/B5/C0/D0/S0 (5.8%) 4. H0/A32/B2/C0/D0/S32 (3.5%) 5. H32/A32/B2/C0/D0/S0 (3.4%) 6. H29/A26/B11/C0/D0/S0 (2.4%) 7. H1/A32/B0/C0/D1/S32 (2.1%) 8. H29/A30/B7/C0/D0/S0 (1.7%) 9. H28/A30/B7/C0/D0/S1 (1.7%) 10. H0/A32/B0/C0/D2/S32 (1.5%) | I3: No significant change this update | J3: 1. Play Rough (98.4%) 2. Shadow Sneak (97.9%) 3. Swords Dance (85.4%) 4. Shadow Claw (69.9%) 5. Curse (13.8%) | K3: 6. Wood Hammer (11.5%) 7. Trick Room (7.8%) 8. Drain Punch (7.7%) 9. Will-O-Wisp (1.5%) 10. Destiny Bond (1.5%) | L3: 1. Life Orb (85.2%) 2. Scope Lens (5.4%) 3. Lum Berry (3.2%) 4. Spell Tag (2%) 5. Fairy Feather (0.8%) | M3: 6. Leftovers (0.6%) 7. Wide Lens (0.6%) 8. Bright Powder (0.4%) 9. Mental Herb (0.4%) 10. Sitrus Berry (0.3%) | N3: 1. Adamant +A -C (82.8%) 2. Jolly +S -C (12.8%) 3. Brave +A -S (2.6%) 4. Impish +B -C (0.4%) 5. Relaxed +B -S (0.2%) | O3: 6. Careful +D -C (0.2%) 7. Lonely +A -B (0.2%) 8. Naughty +A -D (0.1%) 9. Timid +S -A (0.1%) 10. Sassy +D -S (0.1%) | P3: 1. H1/A32/B1/C0/D0/S32 (24.6%) 2. H2/A32/B0/C0/D0/S32 (20.6%) 3. H29/A32/B5/C0/D0/S0 (5.8%) 4. H0/A32/B2/C0/D0/S32 (3.5%) 5. H32/A32/B2/C0/D0/S0 (3.4%) | Q3: 6. H29/A26/B11/C0/D0/S0 (2.4%) 7. H1/A32/B0/C0/D1/S32 (2.1%) 8. H29/A30/B7/C0/D0/S0 (1.7%) 9. H28/A30/B7/C0/D0/S1 (1.7%) 10. H0/A32/B0/C0/D2/S32 (1.5%) | R3: 1. Garchomp 2. Metagross 3. Archaludon 4. Hippowdon 5. Primarina | S3: 6. Greninja 7. Charizard 8. Gyarados 9. Delphox 10. Meowscarada
A4: 3 | B4: Archaludon | C4: 1. Flash Cannon (73.8%) 2. Draco Meteor (73%) 3. Thunderbolt (62.6%) 4. Stealth Rock (38.1%) 5. Mirror Coat (21%) 6. Aura Sphere (18.1%) 7. Roar (16.8%) 8. Dark Pulse (16.4%) 9. Electro Shot (15.8%) 10. Dragon Tail (14.9%) | D4: 1. Sitrus Berry (31.7%) 2. White Herb (20.5%) 3. Leftovers (20.4%) 4. Choice Scarf (12.9%) 5. Scope Lens (6.1%) 6. Shuca Berry (2.1%) 7. Dragon Fang (0.9%) 8. Expert Belt (0.9%) 9. Chesto Berry (0.8%) 10. Chople Berry (0.6%) | E4: 1. Stamina (67.7%) 2. Sturdy (32.3%) 3. Stalwart (0.1%) | F4: 1. Modest +C -A (43.3%) 2. Bold +B -A (17.5%) 3. Timid +S -A (16.6%) 4. Calm +D -A (14.9%) 5. Relaxed +B -S (1.7%) 6. Impish +B -C (1.7%) 7. Careful +D -C (1.5%) 8. Sassy +D -S (1%) 9. Rash +C -D (0.6%) 10. Quiet +C -S (0.6%) | G4: 1. Mimikyu 2. Garchomp 3. Metagross 4. Hippowdon 5. Primarina 6. Gyarados 7. Meowscarada 8. Blaziken 9. Delphox 10. Greninja | H4: 1. H2/A0/B0/C32/D0/S32 (23.3%) 2. H32/A0/B2/C0/D32/S0 (9.2%) 3. H32/A0/B0/C0/D32/S2 (5.1%) 4. H0/A0/B1/C32/D1/S32 (4.3%) 5. H0/A0/B2/C32/D0/S32 (2.7%) 6. H32/A0/B0/C32/D0/S2 (2.4%) 7. H32/A0/B2/C32/D0/S0 (2.4%) 8. H32/A0/B0/C32/D2/S0 (2.2%) 9. H32/A0/B32/C0/D2/S0 (1.7%) 10. H0/A0/B0/C32/D2/S32 (1.6%) | I4: No significant change this update | J4: 1. Flash Cannon (73.8%) 2. Draco Meteor (73%) 3. Thunderbolt (62.6%) 4. Stealth Rock (38.1%) 5. Mirror Coat (21%) | K4: 6. Aura Sphere (18.1%) 7. Roar (16.8%) 8. Dark Pulse (16.4%) 9. Electro Shot (15.8%) 10. Dragon Tail (14.9%) | L4: 1. Sitrus Berry (31.7%) 2. White Herb (20.5%) 3. Leftovers (20.4%) 4. Choice Scarf (12.9%) 5. Scope Lens (6.1%) | M4: 6. Shuca Berry (2.1%) 7. Dragon Fang (0.9%) 8. Expert Belt (0.9%) 9. Chesto Berry (0.8%) 10. Chople Berry (0.6%) | N4: 1. Modest +C -A (43.3%) 2. Bold +B -A (17.5%) 3. Timid +S -A (16.6%) 4. Calm +D -A (14.9%) 5. Relaxed +B -S (1.7%) | O4: 6. Impish +B -C (1.7%) 7. Careful +D -C (1.5%) 8. Sassy +D -S (1%) 9. Rash +C -D (0.6%) 10. Quiet +C -S (0.6%) | P4: 1. H2/A0/B0/C32/D0/S32 (23.3%) 2. H32/A0/B2/C0/D32/S0 (9.2%) 3. H32/A0/B0/C0/D32/S2 (5.1%) 4. H0/A0/B1/C32/D1/S32 (4.3%) 5. H0/A0/B2/C32/D0/S32 (2.7%) | Q4: 6. H32/A0/B0/C32/D0/S2 (2.4%) 7. H32/A0/B2/C32/D0/S0 (2.4%) 8. H32/A0/B0/C32/D2/S0 (2.2%) 9. H32/A0/B32/C0/D2/S0 (1.7%) 10. H0/A0/B0/C32/D2/S32 (1.6%) | R4: 1. Mimikyu 2. Garchomp 3. Metagross 4. Hippowdon 5. Primarina | S4: 6. Gyarados 7. Meowscarada 8. Blaziken 9. Delphox 10. Greninja
A5: 4 | B5: Metagross | C5: 1. Psychic Fangs (94.9%) 2. Bullet Punch (91.4%) 3. Earthquake (52.6%) 4. Ice Punch (46.8%) 5. Thunder Punch (33.6%) 6. Body Press (17.8%) 7. Iron Defense (17.3%) 8. Hammer Arm (13%) 9. Iron Head (8.1%) 10. Meteor Mash (6.3%) | D5: 1. Metagrossite (99%) 2. Life Orb (0.1%) 3. Sitrus Berry (0.1%) 4. Leftovers (0.1%) 5. Choice Scarf (0.1%) 6. Shuca Berry (0.1%) 7. Lum Berry (0.1%) 8. Light Clay (0.1%) 9. Expert Belt (0.1%) 10. Charizardite Y (0%) | E5: 1. Clear Body (99.5%) 2. Light Metal (0.5%) | F5: 1. Adamant +A -C (47.3%) 2. Jolly +S -C (38.5%) 3. Impish +B -C (12.5%) 4. Careful +D -C (0.4%) 5. Naive +S -D (0.3%) 6. Brave +A -S (0.2%) 7. Lonely +A -B (0.2%) 8. Naughty +A -D (0.1%) 9. Sassy +D -S (0.1%) 10. Bold +B -A (0.1%) | G5: 1. Primarina 2. Mimikyu 3. Garchomp 4. Hydreigon 5. Hippowdon 6. Archaludon 7. Meowscarada 8. Charizard 9. Dragonite 10. Greninja | H5: 1. H2/A32/B0/C0/D0/S32 (25.1%) 2. H20/A25/B1/C0/D1/S19 (4.9%) 3. H10/A25/B0/C8/D0/S23 (4%) 4. H26/A32/B0/C0/D0/S8 (3.8%) 5. H12/A22/B0/C0/D0/S32 (3.2%) 6. H16/A25/B0/C0/D0/S25 (2.8%) 7. H32/A0/B32/C0/D0/S2 (2.3%) 8. H22/A32/B3/C0/D0/S9 (2%) 9. H32/A32/B0/C0/D0/S2 (1.8%) 10. H9/A32/B0/C0/D0/S25 (1.7%) | I5: No significant change this update | J5: 1. Psychic Fangs (94.9%) 2. Bullet Punch (91.4%) 3. Earthquake (52.6%) 4. Ice Punch (46.8%) 5. Thunder Punch (33.6%) | K5: 6. Body Press (17.8%) 7. Iron Defense (17.3%) 8. Hammer Arm (13%) 9. Iron Head (8.1%) 10. Meteor Mash (6.3%) | L5: 1. Metagrossite (99%) 2. Life Orb (0.1%) 3. Sitrus Berry (0.1%) 4. Leftovers (0.1%) 5. Choice Scarf (0.1%) | M5: 6. Shuca Berry (0.1%) 7. Lum Berry (0.1%) 8. Light Clay (0.1%) 9. Expert Belt (0.1%) 10. Charizardite Y (0%) | N5: 1. Adamant +A -C (47.3%) 2. Jolly +S -C (38.5%) 3. Impish +B -C (12.5%) 4. Careful +D -C (0.4%) 5. Naive +S -D (0.3%) | O5: 6. Brave +A -S (0.2%) 7. Lonely +A -B (0.2%) 8. Naughty +A -D (0.1%) 9. Sassy +D -S (0.1%) 10. Bold +B -A (0.1%) | P5: 1. H2/A32/B0/C0/D0/S32 (25.1%) 2. H20/A25/B1/C0/D1/S19 (4.9%) 3. H10/A25/B0/C8/D0/S23 (4%) 4. H26/A32/B0/C0/D0/S8 (3.8%) 5. H12/A22/B0/C0/D0/S32 (3.2%) | Q5: 6. H16/A25/B0/C0/D0/S25 (2.8%) 7. H32/A0/B32/C0/D0/S2 (2.3%) 8. H22/A32/B3/C0/D0/S9 (2%) 9. H32/A32/B0/C0/D0/S2 (1.8%) 10. H9/A32/B0/C0/D0/S25 (1.7%) | R5: 1. Primarina 2. Mimikyu 3. Garchomp 4. Hydreigon 5. Hippowdon | S5: 6. Archaludon 7. Meowscarada 8. Charizard 9. Dragonite 10. Greninja
A6: 5 | B6: Hippowdon | C6: 1. Earthquake (98.6%) 2. Yawn (95%) 3. Stealth Rock (74.8%) 4. Slack Off (66.3%) 5. Whirlwind (40.1%) 6. Protect (17.4%) 7. Roar (3.3%) 8. Rock Tomb (1%) 9. Ice Fang (0.7%) 10. Fissure (0.6%) | D6: 1. Sitrus Berry (57.4%) 2. Leftovers (40.6%) 3. Smooth Rock (0.5%) 4. Mental Herb (0.3%) 5. Lum Berry (0.2%) 6. Rindo Berry (0.2%) 7. Life Orb (0.1%) 8. Bright Powder (0.1%) 9. Quick Claw (0.1%) 10. Focus Sash (0.1%) | E6: 1. Sand Stream (99.9%) 2. Sand Force (0.1%) | F6: 1. Impish +B -C (74.5%) 2. Careful +D -C (13.5%) 3. Relaxed +B -S (8.3%) 4. Sassy +D -S (1.4%) 5. Bold +B -A (1%) 6. Adamant +A -C (0.7%) 7. Calm +D -A (0.2%) 8. Brave +A -S (0.2%) 9. Lonely +A -B (0.1%) 10. Naughty +A -D (0%) | G6: 1. Mimikyu 2. Metagross 3. Primarina 4. Meowscarada 5. Archaludon 6. Gyarados 7. Hydreigon 8. Dragonite 9. Garchomp 10. Charizard | H6: 1. H32/A0/B32/C0/D2/S0 (23.9%) 2. H32/A0/B2/C0/D32/S0 (17.4%) 3. H32/A0/B22/C0/D12/S0 (8.8%) 4. H32/A0/B22/C0/D10/S2 (5.2%) 5. H32/A0/B12/C0/D22/S0 (4.2%) 6. H32/A0/B15/C0/D19/S0 (4.1%) 7. H32/A0/B18/C0/D16/S0 (2.8%) 8. H32/A0/B20/C0/D14/S0 (2.3%) 9. H32/A0/B32/C0/D0/S2 (2%) 10. H32/A0/B6/C0/D28/S0 (1.7%) | I6: No significant change this update | J6: 1. Earthquake (98.6%) 2. Yawn (95%) 3. Stealth Rock (74.8%) 4. Slack Off (66.3%) 5. Whirlwind (40.1%) | K6: 6. Protect (17.4%) 7. Roar (3.3%) 8. Rock Tomb (1%) 9. Ice Fang (0.7%) 10. Fissure (0.6%) | L6: 1. Sitrus Berry (57.4%) 2. Leftovers (40.6%) 3. Smooth Rock (0.5%) 4. Mental Herb (0.3%) 5. Lum Berry (0.2%) | M6: 6. Rindo Berry (0.2%) 7. Life Orb (0.1%) 8. Bright Powder (0.1%) 9. Quick Claw (0.1%) 10. Focus Sash (0.1%) | N6: 1. Impish +B -C (74.5%) 2. Careful +D -C (13.5%) 3. Relaxed +B -S (8.3%) 4. Sassy +D -S (1.4%) 5. Bold +B -A (1%) | O6: 6. Adamant +A -C (0.7%) 7. Calm +D -A (0.2%) 8. Brave +A -S (0.2%) 9. Lonely +A -B (0.1%) 10. Naughty +A -D (0%) | P6: 1. H32/A0/B32/C0/D2/S0 (23.9%) 2. H32/A0/B2/C0/D32/S0 (17.4%) 3. H32/A0/B22/C0/D12/S0 (8.8%) 4. H32/A0/B22/C0/D10/S2 (5.2%) 5. H32/A0/B12/C0/D22/S0 (4.2%) | Q6: 6. H32/A0/B15/C0/D19/S0 (4.1%) 7. H32/A0/B18/C0/D16/S0 (2.8%) 8. H32/A0/B20/C0/D14/S0 (2.3%) 9. H32/A0/B32/C0/D0/S2 (2%) 10. H32/A0/B6/C0/D28/S0 (1.7%) | R6: 1. Mimikyu 2. Metagross 3. Primarina 4. Meowscarada 5. Archaludon | S6: 6. Gyarados 7. Hydreigon 8. Dragonite 9. Garchomp 10. Charizard
A7: 6 | B7: Primarina | C7: 1. Moonblast (98.4%) 2. Sparkling Aria (87.6%) 3. Aqua Jet (75%) 4. Encore (43.1%) 5. Calm Mind (23.2%) 6. Flip Turn (21.7%) 7. Surf (10.1%) 8. Ice Beam (6.6%) 9. Misty Terrain (5.7%) 10. Energy Ball (5.4%) | D7: 1. Sitrus Berry (50.2%) 2. Leftovers (22.7%) 3. Mystic Water (9.9%) 4. Focus Sash (4.7%) 5. Chesto Berry (3.3%) 6. Lum Berry (2.8%) 7. Wacan Berry (1.7%) 8. Fairy Feather (1.5%) 9. Life Orb (1%) 10. Quick Claw (0.4%) | E7: 1. Torrent (96.3%) 2. Liquid Voice (3.7%) | F7: 1. Modest +C -A (63.4%) 2. Quiet +C -S (16%) 3. Bold +B -A (12.3%) 4. Relaxed +B -S (3.7%) 5. Calm +D -A (2.6%) 6. Timid +S -A (0.8%) 7. Sassy +D -S (0.4%) 8. Mild +C -B (0.4%) 9. Rash +C -D (0.2%) 10. Naive +S -D (0%) | G7: 1. Garchomp 2. Metagross 3. Mimikyu 4. Hippowdon 5. Hydreigon 6. Meowscarada 7. Archaludon 8. Charizard 9. Delphox 10. Dragonite | H7: 1. H32/A0/B0/C32/D0/S2 (7.5%) 2. H32/A0/B20/C14/D0/S0 (6.4%) 3. H32/A0/B29/C4/D1/S0 (4.4%) 4. H32/A0/B2/C32/D0/S0 (4.3%) 5. H32/A0/B32/C2/D0/S0 (3.7%) 6. H2/A0/B0/C32/D0/S32 (3.4%) 7. H32/A0/B0/C32/D2/S0 (3.1%) 8. H32/A0/B32/C0/D2/S0 (2.2%) 9. H32/A0/B30/C4/D0/S0 (2.1%) 10. H32/A0/B0/C24/D0/S10 (2%) | I7: No significant change this update | J7: 1. Moonblast (98.4%) 2. Sparkling Aria (87.6%) 3. Aqua Jet (75%) 4. Encore (43.1%) 5. Calm Mind (23.2%) | K7: 6. Flip Turn (21.7%) 7. Surf (10.1%) 8. Ice Beam (6.6%) 9. Misty Terrain (5.7%) 10. Energy Ball (5.4%) | L7: 1. Sitrus Berry (50.2%) 2. Leftovers (22.7%) 3. Mystic Water (9.9%) 4. Focus Sash (4.7%) 5. Chesto Berry (3.3%) | M7: 6. Lum Berry (2.8%) 7. Wacan Berry (1.7%) 8. Fairy Feather (1.5%) 9. Life Orb (1%) 10. Quick Claw (0.4%) | N7: 1. Modest +C -A (63.4%) 2. Quiet +C -S (16%) 3. Bold +B -A (12.3%) 4. Relaxed +B -S (3.7%) 5. Calm +D -A (2.6%) | O7: 6. Timid +S -A (0.8%) 7. Sassy +D -S (0.4%) 8. Mild +C -B (0.4%) 9. Rash +C -D (0.2%) 10. Naive +S -D (0%) | P7: 1. H32/A0/B0/C32/D0/S2 (7.5%) 2. H32/A0/B20/C14/D0/S0 (6.4%) 3. H32/A0/B29/C4/D1/S0 (4.4%) 4. H32/A0/B2/C32/D0/S0 (4.3%) 5. H32/A0/B32/C2/D0/S0 (3.7%) | Q7: 6. H2/A0/B0/C32/D0/S32 (3.4%) 7. H32/A0/B0/C32/D2/S0 (3.1%) 8. H32/A0/B32/C0/D2/S0 (2.2%) 9. H32/A0/B30/C4/D0/S0 (2.1%) 10. H32/A0/B0/C24/D0/S10 (2%) | R7: 1. Garchomp 2. Metagross 3. Mimikyu 4. Hippowdon 5. Hydreigon | S7: 6. Meowscarada 7. Archaludon 8. Charizard 9. Delphox 10. Dragonite
A8: 7 | B8: Meowscarada | C8: 1. Flower Trick (96.9%) 2. Triple Axel (84.3%) 3. U-turn (72.2%) 4. Knock Off (62.1%) 5. Sucker Punch (17.2%) 6. Thunder Punch (16.9%) 7. Foul Play (7.2%) 8. Play Rough (6.6%) 9. Power Gem (5.9%) 10. Toxic Spikes (5.7%) | D8: 1. Choice Scarf (74.7%) 2. Focus Sash (17.3%) 3. Life Orb (4.7%) 4. Expert Belt (1.3%) 5. Light Ball (0.3%) 6. Wide Lens (0.2%) 7. Lum Berry (0.2%) 8. Muscle Band (0.2%) 9. Leftovers (0.2%) 10. Quick Claw (0.1%) | E8: 1. Protean (93.1%) 2. Overgrow (6.9%) | F8: 1. Jolly +S -C (57.9%) 2. Adamant +A -C (34%) 3. Naive +S -D (4.2%) 4. Rash +C -D (1.3%) 5. Naughty +A -D (0.8%) 6. Hasty +S -B (0.6%) 7. Timid +S -A (0.4%) 8. Modest +C -A (0.4%) 9. Lonely +A -B (0.3%) 10. Mild +C -B (0.1%) | G8: 1. Garchomp 2. Hippowdon 3. Primarina 4. Mimikyu 5. Archaludon 6. Metagross 7. Delphox 8. Charizard 9. Blaziken 10. Gyarados | H8: 1. H2/A32/B0/C0/D0/S32 (59.8%) 2. H0/A32/B2/C0/D0/S32 (9.6%) 3. H0/A32/B1/C0/D1/S32 (3.9%) 4. H0/A32/B0/C0/D2/S32 (3.8%) 5. H4/A30/B20/C0/D0/S12 (1.8%) 6. H0/A32/B0/C0/D0/S32 (1.4%) 7. H0/A30/B0/C11/D0/S25 (1.2%) 8. H4/A25/B23/C0/D0/S14 (1%) 9. H8/A30/B14/C0/D0/S14 (0.8%) 10. H0/A2/B0/C32/D0/S32 (0.8%) | I8: No significant change this update | J8: 1. Flower Trick (96.9%) 2. Triple Axel (84.3%) 3. U-turn (72.2%) 4. Knock Off (62.1%) 5. Sucker Punch (17.2%) | K8: 6. Thunder Punch (16.9%) 7. Foul Play (7.2%) 8. Play Rough (6.6%) 9. Power Gem (5.9%) 10. Toxic Spikes (5.7%) | L8: 1. Choice Scarf (74.7%) 2. Focus Sash (17.3%) 3. Life Orb (4.7%) 4. Expert Belt (1.3%) 5. Light Ball (0.3%) | M8: 6. Wide Lens (0.2%) 7. Lum Berry (0.2%) 8. Muscle Band (0.2%) 9. Leftovers (0.2%) 10. Quick Claw (0.1%) | N8: 1. Jolly +S -C (57.9%) 2. Adamant +A -C (34%) 3. Naive +S -D (4.2%) 4. Rash +C -D (1.3%) 5. Naughty +A -D (0.8%) | O8: 6. Hasty +S -B (0.6%) 7. Timid +S -A (0.4%) 8. Modest +C -A (0.4%) 9. Lonely +A -B (0.3%) 10. Mild +C -B (0.1%) | P8: 1. H2/A32/B0/C0/D0/S32 (59.8%) 2. H0/A32/B2/C0/D0/S32 (9.6%) 3. H0/A32/B1/C0/D1/S32 (3.9%) 4. H0/A32/B0/C0/D2/S32 (3.8%) 5. H4/A30/B20/C0/D0/S12 (1.8%) | Q8: 6. H0/A32/B0/C0/D0/S32 (1.4%) 7. H0/A30/B0/C11/D0/S25 (1.2%) 8. H4/A25/B23/C0/D0/S14 (1%) 9. H8/A30/B14/C0/D0/S14 (0.8%) 10. H0/A2/B0/C32/D0/S32 (0.8%) | R8: 1. Garchomp 2. Hippowdon 3. Primarina 4. Mimikyu 5. Archaludon | S8: 6. Metagross 7. Delphox 8. Charizard 9. Blaziken 10. Gyarados
A9: 8 | B9: Gyarados | C9: 1. Waterfall (84.9%) 2. Dragon Dance (84.1%) 3. Earthquake (81.1%) 4. Ice Fang (52%) 5. Power Whip (38.5%) 6. Taunt (23.9%) 7. Crunch (13.5%) 8. Avalanche (11%) 9. Temper Flare (2.3%) 10. Substitute (2%) | D9: 1. Gyaradosite (80.1%) 2. Leftovers (10.8%) 3. Sitrus Berry (3.9%) 4. Lum Berry (2.2%) 5. Expert Belt (0.9%) 6. Wacan Berry (0.5%) 7. Life Orb (0.4%) 8. Chesto Berry (0.3%) 9. Focus Sash (0.2%) 10. Choice Scarf (0.2%) | E9: 1. Intimidate (99.3%) 2. Moxie (0.7%) | F9: 1. Jolly +S -C (53.4%) 2. Adamant +A -C (40.1%) 3. Impish +B -C (5.5%) 4. Careful +D -C (0.6%) 5. Naughty +A -D (0.1%) 6. Naive +S -D (0%) 7. Timid +S -A (0%) 8. Brave +A -S (0%) 9. Relaxed +B -S (0%) 10. Sassy +D -S (0%) | G9: 1. Garchomp 2. Mimikyu 3. Archaludon 4. Hippowdon 5. Blaziken 6. Ninetales-Alola 7. Delphox 8. Meowscarada 9. Metagross 10. Glimmora | H9: 1. H1/A32/B1/C0/D0/S32 (25.7%) 2. H2/A32/B0/C0/D0/S32 (18.9%) 3. H1/A32/B0/C0/D1/S32 (2.9%) 4. H7/A32/B1/C0/D0/S26 (2%) 5. H0/A32/B2/C0/D0/S32 (1.9%) 6. H13/A32/B0/C0/D0/S21 (1.9%) 7. H31/A11/B21/C0/D1/S2 (1.7%) 8. H5/A26/B5/C0/D0/S30 (1.6%) 9. H3/A32/B1/C0/D0/S30 (1.4%) 10. H3/A32/B0/C0/D0/S31 (1.3%) | I9: No significant change this update | J9: 1. Waterfall (84.9%) 2. Dragon Dance (84.1%) 3. Earthquake (81.1%) 4. Ice Fang (52%) 5. Power Whip (38.5%) | K9: 6. Taunt (23.9%) 7. Crunch (13.5%) 8. Avalanche (11%) 9. Temper Flare (2.3%) 10. Substitute (2%) | L9: 1. Gyaradosite (80.1%) 2. Leftovers (10.8%) 3. Sitrus Berry (3.9%) 4. Lum Berry (2.2%) 5. Expert Belt (0.9%) | M9: 6. Wacan Berry (0.5%) 7. Life Orb (0.4%) 8. Chesto Berry (0.3%) 9. Focus Sash (0.2%) 10. Choice Scarf (0.2%) | N9: 1. Jolly +S -C (53.4%) 2. Adamant +A -C (40.1%) 3. Impish +B -C (5.5%) 4. Careful +D -C (0.6%) 5. Naughty +A -D (0.1%) | O9: 6. Naive +S -D (0%) 7. Timid +S -A (0%) 8. Brave +A -S (0%) 9. Relaxed +B -S (0%) 10. Sassy +D -S (0%) | P9: 1. H1/A32/B1/C0/D0/S32 (25.7%) 2. H2/A32/B0/C0/D0/S32 (18.9%) 3. H1/A32/B0/C0/D1/S32 (2.9%) 4. H7/A32/B1/C0/D0/S26 (2%) 5. H0/A32/B2/C0/D0/S32 (1.9%) | Q9: 6. H13/A32/B0/C0/D0/S21 (1.9%) 7. H31/A11/B21/C0/D1/S2 (1.7%) 8. H5/A26/B5/C0/D0/S30 (1.6%) 9. H3/A32/B1/C0/D0/S30 (1.4%) 10. H3/A32/B0/C0/D0/S31 (1.3%) | R9: 1. Garchomp 2. Mimikyu 3. Archaludon 4. Hippowdon 5. Blaziken | S9: 6. Ninetales-Alola 7. Delphox 8. Meowscarada 9. Metagross 10. Glimmora
A10: 9 | B10: Blaziken | C10: 1. Flare Blitz (85%) 2. Close Combat (66.2%) 3. Thunder Punch (48.1%) 4. Swords Dance (47.3%) 5. Protect (40.5%) 6. Detect (31.8%) 7. High Jump Kick (23.2%) 8. Baton Pass (9.6%) 9. Earthquake (6.6%) 10. Overheat (6%) | D10: 1. Blazikenite (73.8%) 2. Focus Sash (14.9%) 3. Life Orb (7.4%) 4. Sitrus Berry (1.5%) 5. Leftovers (0.5%) 6. Shuca Berry (0.3%) 7. Scope Lens (0.2%) 8. White Herb (0.2%) 9. Mental Herb (0.2%) 10. Lum Berry (0.1%) | E10: 1. Speed Boost (98.5%) 2. Blaze (1.5%) | F10: 1. Adamant +A -C (72.5%) 2. Jolly +S -C (15.9%) 3. Naughty +A -D (4.7%) 4. Impish +B -C (1.6%) 5. Rash +C -D (1.4%) 6. Naive +S -D (1.2%) 7. Timid +S -A (0.6%) 8. Modest +C -A (0.6%) 9. Lonely +A -B (0.4%) 10. Careful +D -C (0.4%) | G10: 1. Garchomp 2. Mimikyu 3. Archaludon 4. Gyarados 5. Meowscarada 6. Hippowdon 7. Primarina 8. Ninetales-Alola 9. Metagross 10. Greninja | H10: 1. H2/A32/B0/C0/D0/S32 (46.8%) 2. H16/A32/B0/C0/D0/S18 (6.5%) 3. H10/A32/B0/C0/D0/S24 (4.2%) 4. H0/A32/B2/C0/D0/S32 (3.5%) 5. H0/A32/B0/C5/D0/S29 (2.3%) 6. H0/A32/B1/C0/D1/S32 (2.2%) 7. H0/A32/B0/C0/D0/S32 (2%) 8. H0/A32/B0/C0/D2/S32 (1.8%) 9. H20/A25/B3/C0/D0/S18 (1.4%) 10. H0/A2/B0/C32/D0/S32 (1.3%) | I10: No significant change this update | J10: 1. Flare Blitz (85%) 2. Close Combat (66.2%) 3. Thunder Punch (48.1%) 4. Swords Dance (47.3%) 5. Protect (40.5%) | K10: 6. Detect (31.8%) 7. High Jump Kick (23.2%) 8. Baton Pass (9.6%) 9. Earthquake (6.6%) 10. Overheat (6%) | L10: 1. Blazikenite (73.8%) 2. Focus Sash (14.9%) 3. Life Orb (7.4%) 4. Sitrus Berry (1.5%) 5. Leftovers (0.5%) | M10: 6. Shuca Berry (0.3%) 7. Scope Lens (0.2%) 8. White Herb (0.2%) 9. Mental Herb (0.2%) 10. Lum Berry (0.1%) | N10: 1. Adamant +A -C (72.5%) 2. Jolly +S -C (15.9%) 3. Naughty +A -D (4.7%) 4. Impish +B -C (1.6%) 5. Rash +C -D (1.4%) | O10: 6. Naive +S -D (1.2%) 7. Timid +S -A (0.6%) 8. Modest +C -A (0.6%) 9. Lonely +A -B (0.4%) 10. Careful +D -C (0.4%) | P10: 1. H2/A32/B0/C0/D0/S32 (46.8%) 2. H16/A32/B0/C0/D0/S18 (6.5%) 3. H10/A32/B0/C0/D0/S24 (4.2%) 4. H0/A32/B2/C0/D0/S32 (3.5%) 5. H0/A32/B0/C5/D0/S29 (2.3%) | Q10: 6. H0/A32/B1/C0/D1/S32 (2.2%) 7. H0/A32/B0/C0/D0/S32 (2%) 8. H0/A32/B0/C0/D2/S32 (1.8%) 9. H20/A25/B3/C0/D0/S18 (1.4%) 10. H0/A2/B0/C32/D0/S32 (1.3%) | R10: 1. Garchomp 2. Mimikyu 3. Archaludon 4. Gyarados 5. Meowscarada | S10: 6. Hippowdon 7. Primarina 8. Ninetales-Alola 9. Metagross 10. Greninja
A11: 10 | B11: Charizard | C11: 1. Solar Beam (62.6%) 2. Flamethrower (41.6%) 3. Air Slash (41.1%) 4. Flare Blitz (34.2%) 5. Flame Charge (29.1%) 6. Overheat (24.7%) 7. Dragon Dance (21.6%) 8. Weather Ball (19.8%) 9. Roost (19.5%) 10. Dragon Claw (17.9%) | D11: 1. Charizardite Y (64.2%) 2. Charizardite X (34.8%) 3. Raichunite Y (0.1%) 4. Choice Scarf (0.1%) 5. Lum Berry (0.1%) 6. Expert Belt (0%) 7. Quick Claw (0%) 8. Life Orb (0%) 9. White Herb (0%) 10. Leftovers (0%) | E11: 1. Blaze (87.7%) 2. Solar Power (12.3%) | F11: 1. Modest +C -A (38.7%) 2. Timid +S -A (24.9%) 3. Adamant +A -C (21.5%) 4. Jolly +S -C (13.4%) 5. Bold +B -A (0.4%) 6. Impish +B -C (0.2%) 7. Docile (0.2%) 8. Calm +D -A (0.1%) 9. Naive +S -D (0.1%) 10. Mild +C -B (0.1%) | G11: 1. Garchomp 2. Mimikyu 3. Primarina 4. Metagross 5. Archaludon 6. Hippowdon 7. Meowscarada 8. Hydreigon 9. Greninja 10. Corviknight | H11: 1. H2/A0/B0/C32/D0/S32 (27.9%) 2. H2/A32/B0/C0/D0/S32 (15.5%) 3. H4/A30/B0/C0/D0/S32 (6.2%) 4. H12/A0/B20/C16/D0/S18 (3.6%) 5. H0/A0/B2/C32/D0/S32 (3.1%) 6. H6/A0/B9/C29/D0/S22 (2.5%) 7. H14/A0/B12/C21/D0/S19 (2.2%) 8. H0/A32/B2/C0/D0/S32 (1.6%) 9. H0/A0/B0/C32/D2/S32 (1.4%) 10. H12/A0/B20/C14/D0/S20 (1.3%) | I11: Moves/Outrage 22.7→0.0% (-22.7) Moves/Dragon Claw 0.0→17.9% (+17.9) | J11: 1. Solar Beam (62.6%) 2. Flamethrower (41.6%) 3. Air Slash (41.1%) 4. Flare Blitz (34.2%) 5. Flame Charge (29.1%) | K11: 6. Overheat (24.7%) 7. Dragon Dance (21.6%) 8. Weather Ball (19.8%) 9. Roost (19.5%) 10. Dragon Claw (17.9%) | L11: 1. Charizardite Y (64.2%) 2. Charizardite X (34.8%) 3. Raichunite Y (0.1%) 4. Choice Scarf (0.1%) 5. Lum Berry (0.1%) | M11: 6. Expert Belt (0%) 7. Quick Claw (0%) 8. Life Orb (0%) 9. White Herb (0%) 10. Leftovers (0%) | N11: 1. Modest +C -A (38.7%) 2. Timid +S -A (24.9%) 3. Adamant +A -C (21.5%) 4. Jolly +S -C (13.4%) 5. Bold +B -A (0.4%) | O11: 6. Impish +B -C (0.2%) 7. Docile (0.2%) 8. Calm +D -A (0.1%) 9. Naive +S -D (0.1%) 10. Mild +C -B (0.1%) | P11: 1. H2/A0/B0/C32/D0/S32 (27.9%) 2. H2/A32/B0/C0/D0/S32 (15.5%) 3. H4/A30/B0/C0/D0/S32 (6.2%) 4. H12/A0/B20/C16/D0/S18 (3.6%) 5. H0/A0/B2/C32/D0/S32 (3.1%) | Q11: 6. H6/A0/B9/C29/D0/S22 (2.5%) 7. H14/A0/B12/C21/D0/S19 (2.2%) 8. H0/A32/B2/C0/D0/S32 (1.6%) 9. H0/A0/B0/C32/D2/S32 (1.4%) 10. H12/A0/B20/C14/D0/S20 (1.3%) | R11: 1. Garchomp 2. Mimikyu 3. Primarina 4. Metagross 5. Archaludon | S11: 6. Hippowdon 7. Meowscarada 8. Hydreigon 9. Greninja 10. Corviknight
A12: 11 | B12: Delphox | C12: 1. Flamethrower (84.8%) 2. Dazzling Gleam (63.4%) 3. Psychic (56.5%) 4. Substitute (44.3%) 5. Psyshock (39.9%) 6. Nasty Plot (37.8%) 7. Encore (17.5%) 8. Mystical Fire (10%) 9. Grass Knot (9.3%) 10. Shadow Ball (8.8%) | D12: 1. Delphoxite (99.2%) 2. Choice Scarf (0.3%) 3. Focus Sash (0.1%) 4. Life Orb (0%) 5. Blazikenite (0%) 6. Light Clay (0%) 7. Twisted Spoon (0%) 8. Raichunite Y (0%) 9. Staraptite (0%) 10. Lucarionite (0%) | E12: 1. Blaze (91.5%) 2. Magician (8.5%) | F12: 1. Timid +S -A (80.1%) 2. Modest +C -A (18.9%) 3. Bold +B -A (0.3%) 4. Mild +C -B (0.3%) 5. Hasty +S -B (0.2%) 6. Calm +D -A (0.1%) 7. Gentle +D -B (0%) 8. Quiet +C -S (0%) 9. Quirky (0%) 10. Naive +S -D (0%) | G12: 1. Garchomp 2. Mimikyu 3. Meowscarada 4. Archaludon 5. Primarina 6. Gyarados 7. Hippowdon 8. Metagross 9. Ninetales-Alola 10. Scizor | H12: 1. H2/A0/B0/C32/D0/S32 (20.5%) 2. H1/A0/B1/C32/D0/S32 (10.1%) 3. H5/A0/B0/C32/D0/S29 (9%) 4. H1/A0/B4/C32/D0/S29 (7.5%) 5. H1/A0/B0/C32/D1/S32 (3.5%) 6. H0/A0/B2/C32/D0/S32 (3.2%) 7. H9/A0/B8/C19/D0/S30 (2.6%) 8. H9/A0/B1/C27/D0/S29 (1.8%) 9. H25/A0/B0/C12/D0/S29 (1.7%) 10. H0/A0/B0/C32/D2/S32 (1.7%) | I12: No significant change this update | J12: 1. Flamethrower (84.8%) 2. Dazzling Gleam (63.4%) 3. Psychic (56.5%) 4. Substitute (44.3%) 5. Psyshock (39.9%) | K12: 6. Nasty Plot (37.8%) 7. Encore (17.5%) 8. Mystical Fire (10%) 9. Grass Knot (9.3%) 10. Shadow Ball (8.8%) | L12: 1. Delphoxite (99.2%) 2. Choice Scarf (0.3%) 3. Focus Sash (0.1%) 4. Life Orb (0%) 5. Blazikenite (0%) | M12: 6. Light Clay (0%) 7. Twisted Spoon (0%) 8. Raichunite Y (0%) 9. Staraptite (0%) 10. Lucarionite (0%) | N12: 1. Timid +S -A (80.1%) 2. Modest +C -A (18.9%) 3. Bold +B -A (0.3%) 4. Mild +C -B (0.3%) 5. Hasty +S -B (0.2%) | O12: 6. Calm +D -A (0.1%) 7. Gentle +D -B (0%) 8. Quiet +C -S (0%) 9. Quirky (0%) 10. Naive +S -D (0%) | P12: 1. H2/A0/B0/C32/D0/S32 (20.5%) 2. H1/A0/B1/C32/D0/S32 (10.1%) 3. H5/A0/B0/C32/D0/S29 (9%) 4. H1/A0/B4/C32/D0/S29 (7.5%) 5. H1/A0/B0/C32/D1/S32 (3.5%) | Q12: 6. H0/A0/B2/C32/D0/S32 (3.2%) 7. H9/A0/B8/C19/D0/S30 (2.6%) 8. H9/A0/B1/C27/D0/S29 (1.8%) 9. H25/A0/B0/C12/D0/S29 (1.7%) 10. H0/A0/B0/C32/D2/S32 (1.7%) | R12: 1. Garchomp 2. Mimikyu 3. Meowscarada 4. Archaludon 5. Primarina | S12: 6. Gyarados 7. Hippowdon 8. Metagross 9. Ninetales-Alola 10. Scizor
A13: 12 | B13: Greninja | C13: 1. Dark Pulse (86.9%) 2. Ice Beam (84.4%) 3. Water Shuriken (68.3%) 4. Sludge Wave (68.3%) 5. Surf (46.8%) 6. Grass Knot (7.9%) 7. Hydro Pump (6.6%) 8. Mud Shot (4.6%) 9. Toxic Spikes (4.5%) 10. U-turn (2.4%) | D13: 1. Greninjite (46.9%) 2. Focus Sash (44.3%) 3. Life Orb (4.1%) 4. Choice Scarf (3.5%) 5. Expert Belt (0.6%) 6. Light Ball (0.2%) 7. Mystic Water (0.1%) 8. King's Rock (0.1%) 9. Focus Band (0%) 10. Bright Powder (0%) | E13: 1. Protean (67.7%) 2. Torrent (32.3%) | F13: 1. Timid +S -A (52%) 2. Modest +C -A (42.8%) 3. Naive +S -D (2.5%) 4. Rash +C -D (0.8%) 5. Hasty +S -B (0.7%) 6. Mild +C -B (0.5%) 7. Jolly +S -C (0.3%) 8. Naughty +A -D (0.2%) 9. Adamant +A -C (0.1%) 10. Sassy +D -S (0%) | G13: 1. Mimikyu 2. Garchomp 3. Archaludon 4. Hippowdon 5. Metagross 6. Blaziken 7. Meowscarada 8. Charizard 9. Dragonite 10. Mawile | H13: 1. H2/A0/B0/C32/D0/S32 (59%) 2. H0/A0/B2/C32/D0/S32 (8.4%) 3. H6/A0/B1/C32/D0/S27 (4.3%) 4. H0/A0/B1/C32/D1/S32 (2.8%) 5. H0/A0/B0/C32/D2/S32 (2.7%) 6. H2/A0/B1/C32/D0/S31 (2.4%) 7. H8/A0/B0/C32/D0/S26 (2.1%) 8. H6/A0/B0/C32/D0/S28 (1.5%) 9. H16/A0/B0/C28/D1/S21 (1.5%) 10. H0/A2/B0/C32/D0/S32 (1.4%) | I13: No significant change this update | J13: 1. Dark Pulse (86.9%) 2. Ice Beam (84.4%) 3. Water Shuriken (68.3%) 4. Sludge Wave (68.3%) 5. Surf (46.8%) | K13: 6. Grass Knot (7.9%) 7. Hydro Pump (6.6%) 8. Mud Shot (4.6%) 9. Toxic Spikes (4.5%) 10. U-turn (2.4%) | L13: 1. Greninjite (46.9%) 2. Focus Sash (44.3%) 3. Life Orb (4.1%) 4. Choice Scarf (3.5%) 5. Expert Belt (0.6%) | M13: 6. Light Ball (0.2%) 7. Mystic Water (0.1%) 8. King's Rock (0.1%) 9. Focus Band (0%) 10. Bright Powder (0%) | N13: 1. Timid +S -A (52%) 2. Modest +C -A (42.8%) 3. Naive +S -D (2.5%) 4. Rash +C -D (0.8%) 5. Hasty +S -B (0.7%) | O13: 6. Mild +C -B (0.5%) 7. Jolly +S -C (0.3%) 8. Naughty +A -D (0.2%) 9. Adamant +A -C (0.1%) 10. Sassy +D -S (0%) | P13: 1. H2/A0/B0/C32/D0/S32 (59%) 2. H0/A0/B2/C32/D0/S32 (8.4%) 3. H6/A0/B1/C32/D0/S27 (4.3%) 4. H0/A0/B1/C32/D1/S32 (2.8%) 5. H0/A0/B0/C32/D2/S32 (2.7%) | Q13: 6. H2/A0/B1/C32/D0/S31 (2.4%) 7. H8/A0/B0/C32/D0/S26 (2.1%) 8. H6/A0/B0/C32/D0/S28 (1.5%) 9. H16/A0/B0/C28/D1/S21 (1.5%) 10. H0/A2/B0/C32/D0/S32 (1.4%) | R13: 1. Mimikyu 2. Garchomp 3. Archaludon 4. Hippowdon 5. Metagross | S13: 6. Blaziken 7. Meowscarada 8. Charizard 9. Dragonite 10. Mawile
... A62: 61 | B62: Milotic | C62: 1. Recover (96.9%) 2. Scald (96.6%) 3. Mirror Coat (67.5%) 4. Ice Beam (64.5%) 5. Haze (36.9%) 6. Alluring Voice (4.8%) 7. Coil (4.5%) 8. Hypnosis (4.1%) 9. Icy Wind (3.4%) 10. Flip Turn (2.9%) | D62: 1. Leftovers (65.8%) 2. Sitrus Berry (18.2%) 3. Lum Berry (3%) 4. Wacan Berry (2.6%) 5. Focus Sash (1.4%) 6. Expert Belt (1.1%) 7. Shell Bell (1%) 8. Bright Powder (1%) 9. Rindo Berry (0.9%) 10. Mystic Water (0.8%) | E62: 1. Competitive (71.4%) 2. Marvel Scale (19.2%) 3. Cute Charm (9.4%) | F62: 1. Bold +B -A (62.8%) 2. Calm +D -A (26.7%) 3. Modest +C -A (6.8%) 4. Relaxed +B -S (1.8%) 5. Sassy +D -S (0.8%) 6. Quiet +C -S (0.4%) 7. Jolly +S -C (0.3%) 8. Mild +C -B (0.1%) 9. Impish +B -C (0.1%) 10. Careful +D -C (0.1%) | G62: 1. Garchomp 2. Mimikyu 3. Metagross 4. Hydreigon 5. Meowscarada 6. Gengar 7. Mawile 8. Blaziken 9. Delphox 10. Charizard | H62: 1. H32/A0/B32/C0/D2/S0 (25.5%) 2. H32/A0/B32/C1/D1/S0 (6.2%) 3. H31/A0/B32/C0/D3/S0 (5.5%) 4. H32/A0/B32/C2/D0/S0 (5.5%) 5. H32/A0/B0/C2/D32/S0 (4.8%) 6. H32/A0/B2/C0/D32/S0 (3.6%) 7. H32/A0/B32/C0/D0/S2 (3.1%) 8. H2/A0/B32/C0/D32/S0 (2.9%) 9. H32/A0/B15/C19/D0/S0 (1.9%) 10. H32/A0/B2/C32/D0/S0 (1.7%) | I62: No significant change this update | J62: 1. Recover (96.9%) 2. Scald (96.6%) 3. Mirror Coat (67.5%) 4. Ice Beam (64.5%) 5. Haze (36.9%) | K62: 6. Alluring Voice (4.8%) 7. Coil (4.5%) 8. Hypnosis (4.1%) 9. Icy Wind (3.4%) 10. Flip Turn (2.9%) | L62: 1. Leftovers (65.8%) 2. Sitrus Berry (18.2%) 3. Lum Berry (3%) 4. Wacan Berry (2.6%) 5. Focus Sash (1.4%) | M62: 6. Expert Belt (1.1%) 7. Shell Bell (1%) 8. Bright Powder (1%) 9. Rindo Berry (0.9%) 10. Mystic Water (0.8%) | N62: 1. Bold +B -A (62.8%) 2. Calm +D -A (26.7%) 3. Modest +C -A (6.8%) 4. Relaxed +B -S (1.8%) 5. Sassy +D -S (0.8%) | O62: 6. Quiet +C -S (0.4%) 7. Jolly +S -C (0.3%) 8. Mild +C -B (0.1%) 9. Impish +B -C (0.1%) 10. Careful +D -C (0.1%) | P62: 1. H32/A0/B32/C0/D2/S0 (25.5%) 2. H32/A0/B32/C1/D1/S0 (6.2%) 3. H31/A0/B32/C0/D3/S0 (5.5%) 4. H32/A0/B32/C2/D0/S0 (5.5%) 5. H32/A0/B0/C2/D32/S0 (4.8%) | Q62: 6. H32/A0/B2/C0/D32/S0 (3.6%) 7. H32/A0/B32/C0/D0/S2 (3.1%) 8. H2/A0/B32/C0/D32/S0 (2.9%) 9. H32/A0/B15/C19/D0/S0 (1.9%) 10. H32/A0/B2/C32/D0/S0 (1.7%) | R62: 1. Garchomp 2. Mimikyu 3. Metagross 4. Hydreigon 5. Meowscarada | S62: 6. Gengar 7. Mawile 8. Blaziken 9. Delphox 10. Charizard
A63: 62 | B63: Ditto | C63: 1. Transform (100%) | D63: 1. Choice Scarf (79.5%) 2. Quick Claw (8.7%) 3. Focus Sash (8%) 4. Bright Powder (1.5%) 5. Life Orb (0.8%) 6. Sitrus Berry (0.7%) 7. Leftovers (0.4%) 8. Focus Band (0.1%) 9. Expert Belt (0.1%) 10. Lum Berry (0%) | E63: 1. Imposter (99.6%) 2. Limber (0.4%) | F63: 1. Relaxed +B -S (27.1%) 2. Timid +S -A (9.3%) 3. Sassy +D -S (7.7%) 4. Serious (7.4%) 5. Naive +S -D (6.6%) 6. Brave +A -S (5.8%) 7. Jolly +S -C (4.8%) 8. Quiet +C -S (4.2%) 9. Hasty +S -B (3.2%) 10. Calm +D -A (3%) | G63: 1. Garchomp 2. Mimikyu 3. Archaludon 4. Metagross 5. Primarina 6. Charizard 7. Dragonite 8. Raichu 9. Umbreon 10. Gyarados | H63: 1. H32/A0/B0/C0/D0/S0 (20.4%) 2. H32/A0/B32/C0/D2/S0 (12.4%) 3. H32/A0/B2/C0/D32/S0 (8.1%) 4. H32/A2/B32/C0/D0/S0 (7.7%) 5. H32/A0/B2/C0/D0/S32 (7.3%) 6. H32/A0/B0/C0/D0/S32 (5.2%) 7. H32/A2/B0/C0/D0/S32 (4.4%) 8. H32/A0/B0/C0/D2/S32 (3.1%) 9. H32/A0/B32/C0/D0/S0 (2.6%) 10. H32/A0/B0/C2/D0/S32 (2.5%) | I63: No significant change this update | J63: 1. Transform (100%) | L63: 1. Choice Scarf (79.5%) 2. Quick Claw (8.7%) 3. Focus Sash (8%) 4. Bright Powder (1.5%) 5. Life Orb (0.8%) | M63: 6. Sitrus Berry (0.7%) 7. Leftovers (0.4%) 8. Focus Band (0.1%) 9. Expert Belt (0.1%) 10. Lum Berry (0%) | N63: 1. Relaxed +B -S (27.1%) 2. Timid +S -A (9.3%) 3. Sassy +D -S (7.7%) 4. Serious (7.4%) 5. Naive +S -D (6.6%) | O63: 6. Brave +A -S (5.8%) 7. Jolly +S -C (4.8%) 8. Quiet +C -S (4.2%) 9. Hasty +S -B (3.2%) 10. Calm +D -A (3%) | P63: 1. H32/A0/B0/C0/D0/S0 (20.4%) 2. H32/A0/B32/C0/D2/S0 (12.4%) 3. H32/A0/B2/C0/D32/S0 (8.1%) 4. H32/A2/B32/C0/D0/S0 (7.7%) 5. H32/A0/B2/C0/D0/S32 (7.3%) | Q63: 6. H32/A0/B0/C0/D0/S32 (5.2%) 7. H32/A2/B0/C0/D0/S32 (4.4%) 8. H32/A0/B0/C0/D2/S32 (3.1%) 9. H32/A0/B32/C0/D0/S0 (2.6%) 10. H32/A0/B0/C2/D0/S32 (2.5%) | R63: 1. Garchomp 2. Mimikyu 3. Archaludon 4. Metagross 5. Primarina | S63: 6. Charizard 7. Dragonite 8. Raichu 9. Umbreon 10. Gyarados
A64: 63 | B64: Azumarill | C64: 1. Play Rough (93.4%) 2. Aqua Jet (93.2%) 3. Liquidation (62.3%) 4. Belly Drum (55.5%) 5. Superpower (29.8%) 6. Knock Off (15.5%) 7. Brick Break (11.6%) 8. Perish Song (5.9%) 9. Ice Spinner (5.5%) 10. Encore (5%) | D64: 1. Sitrus Berry (70.2%) 2. Life Orb (8.1%) 3. Lum Berry (7%) 4. Mystic Water (3.6%) 5. Leftovers (3.4%) 6. Wacan Berry (2.4%) 7. Expert Belt (1.8%) 8. Chesto Berry (1.2%) 9. Focus Sash (0.9%) 10. Quick Claw (0.4%) | E64: 1. Huge Power (94.2%) 2. Sap Sipper (5.7%) 3. Thick Fat (0.2%) | F64: 1. Adamant +A -C (91.1%) 2. Brave +A -S (1.7%) 3. Bold +B -A (1.7%) 4. Sassy +D -S (1.4%) 5. Impish +B -C (0.8%) 6. Jolly +S -C (0.7%) 7. Relaxed +B -S (0.7%) 8. Careful +D -C (0.6%) 9. Quiet +C -S (0.6%) 10. Calm +D -A (0.5%) | G64: 1. Garchomp 2. Charizard 3. Raichu 4. Hydreigon 5. Metagross 6. Gengar 7. Meowscarada 8. Mimikyu 9. Delphox 10. Archaludon | H64: 1. H32/A32/B0/C0/D0/S2 (15.7%) 2. H31/A32/B0/C0/D0/S3 (12.2%) 3. H31/A32/B3/C0/D0/S0 (6.4%) 4. H32/A32/B2/C0/D0/S0 (5.3%) 5. H32/A32/B0/C0/D2/S0 (4.1%) 6. H32/A32/B1/C0/D1/S0 (3.3%) 7. H29/A32/B3/C0/D2/S0 (2.8%) 8. H15/A32/B0/C0/D0/S19 (2.3%) 9. H31/A32/B0/C0/D3/S0 (2.1%) 10. H32/A0/B32/C0/D2/S0 (2%) | I64: No significant change this update | J64: 1. Play Rough (93.4%) 2. Aqua Jet (93.2%) 3. Liquidation (62.3%) 4. Belly Drum (55.5%) 5. Superpower (29.8%) | K64: 6. Knock Off (15.5%) 7. Brick Break (11.6%) 8. Perish Song (5.9%) 9. Ice Spinner (5.5%) 10. Encore (5%) | L64: 1. Sitrus Berry (70.2%) 2. Life Orb (8.1%) 3. Lum Berry (7%) 4. Mystic Water (3.6%) 5. Leftovers (3.4%) | M64: 6. Wacan Berry (2.4%) 7. Expert Belt (1.8%) 8. Chesto Berry (1.2%) 9. Focus Sash (0.9%) 10. Quick Claw (0.4%) | N64: 1. Adamant +A -C (91.1%) 2. Brave +A -S (1.7%) 3. Bold +B -A (1.7%) 4. Sassy +D -S (1.4%) 5. Impish +B -C (0.8%) | O64: 6. Jolly +S -C (0.7%) 7. Relaxed +B -S (0.7%) 8. Careful +D -C (0.6%) 9. Quiet +C -S (0.6%) 10. Calm +D -A (0.5%) | P64: 1. H32/A32/B0/C0/D0/S2 (15.7%) 2. H31/A32/B0/C0/D0/S3 (12.2%) 3. H31/A32/B3/C0/D0/S0 (6.4%) 4. H32/A32/B2/C0/D0/S0 (5.3%) 5. H32/A32/B0/C0/D2/S0 (4.1%) | Q64: 6. H32/A32/B1/C0/D1/S0 (3.3%) 7. H29/A32/B3/C0/D2/S0 (2.8%) 8. H15/A32/B0/C0/D0/S19 (2.3%) 9. H31/A32/B0/C0/D3/S0 (2.1%) 10. H32/A0/B32/C0/D2/S0 (2%) | R64: 1. Garchomp 2. Charizard 3. Raichu 4. Hydreigon 5. Metagross | S64: 6. Gengar 7. Meowscarada 8. Mimikyu 9. Delphox 10. Archaludon
A65: 64 | B65: Sceptile | C65: 1. Dragon Pulse (88.9%) 2. Earth Power (83.1%) 3. Leaf Storm (77.9%) 4. Shed Tail (56.2%) 5. Energy Ball (18.6%) 6. Substitute (17.9%) 7. Vacuum Wave (17.3%) 8. Focus Blast (12.4%) 9. Endeavor (5.9%) 10. Giga Drain (3.3%) | D65: 1. Sceptilite (84.4%) 2. Focus Sash (5.8%) 3. Sitrus Berry (4.2%) 4. White Herb (1.4%) 5. Choice Scarf (1.3%) 6. Leftovers (0.4%) 7. Oran Berry (0.3%) 8. Light Ball (0.1%) 9. Bright Powder (0.1%) 10. Life Orb (0.1%) | E65: 1. Overgrow (83.8%) 2. Unburden (16.2%) | F65: 1. Timid +S -A (84.6%) 2. Modest +C -A (10%) 3. Bold +B -A (1.3%) 4. Naive +S -D (1.1%) 5. Adamant +A -C (0.8%) 6. Hasty +S -B (0.4%) 7. Lonely +A -B (0.4%) 8. Mild +C -B (0.3%) 9. Jolly +S -C (0.3%) 10. Relaxed +B -S (0.3%) | G65: 1. Garchomp 2. Hippowdon 3. Mimikyu 4. Primarina 5. Blaziken 6. Archaludon 7. Gyarados 8. Ceruledge 9. Greninja 10. Skeledirge | H65: 1. H2/A0/B0/C32/D0/S32 (70.3%) 2. H0/A0/B2/C32/D0/S32 (8.1%) 3. H0/A0/B0/C32/D2/S32 (3.7%) 4. H4/A0/B0/C32/D0/S30 (1.5%) 5. H1/A0/B1/C32/D0/S32 (1.4%) 6. H1/A0/B2/C31/D0/S32 (1.2%) 7. H3/A0/B0/C32/D0/S31 (1%) 8. H0/A2/B0/C32/D0/S32 (1%) 9. H2/A0/B1/C32/D0/S31 (0.9%) 10. H19/A0/B0/C32/D0/S15 (0.9%) | I65: No significant change this update | J65: 1. Dragon Pulse (88.9%) 2. Earth Power (83.1%) 3. Leaf Storm (77.9%) 4. Shed Tail (56.2%) 5. Energy Ball (18.6%) | K65: 6. Substitute (17.9%) 7. Vacuum Wave (17.3%) 8. Focus Blast (12.4%) 9. Endeavor (5.9%) 10. Giga Drain (3.3%) | L65: 1. Sceptilite (84.4%) 2. Focus Sash (5.8%) 3. Sitrus Berry (4.2%) 4. White Herb (1.4%) 5. Choice Scarf (1.3%) | M65: 6. Leftovers (0.4%) 7. Oran Berry (0.3%) 8. Light Ball (0.1%) 9. Bright Powder (0.1%) 10. Life Orb (0.1%) | N65: 1. Timid +S -A (84.6%) 2. Modest +C -A (10%) 3. Bold +B -A (1.3%) 4. Naive +S -D (1.1%) 5. Adamant +A -C (0.8%) | O65: 6. Hasty +S -B (0.4%) 7. Lonely +A -B (0.4%) 8. Mild +C -B (0.3%) 9. Jolly +S -C (0.3%) 10. Relaxed +B -S (0.3%) | P65: 1. H2/A0/B0/C32/D0/S32 (70.3%) 2. H0/A0/B2/C32/D0/S32 (8.1%) 3. H0/A0/B0/C32/D2/S32 (3.7%) 4. H4/A0/B0/C32/D0/S30 (1.5%) 5. H1/A0/B1/C32/D0/S32 (1.4%) | Q65: 6. H1/A0/B2/C31/D0/S32 (1.2%) 7. H3/A0/B0/C32/D0/S31 (1%) 8. H0/A2/B0/C32/D0/S32 (1%) 9. H2/A0/B1/C32/D0/S31 (0.9%) 10. H19/A0/B0/C32/D0/S15 (0.9%) | R65: 1. Garchomp 2. Hippowdon 3. Mimikyu 4. Primarina 5. Blaziken | S65: 6. Archaludon 7. Gyarados 8. Ceruledge 9. Greninja 10. Skeledirge
A66: 65 | B66: Zoroark-Hisui | C66: 1. Bitter Malice (61.8%) 2. Icy Wind (57.1%) 3. Flamethrower (35.5%) 4. Shadow Ball (34.2%) 5. Focus Blast (33.5%) 6. Taunt (23.3%) 7. Shadow Sneak (22.7%) 8. Hyper Beam (14.6%) 9. Hyper Voice (13.4%) 10. Memento (12.9%) | D66: 1. Focus Sash (69.5%) 2. Choice Scarf (13.2%) 3. Life Orb (6.6%) 4. Expert Belt (2.8%) 5. Wise Glasses (1.8%) 6. Bright Powder (1%) 7. Colbur Berry (0.9%) 8. Sitrus Berry (0.6%) 9. Spell Tag (0.6%) 10. Lum Berry (0.6%) | E66: 1. Illusion (100%) | F66: 1. Timid +S -A (58.3%) 2. Modest +C -A (22.4%) 3. Naive +S -D (11%) 4. Hasty +S -B (4.2%) 5. Rash +C -D (1.3%) 6. Relaxed +B -S (0.7%) 7. Jolly +S -C (0.5%) 8. Mild +C -B (0.4%) 9. Sassy +D -S (0.4%) 10. Quiet +C -S (0.4%) | G66: 1. Garchomp 2. Archaludon 3. Meowscarada 4. Metagross 5. Mimikyu 6. Blaziken 7. Gyarados 8. Starmie 9. Staraptor 10. Raichu | H66: 1. H2/A0/B0/C32/D0/S32 (46.2%) 2. H1/A0/B1/C32/D0/S32 (13.5%) 3. H0/A2/B0/C32/D0/S32 (10.6%) 4. H0/A0/B2/C32/D0/S32 (4.3%) 5. H0/A0/B0/C32/D0/S32 (4.1%) 6. H1/A0/B0/C32/D1/S32 (3.4%) 7. H0/A0/B0/C32/D2/S32 (2%) 8. H1/A0/B0/C32/D0/S32 (1.8%) 9. H1/A1/B0/C32/D0/S32 (1.5%) 10. H0/A0/B1/C32/D1/S32 (0.8%) | I66: No significant change this update | J66: 1. Bitter Malice (61.8%) 2. Icy Wind (57.1%) 3. Flamethrower (35.5%) 4. Shadow Ball (34.2%) 5. Focus Blast (33.5%) | K66: 6. Taunt (23.3%) 7. Shadow Sneak (22.7%) 8. Hyper Beam (14.6%) 9. Hyper Voice (13.4%) 10. Memento (12.9%) | L66: 1. Focus Sash (69.5%) 2. Choice Scarf (13.2%) 3. Life Orb (6.6%) 4. Expert Belt (2.8%) 5. Wise Glasses (1.8%) | M66: 6. Bright Powder (1%) 7. Colbur Berry (0.9%) 8. Sitrus Berry (0.6%) 9. Spell Tag (0.6%) 10. Lum Berry (0.6%) | N66: 1. Timid +S -A (58.3%) 2. Modest +C -A (22.4%) 3. Naive +S -D (11%) 4. Hasty +S -B (4.2%) 5. Rash +C -D (1.3%) | O66: 6. Relaxed +B -S (0.7%) 7. Jolly +S -C (0.5%) 8. Mild +C -B (0.4%) 9. Sassy +D -S (0.4%) 10. Quiet +C -S (0.4%) | P66: 1. H2/A0/B0/C32/D0/S32 (46.2%) 2. H1/A0/B1/C32/D0/S32 (13.5%) 3. H0/A2/B0/C32/D0/S32 (10.6%) 4. H0/A0/B2/C32/D0/S32 (4.3%) 5. H0/A0/B0/C32/D0/S32 (4.1%) | Q66: 6. H1/A0/B0/C32/D1/S32 (3.4%) 7. H0/A0/B0/C32/D2/S32 (2%) 8. H1/A0/B0/C32/D0/S32 (1.8%) 9. H1/A1/B0/C32/D0/S32 (1.5%) 10. H0/A0/B1/C32/D1/S32 (0.8%) | R66: 1. Garchomp 2. Archaludon 3. Meowscarada 4. Metagross 5. Mimikyu | S66: 6. Blaziken 7. Gyarados 8. Starmie 9. Staraptor 10. Raichu
A67: 66 | B67: Gallade | C67: 1. Sacred Sword (95.4%) 2. Psycho Cut (83.1%) 3. Leaf Blade (73.8%) 4. Shadow Sneak (54.6%) 5. Night Slash (13.8%) 6. Triple Axel (12.1%) 7. Shadow Claw (11.7%) 8. Destiny Bond (6%) 9. Aqua Cutter (5.9%) 10. Ice Punch (5%) | D67: 1. Focus Sash (41.8%) 2. Choice Scarf (18.2%) 3. Scope Lens (13.1%) 4. Lum Berry (9%) 5. Galladite (7.6%) 6. Life Orb (4.6%) 7. Expert Belt (2%) 8. Sitrus Berry (1%) 9. Muscle Band (0.9%) 10. Quick Claw (0.5%) | E67: 1. Sharpness (96.6%) 2. Justified (2.9%) 3. Steadfast (0.5%) | F67: 1. Adamant +A -C (63.2%) 2. Jolly +S -C (34.1%) 3. Careful +D -C (1%) 4. Sassy +D -S (0.8%) 5. Brave +A -S (0.6%) 6. Impish +B -C (0.2%) 7. Lonely +A -B (0%) 8. Relaxed +B -S (0%) | G67: 1. Garchomp 2. Meowscarada 3. Mimikyu 4. Primarina 5. Charizard 6. Archaludon 7. Greninja 8. Delphox 9. Gyarados 10. Blaziken | H67: 1. H2/A32/B0/C0/D0/S32 (48.1%) 2. H0/A32/B2/C0/D0/S32 (8.8%) 3. H32/A32/B2/C0/D0/S0 (4.8%) 4. H0/A32/B0/C0/D2/S32 (3.8%) 5. H28/A32/B0/C0/D0/S6 (3.6%) 6. H2/A32/B32/C0/D0/S0 (1.9%) 7. H2/A32/B0/C0/D32/S0 (1.9%) 8. H0/A32/B0/C0/D0/S32 (1.6%) 9. H0/A26/B8/C0/D0/S32 (1%) 10. H18/A32/B16/C0/D0/S0 (1%) | I67: No significant change this update | J67: 1. Sacred Sword (95.4%) 2. Psycho Cut (83.1%) 3. Leaf Blade (73.8%) 4. Shadow Sneak (54.6%) 5. Night Slash (13.8%) | K67: 6. Triple Axel (12.1%) 7. Shadow Claw (11.7%) 8. Destiny Bond (6%) 9. Aqua Cutter (5.9%) 10. Ice Punch (5%) | L67: 1. Focus Sash (41.8%) 2. Choice Scarf (18.2%) 3. Scope Lens (13.1%) 4. Lum Berry (9%) 5. Galladite (7.6%) | M67: 6. Life Orb (4.6%) 7. Expert Belt (2%) 8. Sitrus Berry (1%) 9. Muscle Band (0.9%) 10. Quick Claw (0.5%) | N67: 1. Adamant +A -C (63.2%) 2. Jolly +S -C (34.1%) 3. Careful +D -C (1%) 4. Sassy +D -S (0.8%) | O67: 5. Brave +A -S (0.6%) 6. Impish +B -C (0.2%) 7. Lonely +A -B (0%) 8. Relaxed +B -S (0%) | P67: 1. H2/A32/B0/C0/D0/S32 (48.1%) 2. H0/A32/B2/C0/D0/S32 (8.8%) 3. H32/A32/B2/C0/D0/S0 (4.8%) 4. H0/A32/B0/C0/D2/S32 (3.8%) 5. H28/A32/B0/C0/D0/S6 (3.6%) | Q67: 6. H2/A32/B32/C0/D0/S0 (1.9%) 7. H2/A32/B0/C0/D32/S0 (1.9%) 8. H0/A32/B0/C0/D0/S32 (1.6%) 9. H0/A26/B8/C0/D0/S32 (1%) 10. H18/A32/B16/C0/D0/S0 (1%) | R67: 1. Garchomp 2. Meowscarada 3. Mimikyu 4. Primarina 5. Charizard | S67: 6. Archaludon 7. Greninja 8. Delphox 9. Gyarados 10. Blaziken
A68: 67 | B68: Goodra-Hisui | C68: 1. Draco Meteor (63.8%) 2. Flamethrower (50.6%) 3. Heavy Slam (43.2%) 4. Flash Cannon (38.5%) 5. Dragon Tail (37.6%) 6. Thunderbolt (27.9%) 7. Shelter (22.2%) 8. Body Press (21.2%) 9. Ice Beam (15.1%) 10. Acid Spray (13.7%) | D68: 1. Leftovers (64.1%) 2. Sitrus Berry (11.5%) 3. Chesto Berry (5.1%) 4. Shuca Berry (4.9%) 5. Expert Belt (3.5%) 6. Dragon Fang (2.8%) 7. White Herb (2.3%) 8. Life Orb (1.7%) 9. Focus Sash (1%) 10. Wise Glasses (0.7%) | E68: 1. Gooey (48.6%) 2. Sap Sipper (25.9%) 3. Shell Armor (25.5%) | F68: 1. Sassy +D -S (37.3%) 2. Modest +C -A (20.7%) 3. Calm +D -A (14.7%) 4. Bold +B -A (13%) 5. Quiet +C -S (5.7%) 6. Impish +B -C (2.9%) 7. Relaxed +B -S (1.9%) 8. Careful +D -C (1.6%) 9. Adamant +A -C (1.3%) 10. Serious (0.5%) | G68: 1. Hippowdon 2. Meganium 3. Blastoise 4. Toxapex 5. Gholdengo 6. Garchomp 7. Gyarados 8. Skeledirge 9. Meowscarada 10. Mimikyu | H68: 1. H22/A11/B0/C1/D32/S0 (25.7%) 2. H32/A0/B32/C0/D2/S0 (10.4%) 3. H32/A0/B2/C32/D0/S0 (7.1%) 4. H32/A0/B0/C32/D2/S0 (7.1%) 5. H32/A0/B32/C0/D0/S2 (2.9%) 6. H32/A0/B0/C32/D0/S2 (2.7%) 7. H22/A11/B1/C0/D32/S0 (2.3%) 8. H2/A0/B0/C32/D32/S0 (1.9%) 9. H22/A0/B11/C1/D32/S0 (1.7%) 10. H22/A12/B0/C0/D32/S0 (1.6%) | I68: No significant change this update | J68: 1. Draco Meteor (63.8%) 2. Flamethrower (50.6%) 3. Heavy Slam (43.2%) 4. Flash Cannon (38.5%) 5. Dragon Tail (37.6%) | K68: 6. Thunderbolt (27.9%) 7. Shelter (22.2%) 8. Body Press (21.2%) 9. Ice Beam (15.1%) 10. Acid Spray (13.7%) | L68: 1. Leftovers (64.1%) 2. Sitrus Berry (11.5%) 3. Chesto Berry (5.1%) 4. Shuca Berry (4.9%) 5. Expert Belt (3.5%) | M68: 6. Dragon Fang (2.8%) 7. White Herb (2.3%) 8. Life Orb (1.7%) 9. Focus Sash (1%) 10. Wise Glasses (0.7%) | N68: 1. Sassy +D -S (37.3%) 2. Modest +C -A (20.7%) 3. Calm +D -A (14.7%) 4. Bold +B -A (13%) 5. Quiet +C -S (5.7%) | O68: 6. Impish +B -C (2.9%) 7. Relaxed +B -S (1.9%) 8. Careful +D -C (1.6%) 9. Adamant +A -C (1.3%) 10. Serious (0.5%) | P68: 1. H22/A11/B0/C1/D32/S0 (25.7%) 2. H32/A0/B32/C0/D2/S0 (10.4%) 3. H32/A0/B2/C32/D0/S0 (7.1%) 4. H32/A0/B0/C32/D2/S0 (7.1%) 5. H32/A0/B32/C0/D0/S2 (2.9%) | Q68: 6. H32/A0/B0/C32/D0/S2 (2.7%) 7. H22/A11/B1/C0/D32/S0 (2.3%) 8. H2/A0/B0/C32/D32/S0 (1.9%) 9. H22/A0/B11/C1/D32/S0 (1.7%) 10. H22/A12/B0/C0/D32/S0 (1.6%) | R68: 1. Hippowdon 2. Meganium 3. Blastoise 4. Toxapex 5. Gholdengo | S68: 6. Garchomp 7. Gyarados 8. Skeledirge 9. Meowscarada 10. Mimikyu
A69: 68 | B69: Araquanid | C69: 1. Sticky Web (89.3%) 2. Liquidation (78.3%) 3. Mirror Coat (70.6%) 4. Leech Life (26.8%) 5. Lunge (20.4%) 6. Surf (18.8%) 7. Icy Wind (13.9%) 8. Endeavor (12.4%) 9. Ice Beam (10.7%) 10. Pounce (9.8%) | D69: 1. Sitrus Berry (44.7%) 2. Mystic Water (14.2%) 3. Focus Sash (12%) 4. Leftovers (10.2%) 5. Wacan Berry (5.3%) 6. Life Orb (3.6%) 7. Lum Berry (2.6%) 8. Quick Claw (2.1%) 9. Mental Herb (1.2%) 10. Chesto Berry (0.8%) | E69: 1. Water Bubble (99.1%) 2. Water Absorb (0.9%) | F69: 1. Adamant +A -C (38.5%) 2. Modest +C -A (14.8%) 3. Impish +B -C (10.8%) 4. Careful +D -C (8%) 5. Jolly +S -C (6.7%) 6. Relaxed +B -S (5.7%) 7. Brave +A -S (4.5%) 8. Quiet +C -S (2.9%) 9. Bold +B -A (2.8%) 10. Calm +D -A (1.8%) | G69: 1. Garchomp 2. Mimikyu 3. Raichu 4. Metagross 5. Hippowdon 6. Scizor 7. Meowscarada 8. Gyarados 9. Charizard 10. Archaludon | H69: 1. H32/A32/B2/C0/D0/S0 (22.9%) 2. H32/A0/B32/C0/D2/S0 (7%) 3. H16/A18/B0/C0/D0/S32 (4.9%) 4. H32/A0/B2/C32/D0/S0 (4.5%) 5. H32/A32/B0/C0/D2/S0 (3.9%) 6. H32/A0/B0/C32/D2/S0 (3.6%) 7. H28/A0/B0/C32/D0/S6 (3.3%) 8. H28/A32/B0/C0/D0/S6 (2.4%) 9. H32/A2/B32/C0/D0/S0 (2.3%) 10. H32/A0/B28/C0/D6/S0 (2.1%) | I69: No significant change this update | J69: 1. Sticky Web (89.3%) 2. Liquidation (78.3%) 3. Mirror Coat (70.6%) 4. Leech Life (26.8%) 5. Lunge (20.4%) | K69: 6. Surf (18.8%) 7. Icy Wind (13.9%) 8. Endeavor (12.4%) 9. Ice Beam (10.7%) 10. Pounce (9.8%) | L69: 1. Sitrus Berry (44.7%) 2. Mystic Water (14.2%) 3. Focus Sash (12%) 4. Leftovers (10.2%) 5. Wacan Berry (5.3%) | M69: 6. Life Orb (3.6%) 7. Lum Berry (2.6%) 8. Quick Claw (2.1%) 9. Mental Herb (1.2%) 10. Chesto Berry (0.8%) | N69: 1. Adamant +A -C (38.5%) 2. Modest +C -A (14.8%) 3. Impish +B -C (10.8%) 4. Careful +D -C (8%) 5. Jolly +S -C (6.7%) | O69: 6. Relaxed +B -S (5.7%) 7. Brave +A -S (4.5%) 8. Quiet +C -S (2.9%) 9. Bold +B -A (2.8%) 10. Calm +D -A (1.8%) | P69: 1. H32/A32/B2/C0/D0/S0 (22.9%) 2. H32/A0/B32/C0/D2/S0 (7%) 3. H16/A18/B0/C0/D0/S32 (4.9%) 4. H32/A0/B2/C32/D0/S0 (4.5%) 5. H32/A32/B0/C0/D2/S0 (3.9%) | Q69: 6. H32/A0/B0/C32/D2/S0 (3.6%) 7. H28/A0/B0/C32/D0/S6 (3.3%) 8. H28/A32/B0/C0/D0/S6 (2.4%) 9. H32/A2/B32/C0/D0/S0 (2.3%) 10. H32/A0/B28/C0/D6/S0 (2.1%) | R69: 1. Garchomp 2. Mimikyu 3. Raichu 4. Metagross 5. Hippowdon | S69: 6. Scizor 7. Meowscarada 8. Gyarados 9. Charizard 10. Archaludon
A70: 69 | B70: Vivillon | C70: 1. Sleep Powder (98.3%) 2. Hurricane (97.5%) 3. Quiver Dance (96.9%) 4. Substitute (91.5%) 5. Bug Buzz (4.9%) 6. Tailwind (2.1%) 7. Rage Powder (1.7%) 8. Protect (1.5%) 9. Pollen Puff (1.5%) 10. Giga Drain (1.4%) | D70: 1. Leftovers (86.5%) 2. Focus Sash (7.5%) 3. Wide Lens (1%) 4. Bright Powder (0.8%) 5. Quick Claw (0.8%) 6. Wise Glasses (0.8%) 7. Choice Scarf (0.2%) 8. Sitrus Berry (0.2%) 9. Life Orb (0.1%) 10. Lum Berry (0.1%) | E70: 1. Compound Eyes (97.7%) 2. Friend Guard (2.3%) 3. Shield Dust (0%) | F70: 1. Timid +S -A (97.6%) 2. Modest +C -A (1.6%) 3. Serious (0.3%) 4. Calm +D -A (0.2%) 5. Quiet +C -S (0.2%) 6. Bold +B -A (0.1%) 7. Hasty +S -B (0%) | G70: 1. Mimikyu 2. Archaludon 3. Greninja 4. Espathra 5. Lopunny 6. Blaziken 7. Garchomp 8. Metagross 9. Gyarados 10. Basculegion | H70: 1. H6/A0/B28/C0/D0/S32 (41%) 2. H2/A0/B0/C32/D0/S32 (21.9%) 3. H6/A0/B0/C28/D0/S32 (12.8%) 4. H0/A0/B2/C32/D0/S32 (3.2%) 5. H32/A0/B0/C2/D0/S32 (2.3%) 6. H32/A0/B1/C0/D1/S32 (1.8%) 7. H0/A0/B0/C32/D0/S32 (1.8%) 8. H32/A0/B0/C0/D2/S32 (1.6%) 9. H18/A0/B0/C16/D0/S32 (1.4%) 10. H32/A0/B2/C0/D0/S32 (1.4%) | I70: No significant change this update | J70: 1. Sleep Powder (98.3%) 2. Hurricane (97.5%) 3. Quiver Dance (96.9%) 4. Substitute (91.5%) 5. Bug Buzz (4.9%) | K70: 6. Tailwind (2.1%) 7. Rage Powder (1.7%) 8. Protect (1.5%) 9. Pollen Puff (1.5%) 10. Giga Drain (1.4%) | L70: 1. Leftovers (86.5%) 2. Focus Sash (7.5%) 3. Wide Lens (1%) 4. Bright Powder (0.8%) 5. Quick Claw (0.8%) | M70: 6. Wise Glasses (0.8%) 7. Choice Scarf (0.2%) 8. Sitrus Berry (0.2%) 9. Life Orb (0.1%) 10. Lum Berry (0.1%) | N70: 1. Timid +S -A (97.6%) 2. Modest +C -A (1.6%) 3. Serious (0.3%) 4. Calm +D -A (0.2%) | O70: 5. Quiet +C -S (0.2%) 6. Bold +B -A (0.1%) 7. Hasty +S -B (0%) | P70: 1. H6/A0/B28/C0/D0/S32 (41%) 2. H2/A0/B0/C32/D0/S32 (21.9%) 3. H6/A0/B0/C28/D0/S32 (12.8%) 4. H0/A0/B2/C32/D0/S32 (3.2%) 5. H32/A0/B0/C2/D0/S32 (2.3%) | Q70: 6. H32/A0/B1/C0/D1/S32 (1.8%) 7. H0/A0/B0/C32/D0/S32 (1.8%) 8. H32/A0/B0/C0/D2/S32 (1.6%) 9. H18/A0/B0/C16/D0/S32 (1.4%) 10. H32/A0/B2/C0/D0/S32 (1.4%) | R70: 1. Mimikyu 2. Archaludon 3. Greninja 4. Espathra 5. Lopunny | S70: 6. Blaziken 7. Garchomp 8. Metagross 9. Gyarados 10. Basculegion
A71: 70 | B71: Sableye | C71: 1. Will-O-Wisp (71.9%) 2. Foul Play (61.1%) 3. Encore (59%) 4. Recover (48.2%) 5. Light Screen (38.8%) 6. Reflect (34.4%) 7. Disable (12.2%) 8. Calm Mind (11.5%) 9. Taunt (9%) 10. Metal Burst (7.3%) | D71: 1. Light Clay (34.4%) 2. Sablenite (34%) 3. Leftovers (13.7%) 4. Focus Sash (5%) 5. Roseli Berry (3.9%) 6. Sitrus Berry (2.8%) 7. Wide Lens (2.6%) 8. Iron Ball (1%) 9. Bright Powder (0.7%) 10. Damp Rock (0.2%) | E71: 1. Prankster (99.6%) 2. Keen Eye (0.2%) 3. Stall (0.1%) | F71: 1. Bold +B -A (38.5%) 2. Impish +B -C (25.5%) 3. Calm +D -A (13.7%) 4. Careful +D -C (9.3%) 5. Relaxed +B -S (6.6%) 6. Sassy +D -S (3.2%) 7. Adamant +A -C (1.4%) 8. Brave +A -S (0.7%) 9. Lonely +A -B (0.3%) 10. Modest +C -A (0.2%) | G71: 1. Garchomp 2. Blaziken 3. Gyarados 4. Metagross 5. Archaludon 6. Mimikyu 7. Primarina 8. Greninja 9. Meowscarada 10. Staraptor | H71: 1. H32/A0/B32/C0/D2/S0 (35.4%) 2. H32/A0/B2/C0/D32/S0 (15.1%) 3. H32/A0/B25/C0/D9/S0 (9.3%) 4. H32/A0/B18/C0/D16/S0 (4.9%) 5. H32/A0/B32/C0/D0/S0 (3.5%) 6. H32/A0/B7/C0/D27/S0 (2.9%) 7. H32/A0/B15/C0/D19/S0 (2.5%) 8. H32/A0/B9/C0/D25/S0 (2.3%) 9. H32/A0/B16/C0/D18/S0 (2%) 10. H32/A0/B32/C0/D0/S2 (2%) | I71: No significant change this update | J71: 1. Will-O-Wisp (71.9%) 2. Foul Play (61.1%) 3. Encore (59%) 4. Recover (48.2%) 5. Light Screen (38.8%) | K71: 6. Reflect (34.4%) 7. Disable (12.2%) 8. Calm Mind (11.5%) 9. Taunt (9%) 10. Metal Burst (7.3%) | L71: 1. Light Clay (34.4%) 2. Sablenite (34%) 3. Leftovers (13.7%) 4. Focus Sash (5%) 5. Roseli Berry (3.9%) | M71: 6. Sitrus Berry (2.8%) 7. Wide Lens (2.6%) 8. Iron Ball (1%) 9. Bright Powder (0.7%) 10. Damp Rock (0.2%) | N71: 1. Bold +B -A (38.5%) 2. Impish +B -C (25.5%) 3. Calm +D -A (13.7%) 4. Careful +D -C (9.3%) 5. Relaxed +B -S (6.6%) | O71: 6. Sassy +D -S (3.2%) 7. Adamant +A -C (1.4%) 8. Brave +A -S (0.7%) 9. Lonely +A -B (0.3%) 10. Modest +C -A (0.2%) | P71: 1. H32/A0/B32/C0/D2/S0 (35.4%) 2. H32/A0/B2/C0/D32/S0 (15.1%) 3. H32/A0/B25/C0/D9/S0 (9.3%) 4. H32/A0/B18/C0/D16/S0 (4.9%) 5. H32/A0/B32/C0/D0/S0 (3.5%) | Q71: 6. H32/A0/B7/C0/D27/S0 (2.9%) 7. H32/A0/B15/C0/D19/S0 (2.5%) 8. H32/A0/B9/C0/D25/S0 (2.3%) 9. H32/A0/B16/C0/D18/S0 (2%) 10. H32/A0/B32/C0/D0/S2 (2%) | R71: 1. Garchomp 2. Blaziken 3. Gyarados 4. Metagross 5. Archaludon | S71: 6. Mimikyu 7. Primarina 8. Greninja 9. Meowscarada 10. Staraptor
A72: 71 | B72: Skarmory | C72: 1. Roost (63.1%) 2. Stealth Rock (45.6%) 3. Brave Bird (36.9%) 4. Whirlwind (36.7%) 5. Body Press (36.3%) 6. Swords Dance (30.8%) 7. Drill Run (28.9%) 8. Iron Head (28.9%) 9. Iron Defense (27.8%) 10. Spikes (19.4%) | D72: 1. Skarmorite (35.8%) 2. Sitrus Berry (28.5%) 3. Leftovers (19.7%) 4. Mental Herb (4.3%) 5. Lum Berry (4%) 6. Bright Powder (2.5%) 7. Life Orb (1.6%) 8. Wacan Berry (0.8%) 9. Metal Coat (0.6%) 10. Black Belt (0.5%) | E72: 1. Sturdy (72.1%) 2. Weak Armor (26.9%) 3. Keen Eye (0.9%) | F72: 1. Impish +B -C (45.8%) 2. Jolly +S -C (22.4%) 3. Adamant +A -C (13.3%) 4. Careful +D -C (8.5%) 5. Bold +B -A (7.2%) 6. Relaxed +B -S (1.3%) 7. Calm +D -A (0.8%) 8. Timid +S -A (0.2%) 9. Serious (0.2%) 10. Brave +A -S (0.2%) | G72: 1. Garchomp 2. Dragalge 3. Archaludon 4. Delphox 5. Mimikyu 6. Meowscarada 7. Blaziken 8. Primarina 9. Skeledirge 10. Umbreon | H72: 1. H32/A0/B32/C0/D2/S0 (21.6%) 2. H32/A0/B32/C0/D0/S2 (8%) 3. H2/A32/B0/C0/D0/S32 (5.3%) 4. H32/A0/B2/C0/D32/S0 (4.8%) 5. H31/A0/B32/C0/D3/S0 (3.3%) 6. H1/A32/B1/C0/D0/S32 (2.6%) 7. H32/A0/B32/C0/D1/S1 (2.2%) 8. H5/A32/B4/C0/D0/S25 (2.2%) 9. H32/A2/B32/C0/D0/S0 (1.9%) 10. H19/A32/B0/C0/D0/S15 (1.9%) | I72: No significant change this update | J72: 1. Roost (63.1%) 2. Stealth Rock (45.6%) 3. Brave Bird (36.9%) 4. Whirlwind (36.7%) 5. Body Press (36.3%) | K72: 6. Swords Dance (30.8%) 7. Drill Run (28.9%) 8. Iron Head (28.9%) 9. Iron Defense (27.8%) 10. Spikes (19.4%) | L72: 1. Skarmorite (35.8%) 2. Sitrus Berry (28.5%) 3. Leftovers (19.7%) 4. Mental Herb (4.3%) 5. Lum Berry (4%) | M72: 6. Bright Powder (2.5%) 7. Life Orb (1.6%) 8. Wacan Berry (0.8%) 9. Metal Coat (0.6%) 10. Black Belt (0.5%) | N72: 1. Impish +B -C (45.8%) 2. Jolly +S -C (22.4%) 3. Adamant +A -C (13.3%) 4. Careful +D -C (8.5%) 5. Bold +B -A (7.2%) | O72: 6. Relaxed +B -S (1.3%) 7. Calm +D -A (0.8%) 8. Timid +S -A (0.2%) 9. Serious (0.2%) 10. Brave +A -S (0.2%) | P72: 1. H32/A0/B32/C0/D2/S0 (21.6%) 2. H32/A0/B32/C0/D0/S2 (8%) 3. H2/A32/B0/C0/D0/S32 (5.3%) 4. H32/A0/B2/C0/D32/S0 (4.8%) 5. H31/A0/B32/C0/D3/S0 (3.3%) | Q72: 6. H1/A32/B1/C0/D0/S32 (2.6%) 7. H32/A0/B32/C0/D1/S1 (2.2%) 8. H5/A32/B4/C0/D0/S25 (2.2%) 9. H32/A2/B32/C0/D0/S0 (1.9%) 10. H19/A32/B0/C0/D0/S15 (1.9%) | R72: 1. Garchomp 2. Dragalge 3. Archaludon 4. Delphox 5. Mimikyu | S72: 6. Meowscarada 7. Blaziken 8. Primarina 9. Skeledirge 10. Umbreon
A73: 72 | B73: Banette | C73: 1. Destiny Bond (99.4%) 2. Poltergeist (96.2%) 3. Shadow Sneak (72.1%) 4. Encore (67.1%) 5. Taunt (23%) 6. Will-O-Wisp (12.5%) 7. Gunk Shot (9.3%) 8. Sucker Punch (4.5%) 9. Swords Dance (2.9%) 10. Curse (2.7%) | D73: 1. Banettite (99.9%) 2. Choice Scarf (0%) | E73: 1. Frisk (90.1%) 2. Insomnia (6.7%) 3. Cursed Body (3.1%) | F73: 1. Adamant +A -C (73.7%) 2. Brave +A -S (20.8%) 3. Careful +D -C (1.5%) 4. Naughty +A -D (1.4%) 5. Bold +B -A (1.1%) 6. Jolly +S -C (1%) 7. Impish +B -C (0.5%) 8. Sassy +D -S (0.1%) | G73: 1. Mimikyu 2. Archaludon 3. Basculegion 4. Primarina 5. Garchomp 6. Meowscarada 7. Greninja 8. Kingambit 9. Corviknight 10. Staraptor | H73: 1. H32/A32/B2/C0/D0/S0 (32.5%) 2. H32/A32/B0/C0/D2/S0 (12.6%) 3. H32/A32/B0/C0/D0/S2 (10.8%) 4. H30/A25/B0/C0/D4/S7 (5.3%) 5. H32/A32/B1/C0/D1/S0 (3%) 6. H32/A25/B0/C0/D8/S1 (1.6%) 7. H20/A15/B0/C0/D31/S0 (1.5%) 8. H32/A28/B6/C0/D0/S0 (1.5%) 9. H30/A32/B0/C0/D0/S4 (1.4%) 10. H32/A0/B32/C0/D0/S0 (1.3%) | I73: No significant change this update | J73: 1. Destiny Bond (99.4%) 2. Poltergeist (96.2%) 3. Shadow Sneak (72.1%) 4. Encore (67.1%) 5. Taunt (23%) | K73: 6. Will-O-Wisp (12.5%) 7. Gunk Shot (9.3%) 8. Sucker Punch (4.5%) 9. Swords Dance (2.9%) 10. Curse (2.7%) | L73: 1. Banettite (99.9%) | M73: 2. Choice Scarf (0%) | N73: 1. Adamant +A -C (73.7%) 2. Brave +A -S (20.8%) 3. Careful +D -C (1.5%) 4. Naughty +A -D (1.4%) | O73: 5. Bold +B -A (1.1%) 6. Jolly +S -C (1%) 7. Impish +B -C (0.5%) 8. Sassy +D -S (0.1%) | P73: 1. H32/A32/B2/C0/D0/S0 (32.5%) 2. H32/A32/B0/C0/D2/S0 (12.6%) 3. H32/A32/B0/C0/D0/S2 (10.8%) 4. H30/A25/B0/C0/D4/S7 (5.3%) 5. H32/A32/B1/C0/D1/S0 (3%) | Q73: 6. H32/A25/B0/C0/D8/S1 (1.6%) 7. H20/A15/B0/C0/D31/S0 (1.5%) 8. H32/A28/B6/C0/D0/S0 (1.5%) 9. H30/A32/B0/C0/D0/S4 (1.4%) 10. H32/A0/B32/C0/D0/S0 (1.3%) | R73: 1. Mimikyu 2. Archaludon 3. Basculegion 4. Primarina 5. Garchomp | S73: 6. Meowscarada 7. Greninja 8. Kingambit 9. Corviknight 10. Staraptor
