Workbook

Sheet 检索
A1: 宝可梦检索（单 / 双 对照） | AB1: 烈咬陆鲨
A2: 输入中文名 → | B2: 烈咬陆鲨 | AB2: 谜拟丘
AB3: 巨金怪
A4: 项目 | B4: 单打 | I4: 双打 | AB4: 铝钢桥龙
A5: 排名 | B5: =IFERROR(INDEX('单打'!A:A,MATCH($B$2,'单打'!$B:$B,0)),"—") | I5: =IFERROR(INDEX('双打'!A:A,MATCH($B$2,'双打'!$B:$B,0)),"—") | AB5: 河马兽
A6: 英文名 | B6: =IFERROR(INDEX('单打'!C:C,MATCH($B$2,'单打'!$B:$B,0)),"—") | I6: =IFERROR(INDEX('双打'!C:C,MATCH($B$2,'双打'!$B:$B,0)),"—") | AB6: 西狮海壬
A7: 招式 | B7: =IFERROR(INDEX('单打'!K:K,MATCH($B$2,'单打'!$B:$B,0)),"—") | E7: =IFERROR(INDEX('单打'!L:L,MATCH($B$2,'单打'!$B:$B,0)),"—") | I7: =IFERROR(INDEX('双打'!K:K,MATCH($B$2,'双打'!$B:$B,0)),"—") | L7: =IFERROR(INDEX('双打'!L:L,MATCH($B$2,'双打'!$B:$B,0)),"—") | AB7: 魔幻假面喵
A8: 道具 | B8: =IFERROR(INDEX('单打'!M:M,MATCH($B$2,'单打'!$B:$B,0)),"—") | E8: =IFERROR(INDEX('单打'!N:N,MATCH($B$2,'单打'!$B:$B,0)),"—") | I8: =IFERROR(INDEX('双打'!M:M,MATCH($B$2,'双打'!$B:$B,0)),"—") | L8: =IFERROR(INDEX('双打'!N:N,MATCH($B$2,'双打'!$B:$B,0)),"—") | AB8: 暴鲤龙
A9: 特性 | B9: =IFERROR(INDEX('单打'!F:F,MATCH($B$2,'单打'!$B:$B,0)),"—") | I9: =IFERROR(INDEX('双打'!F:F,MATCH($B$2,'双打'!$B:$B,0)),"—") | AB9: 妖火红狐
A10: 性格 | B10: =IFERROR(INDEX('单打'!O:O,MATCH($B$2,'单打'!$B:$B,0)),"—") | E10: =IFERROR(INDEX('单打'!P:P,MATCH($B$2,'单打'!$B:$B,0)),"—") | I10: =IFERROR(INDEX('双打'!O:O,MATCH($B$2,'双打'!$B:$B,0)),"—") | L10: =IFERROR(INDEX('双打'!P:P,MATCH($B$2,'双打'!$B:$B,0)),"—") | AB10: 火焰鸡
A11: 努力值 | B11: =IFERROR(INDEX('单打'!Q:Q,MATCH($B$2,'单打'!$B:$B,0)),"—") | E11: =IFERROR(INDEX('单打'!R:R,MATCH($B$2,'单打'!$B:$B,0)),"—") | I11: =IFERROR(INDEX('双打'!Q:Q,MATCH($B$2,'双打'!$B:$B,0)),"—") | L11: =IFERROR(INDEX('双打'!R:R,MATCH($B$2,'双打'!$B:$B,0)),"—") | AB11: 喷火龙
A12: 队友 | B12: =IFERROR(INDEX('单打'!S:S,MATCH($B$2,'单打'!$B:$B,0)),"—") | E12: =IFERROR(INDEX('单打'!T:T,MATCH($B$2,'单打'!$B:$B,0)),"—") | I12: =IFERROR(INDEX('双打'!S:S,MATCH($B$2,'双打'!$B:$B,0)),"—") | L12: =IFERROR(INDEX('双打'!T:T,MATCH($B$2,'双打'!$B:$B,0)),"—") | AB12: 三首恶龙
A13: 本期变化 | B13: =IFERROR(INDEX('单打'!J:J,MATCH($B$2,'单打'!$B:$B,0)),"—") | I13: =IFERROR(INDEX('双打'!J:J,MATCH($B$2,'双打'!$B:$B,0)),"—") | AB13: 甲贺忍蛙
AB14: 钢铠鸦
AB15: 快龙
AB16: 九尾（阿罗拉）
AB17: 耿鬼
AB18: 晶光花
AB19: 幽尾玄鱼
AB20: 清洗洛托姆
AB21: 大剑鬼（洗翠）
AB22: 雷丘
AB23: 巨钳螳螂
AB24: 宝石海星
AB25: 骨纹巨声鳄
... AB235: 步哨鼠

Sheet 单打
A1: 排名 | B1: 中文名 | C1: 英文名 | D1: 招式 | E1: 道具 | F1: 特性 | G1: 性格 | H1: 队友 | I1: 努力值 | J1: 本期变化 | K1: 招式·1 | L1: 招式·2 | M1: 道具·1 | N1: 道具·2 | O1: 性格·1 | P1: 性格·2 | Q1: 努力值·1 | R1: 努力值·2 | S1: 队友·1 | T1: 队友·2
A2: 1 | B2: 烈咬陆鲨 | C2: Garchomp | D2: 1. 地震 (99.5%) 2. 隐形岩 (48.3%) 3. 鳞射 (40%) 4. 逆鳞 (35.2%) 5. 岩石封锁 (30.3%) 6. 剑舞 (28.6%) 7. 龙尾 (28.1%) 8. 撒菱 (18.3%) 9. 岩崩 (17%) 10. 毒击 (13.8%) | E2: 1. 气势披带 (38.1%) 2. 文柚果 (23.2%) 3. 讲究围巾 (21.6%) 4. 木子果 (9.2%) 5. 生命宝珠 (3.3%) 6. 烈咬陆鲨进化石 (0.9%) 7. 吃剩的东西 (0.9%) 8. 番荔果 (0.6%) 9. 莓榴果 (0.5%) 10. 光粉 (0.3%) | F2: 1. 粗糙皮肤 (99.4%) 2. 沙隐 (0.6%) | G2: 1. 爽朗 +S -C (49.2%) 2. 固执 +A -C (28.9%) 3. 淘气 +B -C (18.7%) 4. 慎重 +D -C (1.7%) 5. 天真 +S -D (0.4%) 6. 大胆 +B -A (0.2%) 7. 顽皮 +A -D (0.2%) 8. 急躁 +S -B (0.2%) 9. 内敛 +C -A (0.1%) 10. 勇敢 +A -S (0.1%) | H2: 1. 谜拟丘 2. 西狮海壬 3. 巨金怪 4. 铝钢桥龙 5. 魔幻假面喵 6. 暴鲤龙 7. 喷火龙 8. 妖火红狐 9. 火焰鸡 10. 甲贺忍蛙 | I2: 1. H2/A32/B0/C0/D0/S32 (49.3%) 2. H0/A32/B2/C0/D0/S32 (9.5%) 3. H0/A32/B1/C0/D1/S32 (4.4%) 4. H32/A0/B32/C0/D0/S2 (3.6%) 5. H32/A0/B32/C0/D2/S0 (3.2%) 6. H0/A32/B0/C0/D2/S32 (2.7%) 7. H32/A0/B30/C0/D0/S4 (1.9%) 8. H0/A30/B4/C0/D0/S32 (1.1%) 9. H0/A32/B0/C0/D0/S32 (1.1%) 10. H32/A0/B25/C0/D0/S9 (1.1%) | J2: 本期无显著变化 | K2: 1. 地震 (99.5%) 2. 隐形岩 (48.3%) 3. 鳞射 (40%) 4. 逆鳞 (35.2%) 5. 岩石封锁 (30.3%) | L2: 6. 剑舞 (28.6%) 7. 龙尾 (28.1%) 8. 撒菱 (18.3%) 9. 岩崩 (17%) 10. 毒击 (13.8%) | M2: 1. 气势披带 (38.1%) 2. 文柚果 (23.2%) 3. 讲究围巾 (21.6%) 4. 木子果 (9.2%) 5. 生命宝珠 (3.3%) | N2: 6. 烈咬陆鲨进化石 (0.9%) 7. 吃剩的东西 (0.9%) 8. 番荔果 (0.6%) 9. 莓榴果 (0.5%) 10. 光粉 (0.3%) | O2: 1. 爽朗 +S -C (49.2%) 2. 固执 +A -C (28.9%) 3. 淘气 +B -C (18.7%) 4. 慎重 +D -C (1.7%) 5. 天真 +S -D (0.4%) | P2: 6. 大胆 +B -A (0.2%) 7. 顽皮 +A -D (0.2%) 8. 急躁 +S -B (0.2%) 9. 内敛 +C -A (0.1%) 10. 勇敢 +A -S (0.1%) | Q2: 1. H2/A32/B0/C0/D0/S32 (49.3%) 2. H0/A32/B2/C0/D0/S32 (9.5%) 3. H0/A32/B1/C0/D1/S32 (4.4%) 4. H32/A0/B32/C0/D0/S2 (3.6%) 5. H32/A0/B32/C0/D2/S0 (3.2%) | R2: 6. H0/A32/B0/C0/D2/S32 (2.7%) 7. H32/A0/B30/C0/D0/S4 (1.9%) 8. H0/A30/B4/C0/D0/S32 (1.1%) 9. H0/A32/B0/C0/D0/S32 (1.1%) 10. H32/A0/B25/C0/D0/S9 (1.1%) | S2: 1. 谜拟丘 2. 西狮海壬 3. 巨金怪 4. 铝钢桥龙 5. 魔幻假面喵 | T2: 6. 暴鲤龙 7. 喷火龙 8. 妖火红狐 9. 火焰鸡 10. 甲贺忍蛙
A3: 2 | B3: 谜拟丘 | C3: Mimikyu | D3: 1. 嬉闹 (98.3%) 2. 影子偷袭 (97.7%) 3. 剑舞 (85.3%) 4. 暗影爪 (68.8%) 5. 咒术 (13.2%) 6. 木槌 (12.4%) 7. 吸取拳 (8.3%) 8. 戏法空间 (7.3%) 9. 磷火 (1.7%) 10. 同命 (1.7%) | E3: 1. 生命宝珠 (86.3%) 2. 焦点镜 (4.5%) 3. 木子果 (2.9%) 4. 咒术之符 (2%) 5. 妖精之羽 (0.6%) 6. 广角镜 (0.5%) 7. 吃剩的东西 (0.5%) 8. 光粉 (0.5%) 9. 心灵香草 (0.4%) 10. 文柚果 (0.3%) | F3: 1. 画皮 (100%) | G3: 1. 固执 +A -C (81.9%) 2. 爽朗 +S -C (13.5%) 3. 勇敢 +A -S (2.5%) 4. 淘气 +B -C (0.4%) 5. 怕寂寞 +A -B (0.3%) 6. 悠闲 +B -S (0.3%) 7. 顽皮 +A -D (0.2%) 8. 慎重 +D -C (0.2%) 9. 自大 +D -S (0.2%) 10. 天真 +S -D (0.1%) | H3: 1. 烈咬陆鲨 2. 巨金怪 3. 铝钢桥龙 4. 河马兽 5. 西狮海壬 6. 甲贺忍蛙 7. 喷火龙 8. 暴鲤龙 9. 妖火红狐 10. 魔幻假面喵 | I3: 1. H1/A32/B1/C0/D0/S32 (24.8%) 2. H2/A32/B0/C0/D0/S32 (22.1%) 3. H29/A32/B5/C0/D0/S0 (5.2%) 4. H29/A26/B11/C0/D0/S0 (3.7%) 5. H0/A32/B2/C0/D0/S32 (3.6%) 6. H32/A32/B2/C0/D0/S0 (3.2%) 7. H1/A32/B0/C0/D1/S32 (2.3%) 8. H0/A32/B0/C0/D2/S32 (1.7%) 9. H29/A30/B7/C0/D0/S0 (1.5%) 10. H28/A30/B7/C0/D0/S1 (1.3%) | J3: 本期无显著变化 | K3: 1. 嬉闹 (98.3%) 2. 影子偷袭 (97.7%) 3. 剑舞 (85.3%) 4. 暗影爪 (68.8%) 5. 咒术 (13.2%) | L3: 6. 木槌 (12.4%) 7. 吸取拳 (8.3%) 8. 戏法空间 (7.3%) 9. 磷火 (1.7%) 10. 同命 (1.7%) | M3: 1. 生命宝珠 (86.3%) 2. 焦点镜 (4.5%) 3. 木子果 (2.9%) 4. 咒术之符 (2%) 5. 妖精之羽 (0.6%) | N3: 6. 广角镜 (0.5%) 7. 吃剩的东西 (0.5%) 8. 光粉 (0.5%) 9. 心灵香草 (0.4%) 10. 文柚果 (0.3%) | O3: 1. 固执 +A -C (81.9%) 2. 爽朗 +S -C (13.5%) 3. 勇敢 +A -S (2.5%) 4. 淘气 +B -C (0.4%) 5. 怕寂寞 +A -B (0.3%) | P3: 6. 悠闲 +B -S (0.3%) 7. 顽皮 +A -D (0.2%) 8. 慎重 +D -C (0.2%) 9. 自大 +D -S (0.2%) 10. 天真 +S -D (0.1%) | Q3: 1. H1/A32/B1/C0/D0/S32 (24.8%) 2. H2/A32/B0/C0/D0/S32 (22.1%) 3. H29/A32/B5/C0/D0/S0 (5.2%) 4. H29/A26/B11/C0/D0/S0 (3.7%) 5. H0/A32/B2/C0/D0/S32 (3.6%) | R3: 6. H32/A32/B2/C0/D0/S0 (3.2%) 7. H1/A32/B0/C0/D1/S32 (2.3%) 8. H0/A32/B0/C0/D2/S32 (1.7%) 9. H29/A30/B7/C0/D0/S0 (1.5%) 10. H28/A30/B7/C0/D0/S1 (1.3%) | S3: 1. 烈咬陆鲨 2. 巨金怪 3. 铝钢桥龙 4. 河马兽 5. 西狮海壬 | T3: 6. 甲贺忍蛙 7. 喷火龙 8. 暴鲤龙 9. 妖火红狐 10. 魔幻假面喵
A4: 3 | B4: 巨金怪 | C4: Metagross | D4: 1. 精神之牙 (95%) 2. 子弹拳 (91.4%) 3. 地震 (47.8%) 4. 冰冻拳 (42.7%) 5. 雷电拳 (28.9%) 6. 扑击 (24.7%) 7. 铁壁 (24.1%) 8. 臂锤 (13.5%) 9. 铁头 (7.2%) 10. 打草结 (7%) | E4: 1. 巨金怪进化石 (98.7%) 2. 生命宝珠 (0.2%) 3. 文柚果 (0.2%) 4. 腰木果 (0.1%) 5. 吃剩的东西 (0.1%) 6. 光之黏土 (0.1%) 7. 讲究围巾 (0.1%) 8. 木子果 (0.1%) 9. 达人带 (0.1%) 10. 气势披带 (0%) | F4: 1. 恒净之躯 (99.4%) 2. 轻金属 (0.6%) | G4: 1. 固执 +A -C (44.2%) 2. 爽朗 +S -C (35.8%) 3. 淘气 +B -C (18.3%) 4. 慎重 +D -C (0.5%) 5. 勇敢 +A -S (0.2%) 6. 天真 +S -D (0.2%) 7. 顽皮 +A -D (0.2%) 8. 大胆 +B -A (0.1%) 9. 怕寂寞 +A -B (0.1%) 10. 悠闲 +B -S (0.1%) | H4: 1. 西狮海壬 2. 谜拟丘 3. 烈咬陆鲨 4. 三首恶龙 5. 河马兽 6. 铝钢桥龙 7. 魔幻假面喵 8. 喷火龙 9. 快龙 10. 甲贺忍蛙 | I4: 1. H2/A32/B0/C0/D0/S32 (24.5%) 2. H10/A25/B0/C8/D0/S23 (5.1%) 3. H32/A0/B32/C0/D0/S2 (4.9%) 4. H20/A25/B1/C0/D1/S19 (3.7%) 5. H26/A32/B0/C0/D0/S8 (2.9%) 6. H32/A0/B30/C0/D0/S4 (2.6%) 7. H12/A22/B0/C0/D0/S32 (2.4%) 8. H16/A25/B0/C0/D0/S25 (2.4%) 9. H32/A32/B0/C0/D0/S2 (2%) 10. H22/A32/B3/C0/D0/S9 (1.7%) | J4: 本期无显著变化 | K4: 1. 精神之牙 (95%) 2. 子弹拳 (91.4%) 3. 地震 (47.8%) 4. 冰冻拳 (42.7%) 5. 雷电拳 (28.9%) | L4: 6. 扑击 (24.7%) 7. 铁壁 (24.1%) 8. 臂锤 (13.5%) 9. 铁头 (7.2%) 10. 打草结 (7%) | M4: 1. 巨金怪进化石 (98.7%) 2. 生命宝珠 (0.2%) 3. 文柚果 (0.2%) 4. 腰木果 (0.1%) 5. 吃剩的东西 (0.1%) | N4: 6. 光之黏土 (0.1%) 7. 讲究围巾 (0.1%) 8. 木子果 (0.1%) 9. 达人带 (0.1%) 10. 气势披带 (0%) | O4: 1. 固执 +A -C (44.2%) 2. 爽朗 +S -C (35.8%) 3. 淘气 +B -C (18.3%) 4. 慎重 +D -C (0.5%) 5. 勇敢 +A -S (0.2%) | P4: 6. 天真 +S -D (0.2%) 7. 顽皮 +A -D (0.2%) 8. 大胆 +B -A (0.1%) 9. 怕寂寞 +A -B (0.1%) 10. 悠闲 +B -S (0.1%) | Q4: 1. H2/A32/B0/C0/D0/S32 (24.5%) 2. H10/A25/B0/C8/D0/S23 (5.1%) 3. H32/A0/B32/C0/D0/S2 (4.9%) 4. H20/A25/B1/C0/D1/S19 (3.7%) 5. H26/A32/B0/C0/D0/S8 (2.9%) | R4: 6. H32/A0/B30/C0/D0/S4 (2.6%) 7. H12/A22/B0/C0/D0/S32 (2.4%) 8. H16/A25/B0/C0/D0/S25 (2.4%) 9. H32/A32/B0/C0/D0/S2 (2%) 10. H22/A32/B3/C0/D0/S9 (1.7%) | S4: 1. 西狮海壬 2. 谜拟丘 3. 烈咬陆鲨 4. 三首恶龙 5. 河马兽 | T4: 6. 铝钢桥龙 7. 魔幻假面喵 8. 喷火龙 9. 快龙 10. 甲贺忍蛙
A5: 4 | B5: 铝钢桥龙 | C5: Archaludon | D5: 1. 加农光炮 (75.4%) 2. 流星群 (72.3%) 3. 十万伏特 (62%) 4. 隐形岩 (38.1%) 5. 镜面反射 (20.2%) 6. 恶之波动 (18.1%) 7. 波导弹 (18%) 8. 吼叫 (16.1%) 9. 电光束 (16%) 10. 龙尾 (15.1%) | E5: 1. 文柚果 (30.9%) 2. 吃剩的东西 (20.7%) 3. 白色香草 (19.5%) 4. 讲究围巾 (14.5%) 5. 焦点镜 (5.8%) 6. 腰木果 (2%) 7. 零余果 (1%) 8. 龙之牙 (0.9%) 9. 达人带 (0.8%) 10. 莲蒲果 (0.6%) | F5: 1. 持久力 (67.6%) 2. 结实 (32.4%) 3. 坚毅 (0%) | G5: 1. 内敛 +C -A (42.8%) 2. 胆小 +S -A (17.6%) 3. 大胆 +B -A (16.7%) 4. 温和 +D -A (14.7%) 5. 淘气 +B -C (2.1%) 6. 悠闲 +B -S (1.7%) 7. 慎重 +D -C (1.4%) 8. 自大 +D -S (1.1%) 9. 冷静 +C -S (0.6%) 10. 马虎 +C -D (0.5%) | H5: 1. 谜拟丘 2. 烈咬陆鲨 3. 巨金怪 4. 河马兽 5. 西狮海壬 6. 暴鲤龙 7. 魔幻假面喵 8. 火焰鸡 9. 妖火红狐 10. 甲贺忍蛙 | I5: 1. H2/A0/B0/C32/D0/S32 (22.7%) 2. H32/A0/B2/C0/D32/S0 (9%) 3. H0/A0/B1/C32/D1/S32 (6.1%) 4. H32/A0/B0/C0/D32/S2 (4.9%) 5. H0/A0/B2/C32/D0/S32 (2.6%) 6. H32/A0/B0/C32/D0/S2 (2.3%) 7. H32/A0/B2/C32/D0/S0 (2.3%) 8. H32/A0/B0/C32/D2/S0 (2.2%) 9. H32/A0/B32/C0/D2/S0 (1.9%) 10. H0/A0/B0/C32/D2/S32 (1.6%) | J5: 本期无显著变化 | K5: 1. 加农光炮 (75.4%) 2. 流星群 (72.3%) 3. 十万伏特 (62%) 4. 隐形岩 (38.1%) 5. 镜面反射 (20.2%) | L5: 6. 恶之波动 (18.1%) 7. 波导弹 (18%) 8. 吼叫 (16.1%) 9. 电光束 (16%) 10. 龙尾 (15.1%) | M5: 1. 文柚果 (30.9%) 2. 吃剩的东西 (20.7%) 3. 白色香草 (19.5%) 4. 讲究围巾 (14.5%) 5. 焦点镜 (5.8%) | N5: 6. 腰木果 (2%) 7. 零余果 (1%) 8. 龙之牙 (0.9%) 9. 达人带 (0.8%) 10. 莲蒲果 (0.6%) | O5: 1. 内敛 +C -A (42.8%) 2. 胆小 +S -A (17.6%) 3. 大胆 +B -A (16.7%) 4. 温和 +D -A (14.7%) 5. 淘气 +B -C (2.1%) | P5: 6. 悠闲 +B -S (1.7%) 7. 慎重 +D -C (1.4%) 8. 自大 +D -S (1.1%) 9. 冷静 +C -S (0.6%) 10. 马虎 +C -D (0.5%) | Q5: 1. H2/A0/B0/C32/D0/S32 (22.7%) 2. H32/A0/B2/C0/D32/S0 (9%) 3. H0/A0/B1/C32/D1/S32 (6.1%) 4. H32/A0/B0/C0/D32/S2 (4.9%) 5. H0/A0/B2/C32/D0/S32 (2.6%) | R5: 6. H32/A0/B0/C32/D0/S2 (2.3%) 7. H32/A0/B2/C32/D0/S0 (2.3%) 8. H32/A0/B0/C32/D2/S0 (2.2%) 9. H32/A0/B32/C0/D2/S0 (1.9%) 10. H0/A0/B0/C32/D2/S32 (1.6%) | S5: 1. 谜拟丘 2. 烈咬陆鲨 3. 巨金怪 4. 河马兽 5. 西狮海壬 | T5: 6. 暴鲤龙 7. 魔幻假面喵 8. 火焰鸡 9. 妖火红狐 10. 甲贺忍蛙
A6: 5 | B6: 河马兽 | C6: Hippowdon | D6: 1. 地震 (98.6%) 2. 哈欠 (94.5%) 3. 隐形岩 (75.1%) 4. 偷懒 (65.3%) 5. 吹飞 (43%) 6. 守住 (15.6%) 7. 吼叫 (3.5%) 8. 岩石封锁 (0.9%) 9. 冰冻牙 (0.7%) 10. 地裂 (0.6%) | E6: 1. 文柚果 (59.5%) 2. 吃剩的东西 (38.3%) 3. 沙沙岩石 (0.5%) 4. 木子果 (0.3%) 5. 心灵香草 (0.3%) 6. 罗子果 (0.1%) 7. 生命宝珠 (0.1%) 8. 先制之爪 (0.1%) 9. 光粉 (0.1%) 10. 气势披带 (0.1%) | F6: 1. 扬沙 (99.8%) 2. 沙之力 (0.2%) | G6: 1. 淘气 +B -C (73.6%) 2. 慎重 +D -C (14.7%) 3. 悠闲 +B -S (7.7%) 4. 自大 +D -S (1.6%) 5. 大胆 +B -A (0.9%) 6. 固执 +A -C (0.8%) 7. 勇敢 +A -S (0.2%) 8. 温和 +D -A (0.2%) 9. 顽皮 +A -D (0.1%) 10. 乐天 +B -D (0%) | H6: 1. 谜拟丘 2. 巨金怪 3. 西狮海壬 4. 魔幻假面喵 5. 铝钢桥龙 6. 暴鲤龙 7. 三首恶龙 8. 快龙 9. 烈咬陆鲨 10. 喷火龙 | I6: 1. H32/A0/B32/C0/D2/S0 (24%) 2. H32/A0/B2/C0/D32/S0 (18.2%) 3. H32/A0/B22/C0/D12/S0 (7.8%) 4. H32/A0/B22/C0/D10/S2 (6.8%) 5. H32/A0/B15/C0/D19/S0 (3.9%) 6. H32/A0/B12/C0/D22/S0 (3.6%) 7. H32/A0/B18/C0/D16/S0 (2.6%) 8. H32/A0/B32/C0/D0/S2 (2.1%) 9. H32/A0/B20/C0/D14/S0 (1.8%) 10. H32/A0/B6/C0/D28/S0 (1.7%) | J6: 本期无显著变化 | K6: 1. 地震 (98.6%) 2. 哈欠 (94.5%) 3. 隐形岩 (75.1%) 4. 偷懒 (65.3%) 5. 吹飞 (43%) | L6: 6. 守住 (15.6%) 7. 吼叫 (3.5%) 8. 岩石封锁 (0.9%) 9. 冰冻牙 (0.7%) 10. 地裂 (0.6%) | M6: 1. 文柚果 (59.5%) 2. 吃剩的东西 (38.3%) 3. 沙沙岩石 (0.5%) 4. 木子果 (0.3%) 5. 心灵香草 (0.3%) | N6: 6. 罗子果 (0.1%) 7. 生命宝珠 (0.1%) 8. 先制之爪 (0.1%) 9. 光粉 (0.1%) 10. 气势披带 (0.1%) | O6: 1. 淘气 +B -C (73.6%) 2. 慎重 +D -C (14.7%) 3. 悠闲 +B -S (7.7%) 4. 自大 +D -S (1.6%) 5. 大胆 +B -A (0.9%) | P6: 6. 固执 +A -C (0.8%) 7. 勇敢 +A -S (0.2%) 8. 温和 +D -A (0.2%) 9. 顽皮 +A -D (0.1%) 10. 乐天 +B -D (0%) | Q6: 1. H32/A0/B32/C0/D2/S0 (24%) 2. H32/A0/B2/C0/D32/S0 (18.2%) 3. H32/A0/B22/C0/D12/S0 (7.8%) 4. H32/A0/B22/C0/D10/S2 (6.8%) 5. H32/A0/B15/C0/D19/S0 (3.9%) | R6: 6. H32/A0/B12/C0/D22/S0 (3.6%) 7. H32/A0/B18/C0/D16/S0 (2.6%) 8. H32/A0/B32/C0/D0/S2 (2.1%) 9. H32/A0/B20/C0/D14/S0 (1.8%) 10. H32/A0/B6/C0/D28/S0 (1.7%) | S6: 1. 谜拟丘 2. 巨金怪 3. 西狮海壬 4. 魔幻假面喵 5. 铝钢桥龙 | T6: 6. 暴鲤龙 7. 三首恶龙 8. 快龙 9. 烈咬陆鲨 10. 喷火龙
A7: 6 | B7: 西狮海壬 | C7: Primarina | D7: 1. 月亮之力 (98.2%) 2. 泡影的咏叹调 (87.8%) 3. 水流喷射 (74.9%) 4. 再来一次 (44.7%) 5. 冥想 (22.7%) 6. 快速折返 (20.8%) 7. 冲浪 (9.7%) 8. 冰冻光束 (6.6%) 9. 能量球 (5.4%) 10. 薄雾场地 (5.3%) | E7: 1. 文柚果 (48.1%) 2. 吃剩的东西 (25.5%) 3. 神秘水滴 (9.6%) 4. 气势披带 (4%) 5. 零余果 (3.2%) 6. 木子果 (2.8%) 7. 妖精之羽 (1.6%) 8. 烛木果 (1.6%) 9. 生命宝珠 (1%) 10. 讲究围巾 (0.5%) | F7: 1. 激流 (96.3%) 2. 湿润之声 (3.7%) | G7: 1. 内敛 +C -A (61.9%) 2. 冷静 +C -S (18.1%) 3. 大胆 +B -A (11.9%) 4. 悠闲 +B -S (3.4%) 5. 温和 +D -A (2.7%) 6. 胆小 +S -A (1%) 7. 慢吞吞 +C -B (0.5%) 8. 自大 +D -S (0.4%) 9. 马虎 +C -D (0.1%) 10. 急躁 +S -B (0%) | H7: 1. 烈咬陆鲨 2. 巨金怪 3. 谜拟丘 4. 河马兽 5. 三首恶龙 6. 魔幻假面喵 7. 铝钢桥龙 8. 喷火龙 9. 妖火红狐 10. 快龙 | I7: 1. H32/A0/B0/C32/D0/S2 (8.1%) 2. H32/A0/B29/C4/D1/S0 (6.5%) 3. H32/A0/B20/C14/D0/S0 (5.6%) 4. H32/A0/B2/C32/D0/S0 (4.5%) 5. H32/A0/B32/C2/D0/S0 (3.6%) 6. H32/A0/B0/C32/D2/S0 (3.3%) 7. H2/A0/B0/C32/D0/S32 (3.1%) 8. H32/A0/B30/C4/D0/S0 (2.8%) 9. H32/A0/B32/C0/D2/S0 (2.1%) 10. H32/A0/B0/C24/D0/S10 (1.8%) | J7: 本期无显著变化 | K7: 1. 月亮之力 (98.2%) 2. 泡影的咏叹调 (87.8%) 3. 水流喷射 (74.9%) 4. 再来一次 (44.7%) 5. 冥想 (22.7%) | L7: 6. 快速折返 (20.8%) 7. 冲浪 (9.7%) 8. 冰冻光束 (6.6%) 9. 能量球 (5.4%) 10. 薄雾场地 (5.3%) | M7: 1. 文柚果 (48.1%) 2. 吃剩的东西 (25.5%) 3. 神秘水滴 (9.6%) 4. 气势披带 (4%) 5. 零余果 (3.2%) | N7: 6. 木子果 (2.8%) 7. 妖精之羽 (1.6%) 8. 烛木果 (1.6%) 9. 生命宝珠 (1%) 10. 讲究围巾 (0.5%) | O7: 1. 内敛 +C -A (61.9%) 2. 冷静 +C -S (18.1%) 3. 大胆 +B -A (11.9%) 4. 悠闲 +B -S (3.4%) 5. 温和 +D -A (2.7%) | P7: 6. 胆小 +S -A (1%) 7. 慢吞吞 +C -B (0.5%) 8. 自大 +D -S (0.4%) 9. 马虎 +C -D (0.1%) 10. 急躁 +S -B (0%) | Q7: 1. H32/A0/B0/C32/D0/S2 (8.1%) 2. H32/A0/B29/C4/D1/S0 (6.5%) 3. H32/A0/B20/C14/D0/S0 (5.6%) 4. H32/A0/B2/C32/D0/S0 (4.5%) 5. H32/A0/B32/C2/D0/S0 (3.6%) | R7: 6. H32/A0/B0/C32/D2/S0 (3.3%) 7. H2/A0/B0/C32/D0/S32 (3.1%) 8. H32/A0/B30/C4/D0/S0 (2.8%) 9. H32/A0/B32/C0/D2/S0 (2.1%) 10. H32/A0/B0/C24/D0/S10 (1.8%) | S7: 1. 烈咬陆鲨 2. 巨金怪 3. 谜拟丘 4. 河马兽 5. 三首恶龙 | T7: 6. 魔幻假面喵 7. 铝钢桥龙 8. 喷火龙 9. 妖火红狐 10. 快龙
A8: 7 | B8: 魔幻假面喵 | C8: Meowscarada | D8: 1. 千变万花 (97.2%) 2. 三旋击 (85.1%) 3. 急速折返 (71.7%) 4. 拍落 (64%) 5. 突袭 (17.9%) 6. 雷电拳 (15.6%) 7. 嬉闹 (7.1%) 8. 移花接木 (6.4%) 9. 力量宝石 (5.7%) 10. 毒菱 (5.4%) | E8: 1. 讲究围巾 (73.5%) 2. 气势披带 (18%) 3. 生命宝珠 (5.2%) 4. 达人带 (1.3%) 5. 先制之爪 (0.3%) 6. 力量头带 (0.2%) 7. 广角镜 (0.2%) 8. 电气球 (0.2%) 9. 木子果 (0.2%) 10. 文柚果 (0.1%) | F8: 1. 变幻自如 (93.3%) 2. 茂盛 (6.7%) | G8: 1. 爽朗 +S -C (57.4%) 2. 固执 +A -C (34.9%) 3. 天真 +S -D (3.9%) 4. 马虎 +C -D (1.1%) 5. 顽皮 +A -D (0.9%) 6. 急躁 +S -B (0.7%) 7. 胆小 +S -A (0.4%) 8. 内敛 +C -A (0.4%) 9. 怕寂寞 +A -B (0.3%) 10. 慢吞吞 +C -B (0.1%) | H8: 1. 烈咬陆鲨 2. 河马兽 3. 西狮海壬 4. 谜拟丘 5. 铝钢桥龙 6. 巨金怪 7. 妖火红狐 8. 喷火龙 9. 火焰鸡 10. 暴鲤龙 | I8: 1. H2/A32/B0/C0/D0/S32 (60.6%) 2. H0/A32/B2/C0/D0/S32 (9%) 3. H0/A32/B0/C0/D2/S32 (4%) 4. H0/A32/B1/C0/D1/S32 (3.8%) 5. H4/A30/B20/C0/D0/S12 (1.7%) 6. H0/A32/B0/C0/D0/S32 (1.7%) 7. H0/A30/B0/C11/D0/S25 (1.1%) 8. H4/A25/B23/C0/D0/S14 (1%) 9. H0/A2/B0/C32/D0/S32 (0.7%) 10. H7/A32/B0/C0/D0/S27 (0.7%) | J8: 本期无显著变化 | K8: 1. 千变万花 (97.2%) 2. 三旋击 (85.1%) 3. 急速折返 (71.7%) 4. 拍落 (64%) 5. 突袭 (17.9%) | L8: 6. 雷电拳 (15.6%) 7. 嬉闹 (7.1%) 8. 移花接木 (6.4%) 9. 力量宝石 (5.7%) 10. 毒菱 (5.4%) | M8: 1. 讲究围巾 (73.5%) 2. 气势披带 (18%) 3. 生命宝珠 (5.2%) 4. 达人带 (1.3%) 5. 先制之爪 (0.3%) | N8: 6. 力量头带 (0.2%) 7. 广角镜 (0.2%) 8. 电气球 (0.2%) 9. 木子果 (0.2%) 10. 文柚果 (0.1%) | O8: 1. 爽朗 +S -C (57.4%) 2. 固执 +A -C (34.9%) 3. 天真 +S -D (3.9%) 4. 马虎 +C -D (1.1%) 5. 顽皮 +A -D (0.9%) | P8: 6. 急躁 +S -B (0.7%) 7. 胆小 +S -A (0.4%) 8. 内敛 +C -A (0.4%) 9. 怕寂寞 +A -B (0.3%) 10. 慢吞吞 +C -B (0.1%) | Q8: 1. H2/A32/B0/C0/D0/S32 (60.6%) 2. H0/A32/B2/C0/D0/S32 (9%) 3. H0/A32/B0/C0/D2/S32 (4%) 4. H0/A32/B1/C0/D1/S32 (3.8%) 5. H4/A30/B20/C0/D0/S12 (1.7%) | R8: 6. H0/A32/B0/C0/D0/S32 (1.7%) 7. H0/A30/B0/C11/D0/S25 (1.1%) 8. H4/A25/B23/C0/D0/S14 (1%) 9. H0/A2/B0/C32/D0/S32 (0.7%) 10. H7/A32/B0/C0/D0/S27 (0.7%) | S8: 1. 烈咬陆鲨 2. 河马兽 3. 西狮海壬 4. 谜拟丘 5. 铝钢桥龙 | T8: 6. 巨金怪 7. 妖火红狐 8. 喷火龙 9. 火焰鸡 10. 暴鲤龙
A9: 8 | B9: 暴鲤龙 | C9: Gyarados | D9: 1. 龙之舞 (84.5%) 2. 攀瀑 (83.2%) 3. 地震 (79.6%) 4. 冰冻牙 (50.7%) 5. 强力鞭打 (40.4%) 6. 挑衅 (22.5%) 7. 咬碎 (17.2%) 8. 雪崩 (10.4%) 9. 豁出去 (2.3%) 10. 替身 (1.7%) | E9: 1. 暴鲤龙进化石 (80.5%) 2. 吃剩的东西 (10.1%) 3. 文柚果 (4%) 4. 木子果 (2.3%) 5. 达人带 (1.1%) 6. 生命宝珠 (0.5%) 7. 烛木果 (0.4%) 8. 气势披带 (0.2%) 9. 零余果 (0.2%) 10. 讲究围巾 (0.2%) | F9: 1. 威吓 (99.3%) 2. 自信过度 (0.7%) | G9: 1. 爽朗 +S -C (52.1%) 2. 固执 +A -C (41.1%) 3. 淘气 +B -C (5.7%) 4. 慎重 +D -C (0.6%) 5. 顽皮 +A -D (0.1%) 6. 怕寂寞 +A -B (0.1%) 7. 天真 +S -D (0%) 8. 大胆 +B -A (0%) 9. 悠闲 +B -S (0%) 10. 勇敢 +A -S (0%) | H9: 1. 烈咬陆鲨 2. 谜拟丘 3. 铝钢桥龙 4. 河马兽 5. 火焰鸡 6. 九尾（阿罗拉的样子） 7. 妖火红狐 8. 魔幻假面喵 9. 巨金怪 10. 晶光花 | I9: 1. H1/A32/B1/C0/D0/S32 (25%) 2. H2/A32/B0/C0/D0/S32 (20%) 3. H1/A32/B0/C0/D1/S32 (2.9%) 4. H0/A32/B2/C0/D0/S32 (2.2%) 5. H19/A32/B0/C0/D0/S15 (2.1%) 6. H7/A32/B1/C0/D0/S26 (1.4%) 7. H31/A11/B21/C0/D1/S2 (1.4%) 8. H13/A32/B0/C0/D0/S21 (1.4%) 9. H3/A32/B0/C0/D0/S31 (1.3%) 10. H5/A26/B5/C0/D0/S30 (1.3%) | J9: 本期无显著变化 | K9: 1. 龙之舞 (84.5%) 2. 攀瀑 (83.2%) 3. 地震 (79.6%) 4. 冰冻牙 (50.7%) 5. 强力鞭打 (40.4%) | L9: 6. 挑衅 (22.5%) 7. 咬碎 (17.2%) 8. 雪崩 (10.4%) 9. 豁出去 (2.3%) 10. 替身 (1.7%) | M9: 1. 暴鲤龙进化石 (80.5%) 2. 吃剩的东西 (10.1%) 3. 文柚果 (4%) 4. 木子果 (2.3%) 5. 达人带 (1.1%) | N9: 6. 生命宝珠 (0.5%) 7. 烛木果 (0.4%) 8. 气势披带 (0.2%) 9. 零余果 (0.2%) 10. 讲究围巾 (0.2%) | O9: 1. 爽朗 +S -C (52.1%) 2. 固执 +A -C (41.1%) 3. 淘气 +B -C (5.7%) 4. 慎重 +D -C (0.6%) 5. 顽皮 +A -D (0.1%) | P9: 6. 怕寂寞 +A -B (0.1%) 7. 天真 +S -D (0%) 8. 大胆 +B -A (0%) 9. 悠闲 +B -S (0%) 10. 勇敢 +A -S (0%) | Q9: 1. H1/A32/B1/C0/D0/S32 (25%) 2. H2/A32/B0/C0/D0/S32 (20%) 3. H1/A32/B0/C0/D1/S32 (2.9%) 4. H0/A32/B2/C0/D0/S32 (2.2%) 5. H19/A32/B0/C0/D0/S15 (2.1%) | R9: 6. H7/A32/B1/C0/D0/S26 (1.4%) 7. H31/A11/B21/C0/D1/S2 (1.4%) 8. H13/A32/B0/C0/D0/S21 (1.4%) 9. H3/A32/B0/C0/D0/S31 (1.3%) 10. H5/A26/B5/C0/D0/S30 (1.3%) | S9: 1. 烈咬陆鲨 2. 谜拟丘 3. 铝钢桥龙 4. 河马兽 5. 火焰鸡 | T9: 6. 九尾（阿罗拉的样子） 7. 妖火红狐 8. 魔幻假面喵 9. 巨金怪 10. 晶光花
A10: 9 | B10: 妖火红狐 | C10: Delphox | D10: 1. 喷射火焰 (84.2%) 2. 魔法闪耀 (63%) 3. 精神强念 (56.4%) 4. 替身 (43.2%) 5. 精神冲击 (40%) 6. 诡计 (37.8%) 7. 再来一次 (17.5%) 8. 魔法火焰 (10.5%) 9. 打草结 (10%) 10. 磷火 (9.3%) | E10: 1. 妖火红狐进化石 (99.2%) 2. 讲究围巾 (0.2%) 3. 气势披带 (0.1%) 4. 博识眼镜 (0%) 5. 生命宝珠 (0%) 6. 光之黏土 (0%) 7. 弯曲的汤匙 (0%) 8. 达人带 (0%) 9. 文柚果 (0%) 10. 火焰鸡进化石 (0%) | F10: 1. 猛火 (90.8%) 2. 魔术师 (9.2%) | G10: 1. 胆小 +S -A (80.6%) 2. 内敛 +C -A (18.4%) 3. 大胆 +B -A (0.3%) 4. 急躁 +S -B (0.2%) 5. 温和 +D -A (0.2%) 6. 慢吞吞 +C -B (0.2%) 7. 爽朗 +S -C (0%) 8. 冷静 +C -S (0%) 9. 温顺 +D -B (0%) 10. 悠闲 +B -S (0%) | H10: 1. 烈咬陆鲨 2. 谜拟丘 3. 魔幻假面喵 4. 铝钢桥龙 5. 西狮海壬 6. 暴鲤龙 7. 河马兽 8. 巨金怪 9. 九尾（阿罗拉的样子） 10. 巨钳螳螂 | I10: 1. H2/A0/B0/C32/D0/S32 (22.4%) 2. H1/A0/B1/C32/D0/S32 (9.8%) 3. H5/A0/B0/C32/D0/S29 (8.4%) 4. H1/A0/B4/C32/D0/S29 (6.6%) 5. H1/A0/B0/C32/D1/S32 (3.5%) 6. H0/A0/B2/C32/D0/S32 (3.4%) 7. H9/A0/B8/C19/D0/S30 (2.3%) 8. H0/A0/B0/C32/D2/S32 (2%) 9. H9/A0/B1/C27/D0/S29 (1.9%) 10. H25/A0/B0/C12/D0/S29 (1.7%) | J10: 本期无显著变化 | K10: 1. 喷射火焰 (84.2%) 2. 魔法闪耀 (63%) 3. 精神强念 (56.4%) 4. 替身 (43.2%) 5. 精神冲击 (40%) | L10: 6. 诡计 (37.8%) 7. 再来一次 (17.5%) 8. 魔法火焰 (10.5%) 9. 打草结 (10%) 10. 磷火 (9.3%) | M10: 1. 妖火红狐进化石 (99.2%) 2. 讲究围巾 (0.2%) 3. 气势披带 (0.1%) 4. 博识眼镜 (0%) 5. 生命宝珠 (0%) | N10: 6. 光之黏土 (0%) 7. 弯曲的汤匙 (0%) 8. 达人带 (0%) 9. 文柚果 (0%) 10. 火焰鸡进化石 (0%) | O10: 1. 胆小 +S -A (80.6%) 2. 内敛 +C -A (18.4%) 3. 大胆 +B -A (0.3%) 4. 急躁 +S -B (0.2%) 5. 温和 +D -A (0.2%) | P10: 6. 慢吞吞 +C -B (0.2%) 7. 爽朗 +S -C (0%) 8. 冷静 +C -S (0%) 9. 温顺 +D -B (0%) 10. 悠闲 +B -S (0%) | Q10: 1. H2/A0/B0/C32/D0/S32 (22.4%) 2. H1/A0/B1/C32/D0/S32 (9.8%) 3. H5/A0/B0/C32/D0/S29 (8.4%) 4. H1/A0/B4/C32/D0/S29 (6.6%) 5. H1/A0/B0/C32/D1/S32 (3.5%) | R10: 6. H0/A0/B2/C32/D0/S32 (3.4%) 7. H9/A0/B8/C19/D0/S30 (2.3%) 8. H0/A0/B0/C32/D2/S32 (2%) 9. H9/A0/B1/C27/D0/S29 (1.9%) 10. H25/A0/B0/C12/D0/S29 (1.7%) | S10: 1. 烈咬陆鲨 2. 谜拟丘 3. 魔幻假面喵 4. 铝钢桥龙 5. 西狮海壬 | T10: 6. 暴鲤龙 7. 河马兽 8. 巨金怪 9. 九尾（阿罗拉的样子） 10. 巨钳螳螂
A11: 10 | B11: 火焰鸡 | C11: Blaziken | D11: 1. 闪焰冲锋 (84.6%) 2. 近身战 (66.2%) 3. 剑舞 (48.3%) 4. 雷电拳 (46%) 5. 守住 (40.1%) 6. 看穿 (33.7%) 7. 飞膝踢 (22.9%) 8. 接棒 (10.8%) 9. 地震 (6.4%) 10. 过热 (5.6%) | E11: 1. 火焰鸡进化石 (73.4%) 2. 气势披带 (14.7%) 3. 生命宝珠 (7.7%) 4. 文柚果 (1.6%) 5. 吃剩的东西 (0.5%) 6. 腰木果 (0.3%) 7. 心灵香草 (0.2%) 8. 白色香草 (0.2%) 9. 焦点镜 (0.2%) 10. 达人带 (0.1%) | F11: 1. 加速 (98.5%) 2. 猛火 (1.5%) | G11: 1. 固执 +A -C (72.8%) 2. 爽朗 +S -C (15.9%) 3. 顽皮 +A -D (4.3%) 4. 淘气 +B -C (1.6%) 5. 天真 +S -D (1.3%) 6. 马虎 +C -D (1.2%) 7. 内敛 +C -A (0.7%) 8. 胆小 +S -A (0.6%) 9. 慎重 +D -C (0.5%) 10. 怕寂寞 +A -B (0.5%) | H11: 1. 烈咬陆鲨 2. 谜拟丘 3. 铝钢桥龙 4. 暴鲤龙 5. 魔幻假面喵 6. 河马兽 7. 西狮海壬 8. 九尾（阿罗拉的样子） 9. 巨金怪 10. 甲贺忍蛙 | I11: 1. H2/A32/B0/C0/D0/S32 (47.7%) 2. H16/A32/B0/C0/D0/S18 (5.8%) 3. H10/A32/B0/C0/D0/S24 (4.3%) 4. H0/A32/B2/C0/D0/S32 (3.7%) 5. H0/A32/B0/C5/D0/S29 (2.2%) 6. H0/A32/B0/C0/D0/S32 (2.1%) 7. H0/A32/B1/C0/D1/S32 (2%) 8. H0/A32/B0/C0/D2/S32 (1.8%) 9. H20/A25/B3/C0/D0/S18 (1.2%) 10. H20/A20/B0/C0/D1/S25 (1.1%) | J11: 本期无显著变化 | K11: 1. 闪焰冲锋 (84.6%) 2. 近身战 (66.2%) 3. 剑舞 (48.3%) 4. 雷电拳 (46%) 5. 守住 (40.1%) | L11: 6. 看穿 (33.7%) 7. 飞膝踢 (22.9%) 8. 接棒 (10.8%) 9. 地震 (6.4%) 10. 过热 (5.6%) | M11: 1. 火焰鸡进化石 (73.4%) 2. 气势披带 (14.7%) 3. 生命宝珠 (7.7%) 4. 文柚果 (1.6%) 5. 吃剩的东西 (0.5%) | N11: 6. 腰木果 (0.3%) 7. 心灵香草 (0.2%) 8. 白色香草 (0.2%) 9. 焦点镜 (0.2%) 10. 达人带 (0.1%) | O11: 1. 固执 +A -C (72.8%) 2. 爽朗 +S -C (15.9%) 3. 顽皮 +A -D (4.3%) 4. 淘气 +B -C (1.6%) 5. 天真 +S -D (1.3%) | P11: 6. 马虎 +C -D (1.2%) 7. 内敛 +C -A (0.7%) 8. 胆小 +S -A (0.6%) 9. 慎重 +D -C (0.5%) 10. 怕寂寞 +A -B (0.5%) | Q11: 1. H2/A32/B0/C0/D0/S32 (47.7%) 2. H16/A32/B0/C0/D0/S18 (5.8%) 3. H10/A32/B0/C0/D0/S24 (4.3%) 4. H0/A32/B2/C0/D0/S32 (3.7%) 5. H0/A32/B0/C5/D0/S29 (2.2%) | R11: 6. H0/A32/B0/C0/D0/S32 (2.1%) 7. H0/A32/B1/C0/D1/S32 (2%) 8. H0/A32/B0/C0/D2/S32 (1.8%) 9. H20/A25/B3/C0/D0/S18 (1.2%) 10. H20/A20/B0/C0/D1/S25 (1.1%) | S11: 1. 烈咬陆鲨 2. 谜拟丘 3. 铝钢桥龙 4. 暴鲤龙 5. 魔幻假面喵 | T11: 6. 河马兽 7. 西狮海壬 8. 九尾（阿罗拉的样子） 9. 巨金怪 10. 甲贺忍蛙
A12: 11 | B12: 喷火龙 | C12: Charizard | D12: 1. 日光束 (63.7%) 2. 喷射火焰 (42.1%) 3. 空气之刃 (41.7%) 4. 闪焰冲锋 (33.1%) 5. 蓄能焰袭 (28.6%) 6. 过热 (24.1%) 7. 龙之舞 (21.5%) 8. 羽栖 (19.8%) 9. 气象球 (19.7%) 10. 龙爪 (18.3%) | E12: 1. 喷火龙进化石Ｙ (65%) 2. 喷火龙进化石Ｘ (33.8%) 3. 讲究围巾 (0.1%) 4. 生命宝珠 (0.1%) 5. 木子果 (0.1%) 6. 白色香草 (0%) 7. 雷丘进化石Ｙ (0%) 8. 木炭 (0%) 9. 气势披带 (0%) 10. 达人带 (0%) | F12: 1. 猛火 (87.2%) 2. 太阳之力 (12.8%) | G12: 1. 内敛 +C -A (38.4%) 2. 胆小 +S -A (26.1%) 3. 固执 +A -C (20.4%) 4. 爽朗 +S -C (13.4%) 5. 大胆 +B -A (0.5%) 6. 淘气 +B -C (0.3%) 7. 天真 +S -D (0.2%) 8. 冷静 +C -S (0.1%) 9. 温和 +D -A (0.1%) 10. 慢吞吞 +C -B (0.1%) | H12: 1. 烈咬陆鲨 2. 谜拟丘 3. 西狮海壬 4. 巨金怪 5. 铝钢桥龙 6. 河马兽 7. 魔幻假面喵 8. 三首恶龙 9. 甲贺忍蛙 10. 钢铠鸦 | I12: 1. H2/A0/B0/C32/D0/S32 (30.2%) 2. H2/A32/B0/C0/D0/S32 (15.2%) 3. H4/A30/B0/C0/D0/S32 (5.3%) 4. H0/A0/B2/C32/D0/S32 (3.6%) 5. H12/A0/B20/C16/D0/S18 (2.9%) 6. H14/A0/B12/C21/D0/S19 (2%) 7. H6/A0/B9/C29/D0/S22 (2%) 8. H0/A32/B2/C0/D0/S32 (1.5%) 9. H0/A0/B0/C32/D2/S32 (1.5%) 10. H12/A0/B20/C14/D0/S20 (1.5%) | J12: 本期无显著变化 | K12: 1. 日光束 (63.7%) 2. 喷射火焰 (42.1%) 3. 空气之刃 (41.7%) 4. 闪焰冲锋 (33.1%) 5. 蓄能焰袭 (28.6%) | L12: 6. 过热 (24.1%) 7. 龙之舞 (21.5%) 8. 羽栖 (19.8%) 9. 气象球 (19.7%) 10. 龙爪 (18.3%) | M12: 1. 喷火龙进化石Ｙ (65%) 2. 喷火龙进化石Ｘ (33.8%) 3. 讲究围巾 (0.1%) 4. 生命宝珠 (0.1%) 5. 木子果 (0.1%) | N12: 6. 白色香草 (0%) 7. 雷丘进化石Ｙ (0%) 8. 木炭 (0%) 9. 气势披带 (0%) 10. 达人带 (0%) | O12: 1. 内敛 +C -A (38.4%) 2. 胆小 +S -A (26.1%) 3. 固执 +A -C (20.4%) 4. 爽朗 +S -C (13.4%) 5. 大胆 +B -A (0.5%) | P12: 6. 淘气 +B -C (0.3%) 7. 天真 +S -D (0.2%) 8. 冷静 +C -S (0.1%) 9. 温和 +D -A (0.1%) 10. 慢吞吞 +C -B (0.1%) | Q12: 1. H2/A0/B0/C32/D0/S32 (30.2%) 2. H2/A32/B0/C0/D0/S32 (15.2%) 3. H4/A30/B0/C0/D0/S32 (5.3%) 4. H0/A0/B2/C32/D0/S32 (3.6%) 5. H12/A0/B20/C16/D0/S18 (2.9%) | R12: 6. H14/A0/B12/C21/D0/S19 (2%) 7. H6/A0/B9/C29/D0/S22 (2%) 8. H0/A32/B2/C0/D0/S32 (1.5%) 9. H0/A0/B0/C32/D2/S32 (1.5%) 10. H12/A0/B20/C14/D0/S20 (1.5%) | S12: 1. 烈咬陆鲨 2. 谜拟丘 3. 西狮海壬 4. 巨金怪 5. 铝钢桥龙 | T12: 6. 河马兽 7. 魔幻假面喵 8. 三首恶龙 9. 甲贺忍蛙 10. 钢铠鸦
A13: 12 | B13: 三首恶龙 | C13: Hydreigon | D13: 1. 恶之波动 (99.5%) 2. 流星群 (93.4%) 3. 急速折返 (76.2%) 4. 喷射火焰 (53.5%) 5. 大字爆炎 (26.7%) 6. 加农光炮 (12.9%) 7. 大地之力 (7.8%) 8. 诡计 (6.4%) 9. 挑衅 (5.3%) 10. 隐形岩 (3.8%) | E13: 1. 讲究围巾 (84%) 2. 生命宝珠 (4.5%) 3. 气势披带 (2.8%) 4. 吃剩的东西 (2.6%) 5. 木子果 (1.3%) 6. 文柚果 (1.3%) 7. 白色香草 (0.8%) 8. 黑色眼镜 (0.5%) 9. 达人带 (0.5%) 10. 莓榴果 (0.4%) | F13: 1. 飘浮 (100%) | G13: 1. 内敛 +C -A (70.6%) 2. 胆小 +S -A (27.9%) 3. 慢吞吞 +C -B (0.4%) 4. 天真 +S -D (0.2%) 5. 马虎 +C -D (0.2%) 6. 急躁 +S -B (0.2%) 7. 大胆 +B -A (0.1%) 8. 爽朗 +S -C (0.1%) 9. 温和 +D -A (0.1%) 10. 冷静 +C -S (0.1%) | H13: 1. 巨金怪 2. 西狮海壬 3. 谜拟丘 4. 烈咬陆鲨 5. 河马兽 6. 喷火龙 7. 火焰鸡 8. 铝钢桥龙 9. 妖火红狐 10. 暴鲤龙 | I13: 1. H2/A0/B0/C32/D0/S32 (71.9%) 2. H0/A0/B2/C32/D0/S32 (5.5%) 3. H0/A0/B1/C32/D1/S32 (4.5%) 4. H0/A0/B0/C32/D2/S32 (2.9%) 5. H8/A0/B0/C32/D0/S26 (2%) 6. H10/A0/B0/C32/D0/S24 (1.5%) 7. H0/A0/B0/C32/D0/S32 (1.3%) 8. H0/A0/B8/C26/D0/S32 (1.1%) 9. H1/A0/B1/C32/D0/S32 (0.9%) 10. H1/A0/B0/C32/D0/S32 (0.5%) | J13: 本期无显著变化 | K13: 1. 恶之波动 (99.5%) 2. 流星群 (93.4%) 3. 急速折返 (76.2%) 4. 喷射火焰 (53.5%) 5. 大字爆炎 (26.7%) | L13: 6. 加农光炮 (12.9%) 7. 大地之力 (7.8%) 8. 诡计 (6.4%) 9. 挑衅 (5.3%) 10. 隐形岩 (3.8%) | M13: 1. 讲究围巾 (84%) 2. 生命宝珠 (4.5%) 3. 气势披带 (2.8%) 4. 吃剩的东西 (2.6%) 5. 木子果 (1.3%) | N13: 6. 文柚果 (1.3%) 7. 白色香草 (0.8%) 8. 黑色眼镜 (0.5%) 9. 达人带 (0.5%) 10. 莓榴果 (0.4%) | O13: 1. 内敛 +C -A (70.6%) 2. 胆小 +S -A (27.9%) 3. 慢吞吞 +C -B (0.4%) 4. 天真 +S -D (0.2%) 5. 马虎 +C -D (0.2%) | P13: 6. 急躁 +S -B (0.2%) 7. 大胆 +B -A (0.1%) 8. 爽朗 +S -C (0.1%) 9. 温和 +D -A (0.1%) 10. 冷静 +C -S (0.1%) | Q13: 1. H2/A0/B0/C32/D0/S32 (71.9%) 2. H0/A0/B2/C32/D0/S32 (5.5%) 3. H0/A0/B1/C32/D1/S32 (4.5%) 4. H0/A0/B0/C32/D2/S32 (2.9%) 5. H8/A0/B0/C32/D0/S26 (2%) | R13: 6. H10/A0/B0/C32/D0/S24 (1.5%) 7. H0/A0/B0/C32/D0/S32 (1.3%) 8. H0/A0/B8/C26/D0/S32 (1.1%) 9. H1/A0/B1/C32/D0/S32 (0.9%) 10. H1/A0/B0/C32/D0/S32 (0.5%) | S13: 1. 巨金怪 2. 西狮海壬 3. 谜拟丘 4. 烈咬陆鲨 5. 河马兽 | T13: 6. 喷火龙 7. 火焰鸡 8. 铝钢桥龙 9. 妖火红狐 10. 暴鲤龙
... A51: 50 | B51: 毒藻龙 | C51: Dragalge | D51: 1. 快速折返 (91%) 2. 流星群 (90.5%) 3. 剧毒 (65.6%) 4. 毒菱 (35.5%) 5. 十万伏特 (28.3%) 6. 污泥波 (28.2%) 7. 污泥炸弹 (19.3%) 8. 热水 (10%) 9. 暗影球 (6.4%) 10. 守住 (4.3%) | E51: 1. 毒藻龙进化石 (96.1%) 2. 生命宝珠 (0.7%) 3. 白色香草 (0.5%) 4. 龙之牙 (0.5%) 5. 文柚果 (0.4%) 6. 吃剩的东西 (0.2%) 7. 气势披带 (0.1%) 8. 喷火龙进化石Ｙ (0.1%) 9. 腰木果 (0.1%) 10. 大针蜂进化石 (0.1%) | F51: 1. 适应力 (64.6%) 2. 毒刺 (31%) 3. 毒手 (4.5%) | G51: 1. 自大 +D -S (46.2%) 2. 温和 +D -A (22.1%) 3. 内敛 +C -A (10%) 4. 冷静 +C -S (8.5%) 5. 大胆 +B -A (6.4%) 6. 悠闲 +B -S (5.7%) 7. 慎重 +D -C (0.3%) 8. 温顺 +D -B (0.1%) 9. 急躁 +S -B (0.1%) 10. 胆小 +S -A (0.1%) | H51: 1. 钢铠鸦 2. 长毛巨魔 3. 烈咬陆鲨 4. 月亮伊布 5. 骨纹巨声鳄 6. 魔幻假面喵 7. 谜拟丘 8. 河马兽 9. 火焰鸡 10. 大剑鬼（洗翠的样子） | I51: 1. H32/A0/B2/C0/D32/S0 (21.5%) 2. H32/A0/B17/C0/D17/S0 (7.6%) 3. H32/A0/B0/C2/D32/S0 (5.7%) 4. H32/A0/B32/C0/D2/S0 (4.4%) 5. H31/A0/B18/C0/D17/S0 (3.8%) 6. H31/A0/B3/C0/D32/S0 (3.8%) 7. H32/A0/B0/C32/D2/S0 (3.6%) 8. H32/A0/B2/C32/D0/S0 (2.9%) 9. H31/A0/B32/C0/D3/S0 (2.5%) 10. H31/A0/B0/C3/D32/S0 (2.1%) | J51: 本期无显著变化 | K51: 1. 快速折返 (91%) 2. 流星群 (90.5%) 3. 剧毒 (65.6%) 4. 毒菱 (35.5%) 5. 十万伏特 (28.3%) | L51: 6. 污泥波 (28.2%) 7. 污泥炸弹 (19.3%) 8. 热水 (10%) 9. 暗影球 (6.4%) 10. 守住 (4.3%) | M51: 1. 毒藻龙进化石 (96.1%) 2. 生命宝珠 (0.7%) 3. 白色香草 (0.5%) 4. 龙之牙 (0.5%) 5. 文柚果 (0.4%) | N51: 6. 吃剩的东西 (0.2%) 7. 气势披带 (0.1%) 8. 喷火龙进化石Ｙ (0.1%) 9. 腰木果 (0.1%) 10. 大针蜂进化石 (0.1%) | O51: 1. 自大 +D -S (46.2%) 2. 温和 +D -A (22.1%) 3. 内敛 +C -A (10%) 4. 冷静 +C -S (8.5%) 5. 大胆 +B -A (6.4%) | P51: 6. 悠闲 +B -S (5.7%) 7. 慎重 +D -C (0.3%) 8. 温顺 +D -B (0.1%) 9. 急躁 +S -B (0.1%) 10. 胆小 +S -A (0.1%) | Q51: 1. H32/A0/B2/C0/D32/S0 (21.5%) 2. H32/A0/B17/C0/D17/S0 (7.6%) 3. H32/A0/B0/C2/D32/S0 (5.7%) 4. H32/A0/B32/C0/D2/S0 (4.4%) 5. H31/A0/B18/C0/D17/S0 (3.8%) | R51: 6. H31/A0/B3/C0/D32/S0 (3.8%) 7. H32/A0/B0/C32/D2/S0 (3.6%) 8. H32/A0/B2/C32/D0/S0 (2.9%) 9. H31/A0/B32/C0/D3/S0 (2.5%) 10. H31/A0/B0/C3/D32/S0 (2.1%) | S51: 1. 钢铠鸦 2. 长毛巨魔 3. 烈咬陆鲨 4. 月亮伊布 5. 骨纹巨声鳄 | T51: 6. 魔幻假面喵 7. 谜拟丘 8. 河马兽 9. 火焰鸡 10. 大剑鬼（洗翠的样子）
A52: 51 | B52: 花叶蒂（永恒之花） | C52: Floette-Eternal | D52: 1. 月亮之力 (90.1%) 2. 冥想 (86.7%) 3. 吸取之吻 (76.9%) 4. 破灭之光 (68.2%) 5. 精神强念 (26.8%) 6. 光合作用 (16.6%) 7. 替身 (8.4%) 8. 戏法 (3.1%) 9. 终极吸取 (2.5%) 10. 撒娇 (2.2%) | E52: 1. 花叶蒂进化石 (95.1%) 2. 讲究围巾 (3.5%) 3. 生命宝珠 (0.8%) 4. 气势披带 (0.1%) 5. 文柚果 (0.1%) 6. 大根茎 (0%) 7. 妖精之羽 (0%) 8. 狠辣椒进化石 (0%) 9. 霹霹果 (0%) 10. 妖火红狐进化石 (0%) | F52: 1. 花幕 (96.5%) 2. 共生 (3.5%) | G52: 1. 胆小 +S -A (64.6%) 2. 内敛 +C -A (30.6%) 3. 大胆 +B -A (4.5%) 4. 温和 +D -A (0.2%) 5. 天真 +S -D (0.1%) 6. 爽朗 +S -C (0%) 7. 冷静 +C -S (0%) | I52: 1. H0/A0/B6/C28/D0/S32 (22.8%) 2. H2/A0/B0/C32/D0/S32 (18%) 3. H0/A0/B2/C32/D0/S32 (4.3%) 4. H6/A0/B7/C32/D0/S21 (4%) 5. H2/A0/B11/C21/D0/S32 (2.9%) 6. H9/A0/B10/C15/D0/S32 (2.4%) 7. H32/A0/B29/C5/D0/S0 (2.1%) 8. H0/A0/B10/C24/D0/S32 (1.8%) 9. H26/A0/B0/C8/D0/S32 (1.6%) 10. H32/A0/B32/C2/D0/S0 (1.3%) | J52: 本期无显著变化 | K52: 1. 月亮之力 (90.1%) 2. 冥想 (86.7%) 3. 吸取之吻 (76.9%) 4. 破灭之光 (68.2%) 5. 精神强念 (26.8%) | L52: 6. 光合作用 (16.6%) 7. 替身 (8.4%) 8. 戏法 (3.1%) 9. 终极吸取 (2.5%) 10. 撒娇 (2.2%) | M52: 1. 花叶蒂进化石 (95.1%) 2. 讲究围巾 (3.5%) 3. 生命宝珠 (0.8%) 4. 气势披带 (0.1%) 5. 文柚果 (0.1%) | N52: 6. 大根茎 (0%) 7. 妖精之羽 (0%) 8. 狠辣椒进化石 (0%) 9. 霹霹果 (0%) 10. 妖火红狐进化石 (0%) | O52: 1. 胆小 +S -A (64.6%) 2. 内敛 +C -A (30.6%) 3. 大胆 +B -A (4.5%) 4. 温和 +D -A (0.2%) | P52: 5. 天真 +S -D (0.1%) 6. 爽朗 +S -C (0%) 7. 冷静 +C -S (0%) | Q52: 1. H0/A0/B6/C28/D0/S32 (22.8%) 2. H2/A0/B0/C32/D0/S32 (18%) 3. H0/A0/B2/C32/D0/S32 (4.3%) 4. H6/A0/B7/C32/D0/S21 (4%) 5. H2/A0/B11/C21/D0/S32 (2.9%) | R52: 6. H9/A0/B10/C15/D0/S32 (2.4%) 7. H32/A0/B29/C5/D0/S0 (2.1%) 8. H0/A0/B10/C24/D0/S32 (1.8%) 9. H26/A0/B0/C8/D0/S32 (1.6%) 10. H32/A0/B32/C2/D0/S0 (1.3%)
A53: 52 | B53: 超能艳鸵 | C53: Espathra | D53: 1. 琉光冲激 (89.7%) 2. 守住 (86.7%) 3. 魔法闪耀 (64.8%) 4. 暗影球 (51.9%) 5. 接棒 (39.3%) 6. 冥想 (34.5%) 7. 替身 (8.6%) 8. 能量球 (5%) 9. 辅助力量 (3.5%) 10. 反射壁 (2.9%) | E53: 1. 气势披带 (64.2%) 2. 文柚果 (14.1%) 3. 吃剩的东西 (8.9%) 4. 心灵香草 (2.8%) 5. 刺耳果 (2.2%) 6. 光之黏土 (1.5%) 7. 佛柑果 (1.2%) 8. 木子果 (1.1%) 9. 弯曲的汤匙 (0.7%) 10. 光粉 (0.6%) | F53: 1. 加速 (99.7%) 2. 跟风 (0.2%) 3. 察觉 (0%) | G53: 1. 内敛 +C -A (59.3%) 2. 大胆 +B -A (19.3%) 3. 胆小 +S -A (18.8%) 4. 温和 +D -A (2.1%) 5. 淘气 +B -C (0.2%) 6. 慢吞吞 +C -B (0.1%) 7. 悠闲 +B -S (0.1%) 8. 急躁 +S -B (0.1%) 9. 自大 +D -S (0.1%) 10. 勇敢 +A -S (0%) | H53: 1. 谜拟丘 2. 甲贺忍蛙 3. 铝钢桥龙 4. 烈咬陆鲨 5. 路卡利欧 6. 火焰鸡 7. 彩粉蝶 8. 皮可西 9. 长耳兔 10. 快龙 | I53: 1. H2/A0/B0/C32/D0/S32 (26.9%) 2. H1/A0/B1/C32/D0/S32 (22.7%) 3. H32/A0/B32/C0/D2/S0 (3.2%) 4. H31/A0/B26/C0/D0/S9 (2.7%) 5. H1/A0/B0/C32/D1/S32 (2%) 6. H0/A0/B2/C32/D0/S32 (1.8%) 7. H32/A0/B32/C0/D0/S2 (1.3%) 8. H32/A0/B30/C0/D2/S2 (1.2%) 9. H25/A0/B32/C0/D0/S9 (0.9%) 10. H0/A0/B0/C32/D0/S32 (0.9%) | J53: 本期无显著变化 | K53: 1. 琉光冲激 (89.7%) 2. 守住 (86.7%) 3. 魔法闪耀 (64.8%) 4. 暗影球 (51.9%) 5. 接棒 (39.3%) | L53: 6. 冥想 (34.5%) 7. 替身 (8.6%) 8. 能量球 (5%) 9. 辅助力量 (3.5%) 10. 反射壁 (2.9%) | M53: 1. 气势披带 (64.2%) 2. 文柚果 (14.1%) 3. 吃剩的东西 (8.9%) 4. 心灵香草 (2.8%) 5. 刺耳果 (2.2%) | N53: 6. 光之黏土 (1.5%) 7. 佛柑果 (1.2%) 8. 木子果 (1.1%) 9. 弯曲的汤匙 (0.7%) 10. 光粉 (0.6%) | O53: 1. 内敛 +C -A (59.3%) 2. 大胆 +B -A (19.3%) 3. 胆小 +S -A (18.8%) 4. 温和 +D -A (2.1%) 5. 淘气 +B -C (0.2%) | P53: 6. 慢吞吞 +C -B (0.1%) 7. 悠闲 +B -S (0.1%) 8. 急躁 +S -B (0.1%) 9. 自大 +D -S (0.1%) 10. 勇敢 +A -S (0%) | Q53: 1. H2/A0/B0/C32/D0/S32 (26.9%) 2. H1/A0/B1/C32/D0/S32 (22.7%) 3. H32/A0/B32/C0/D2/S0 (3.2%) 4. H31/A0/B26/C0/D0/S9 (2.7%) 5. H1/A0/B0/C32/D1/S32 (2%) | R53: 6. H0/A0/B2/C32/D0/S32 (1.8%) 7. H32/A0/B32/C0/D0/S2 (1.3%) 8. H32/A0/B30/C0/D2/S2 (1.2%) 9. H25/A0/B32/C0/D0/S9 (0.9%) 10. H0/A0/B0/C32/D0/S32 (0.9%) | S53: 1. 谜拟丘 2. 甲贺忍蛙 3. 铝钢桥龙 4. 烈咬陆鲨 5. 路卡利欧 | T53: 6. 火焰鸡 7. 彩粉蝶 8. 皮可西 9. 长耳兔 10. 快龙
A54: 53 | B54: 卡比兽 | C54: Snorlax | D54: 1. 地震 (70.3%) 2. 地裂 (56.7%) 3. 睡觉 (51.2%) 4. 击落 (38.9%) 5. 哈欠 (28.7%) 6. 冰冻拳 (24.2%) 7. 玉石俱碎 (13.8%) 8. 泰山压顶 (13.1%) 9. 双倍奉还 (11.4%) 10. 守住 (8.3%) | E54: 1. 吃剩的东西 (53.2%) 2. 零余果 (15.3%) 3. 莲蒲果 (11.7%) 4. 文柚果 (10%) 5. 木子果 (3.9%) 6. 丝绸围巾 (1.8%) 7. 达人带 (1.5%) 8. 先制之爪 (0.8%) 9. 生命宝珠 (0.4%) 10. 力量头带 (0.4%) | F54: 1. 厚脂肪 (92.3%) 2. 免疫 (7.1%) 3. 贪吃鬼 (0.5%) | G54: 1. 慎重 +D -C (59.7%) 2. 固执 +A -C (19.4%) 3. 淘气 +B -C (12.8%) 4. 悠闲 +B -S (2.9%) 5. 自大 +D -S (2.7%) 6. 勇敢 +A -S (1.4%) 7. 温和 +D -A (0.8%) 8. 大胆 +B -A (0.1%) 9. 慢吞吞 +C -B (0.1%) 10. 爽朗 +S -C (0.1%) | H54: 1. 呆壳兽 2. 超坏星 3. 皮可西 4. 大竺葵 5. 大剑鬼（洗翠的样子） 6. 烈咬陆鲨 7. 骨纹巨声鳄 8. 谜拟丘 9. 魔幻假面喵 10. 铝钢桥龙 | I54: 1. H32/A0/B2/C0/D32/S0 (32.8%) 2. H32/A0/B32/C0/D2/S0 (7.4%) 3. H32/A2/B0/C0/D32/S0 (6.5%) 4. H2/A32/B32/C0/D0/S0 (6%) 5. H0/A32/B32/C0/D2/S0 (3.8%) 6. H2/A0/B32/C0/D32/S0 (2.4%) 7. H2/A32/B0/C0/D32/S0 (2.4%) 8. H32/A32/B2/C0/D0/S0 (2.3%) 9. H22/A0/B32/C0/D12/S0 (1.9%) 10. H32/A2/B32/C0/D0/S0 (1.8%) | J54: 本期无显著变化 | K54: 1. 地震 (70.3%) 2. 地裂 (56.7%) 3. 睡觉 (51.2%) 4. 击落 (38.9%) 5. 哈欠 (28.7%) | L54: 6. 冰冻拳 (24.2%) 7. 玉石俱碎 (13.8%) 8. 泰山压顶 (13.1%) 9. 双倍奉还 (11.4%) 10. 守住 (8.3%) | M54: 1. 吃剩的东西 (53.2%) 2. 零余果 (15.3%) 3. 莲蒲果 (11.7%) 4. 文柚果 (10%) 5. 木子果 (3.9%) | N54: 6. 丝绸围巾 (1.8%) 7. 达人带 (1.5%) 8. 先制之爪 (0.8%) 9. 生命宝珠 (0.4%) 10. 力量头带 (0.4%) | O54: 1. 慎重 +D -C (59.7%) 2. 固执 +A -C (19.4%) 3. 淘气 +B -C (12.8%) 4. 悠闲 +B -S (2.9%) 5. 自大 +D -S (2.7%) | P54: 6. 勇敢 +A -S (1.4%) 7. 温和 +D -A (0.8%) 8. 大胆 +B -A (0.1%) 9. 慢吞吞 +C -B (0.1%) 10. 爽朗 +S -C (0.1%) | Q54: 1. H32/A0/B2/C0/D32/S0 (32.8%) 2. H32/A0/B32/C0/D2/S0 (7.4%) 3. H32/A2/B0/C0/D32/S0 (6.5%) 4. H2/A32/B32/C0/D0/S0 (6%) 5. H0/A32/B32/C0/D2/S0 (3.8%) | R54: 6. H2/A0/B32/C0/D32/S0 (2.4%) 7. H2/A32/B0/C0/D32/S0 (2.4%) 8. H32/A32/B2/C0/D0/S0 (2.3%) 9. H22/A0/B32/C0/D12/S0 (1.9%) 10. H32/A2/B32/C0/D0/S0 (1.8%) | S54: 1. 呆壳兽 2. 超坏星 3. 皮可西 4. 大竺葵 5. 大剑鬼（洗翠的样子） | T54: 6. 烈咬陆鲨 7. 骨纹巨声鳄 8. 谜拟丘 9. 魔幻假面喵 10. 铝钢桥龙
A55: 54 | B55: 狠辣椒 | C55: Scovillain | D55: 1. 寄生种子 (94.3%) 2. 守住 (91.1%) 3. 终极吸取 (67.7%) 4. 喷射火焰 (60.9%) 5. 飞叶风暴 (19.6%) 6. 妒火 (17.8%) 7. 替身 (16.4%) 8. 闪焰冲锋 (9.9%) 9. 过热 (7.5%) 10. 愤怒门牙 (2.2%) | E55: 1. 狠辣椒进化石 (88.6%) 2. 吃剩的东西 (9.2%) 3. 大根茎 (0.5%) 4. 生命宝珠 (0.5%) 5. 文柚果 (0.2%) 6. 白色香草 (0.2%) 7. 光粉 (0.2%) 8. 木炭 (0.2%) 9. 气势披带 (0.2%) 10. 棱瓜果 (0.1%) | F55: 1. 心情不定 (54.3%) 2. 不眠 (42.1%) 3. 叶绿素 (3.6%) | G55: 1. 大胆 +B -A (49.1%) 2. 内敛 +C -A (16.1%) 3. 温和 +D -A (14.7%) 4. 慎重 +D -C (8.5%) 5. 胆小 +S -A (7.7%) 6. 固执 +A -C (0.7%) 7. 悠闲 +B -S (0.7%) 8. 淘气 +B -C (0.6%) 9. 冷静 +C -S (0.6%) 10. 自大 +D -S (0.5%) | H55: 1. 烈咬陆鲨 2. 班基拉斯 3. 谜拟丘 4. 河马兽 5. 龙头地鼠 6. 铝钢桥龙 7. 魔幻假面喵 8. 快龙 9. 超坏星 10. 幽尾玄鱼 | I55: 1. H32/A0/B32/C0/D2/S0 (18.3%) 2. H31/A0/B3/C0/D32/S0 (9.5%) 3. H32/A0/B32/C2/D0/S0 (7.3%) 4. H32/A0/B2/C0/D32/S0 (7.1%) 5. H32/A0/B32/C0/D0/S2 (6.2%) 6. H31/A0/B32/C0/D3/S0 (3.3%) 7. H31/A0/B32/C2/D1/S0 (2.4%) 8. H21/A0/B18/C0/D6/S21 (2%) 9. H31/A0/B32/C3/D0/S0 (1.5%) 10. H32/A0/B7/C4/D22/S1 (1.5%) | J55: 本期无显著变化 | K55: 1. 寄生种子 (94.3%) 2. 守住 (91.1%) 3. 终极吸取 (67.7%) 4. 喷射火焰 (60.9%) 5. 飞叶风暴 (19.6%) | L55: 6. 妒火 (17.8%) 7. 替身 (16.4%) 8. 闪焰冲锋 (9.9%) 9. 过热 (7.5%) 10. 愤怒门牙 (2.2%) | M55: 1. 狠辣椒进化石 (88.6%) 2. 吃剩的东西 (9.2%) 3. 大根茎 (0.5%) 4. 生命宝珠 (0.5%) 5. 文柚果 (0.2%) | N55: 6. 白色香草 (0.2%) 7. 光粉 (0.2%) 8. 木炭 (0.2%) 9. 气势披带 (0.2%) 10. 棱瓜果 (0.1%) | O55: 1. 大胆 +B -A (49.1%) 2. 内敛 +C -A (16.1%) 3. 温和 +D -A (14.7%) 4. 慎重 +D -C (8.5%) 5. 胆小 +S -A (7.7%) | P55: 6. 固执 +A -C (0.7%) 7. 悠闲 +B -S (0.7%) 8. 淘气 +B -C (0.6%) 9. 冷静 +C -S (0.6%) 10. 自大 +D -S (0.5%) | Q55: 1. H32/A0/B32/C0/D2/S0 (18.3%) 2. H31/A0/B3/C0/D32/S0 (9.5%) 3. H32/A0/B32/C2/D0/S0 (7.3%) 4. H32/A0/B2/C0/D32/S0 (7.1%) 5. H32/A0/B32/C0/D0/S2 (6.2%) | R55: 6. H31/A0/B32/C0/D3/S0 (3.3%) 7. H31/A0/B32/C2/D1/S0 (2.4%) 8. H21/A0/B18/C0/D6/S21 (2%) 9. H31/A0/B32/C3/D0/S0 (1.5%) 10. H32/A0/B7/C4/D22/S1 (1.5%) | S55: 1. 烈咬陆鲨 2. 班基拉斯 3. 谜拟丘 4. 河马兽 5. 龙头地鼠 | T55: 6. 铝钢桥龙 7. 魔幻假面喵 8. 快龙 9. 超坏星 10. 幽尾玄鱼
A56: 55 | B56: 仙子伊布 | C56: Sylveon | D56: 1. 巨声 (98.2%) 2. 哈欠 (74.1%) 3. 电光一闪 (47.6%) 4. 魔法火焰 (44.1%) 5. 祈愿 (41.9%) 6. 守住 (39.2%) 7. 冥想 (12.7%) 8. 破坏光线 (9.2%) 9. 暗影球 (9%) 10. 看穿 (2.7%) | E56: 1. 吃剩的东西 (46.5%) 2. 妖精之羽 (37.5%) 3. 文柚果 (9.3%) 4. 生命宝珠 (1.5%) 5. 霹霹果 (1.2%) 6. 先制之爪 (0.9%) 7. 零余果 (0.7%) 8. 木子果 (0.5%) 9. 气势披带 (0.3%) 10. 光之黏土 (0.3%) | F56: 1. 妖精皮肤 (99.1%) 2. 迷人之躯 (0.9%) | G56: 1. 内敛 +C -A (46.9%) 2. 大胆 +B -A (38.1%) 3. 温和 +D -A (5.8%) 4. 冷静 +C -S (5.2%) 5. 悠闲 +B -S (2.3%) 6. 胆小 +S -A (0.8%) 7. 慢吞吞 +C -B (0.4%) 8. 自大 +D -S (0.3%) 9. 马虎 +C -D (0.1%) 10. 认真 (0.1%) | H56: 1. 烈咬陆鲨 2. 铝钢桥龙 3. 暴鲤龙 4. 巨金怪 5. 喷火龙 6. 妖火红狐 7. 谜拟丘 8. 快龙 9. 甲贺忍蛙 10. 魔幻假面喵 | I56: 1. H32/A0/B32/C0/D2/S0 (16.3%) 2. H32/A0/B32/C0/D0/S2 (9.9%) 3. H32/A0/B0/C32/D0/S2 (9%) 4. H32/A0/B32/C2/D0/S0 (4.3%) 5. H19/A0/B8/C30/D0/S9 (3.9%) 6. H32/A0/B2/C32/D0/S0 (3.8%) 7. H21/A0/B10/C30/D2/S3 (3.2%) 8. H32/A0/B0/C32/D2/S0 (3.1%) 9. H31/A0/B32/C0/D3/S0 (2%) 10. H21/A0/B13/C32/D0/S0 (1.6%) | J56: 本期无显著变化 | K56: 1. 巨声 (98.2%) 2. 哈欠 (74.1%) 3. 电光一闪 (47.6%) 4. 魔法火焰 (44.1%) 5. 祈愿 (41.9%) | L56: 6. 守住 (39.2%) 7. 冥想 (12.7%) 8. 破坏光线 (9.2%) 9. 暗影球 (9%) 10. 看穿 (2.7%) | M56: 1. 吃剩的东西 (46.5%) 2. 妖精之羽 (37.5%) 3. 文柚果 (9.3%) 4. 生命宝珠 (1.5%) 5. 霹霹果 (1.2%) | N56: 6. 先制之爪 (0.9%) 7. 零余果 (0.7%) 8. 木子果 (0.5%) 9. 气势披带 (0.3%) 10. 光之黏土 (0.3%) | O56: 1. 内敛 +C -A (46.9%) 2. 大胆 +B -A (38.1%) 3. 温和 +D -A (5.8%) 4. 冷静 +C -S (5.2%) 5. 悠闲 +B -S (2.3%) | P56: 6. 胆小 +S -A (0.8%) 7. 慢吞吞 +C -B (0.4%) 8. 自大 +D -S (0.3%) 9. 马虎 +C -D (0.1%) 10. 认真 (0.1%) | Q56: 1. H32/A0/B32/C0/D2/S0 (16.3%) 2. H32/A0/B32/C0/D0/S2 (9.9%) 3. H32/A0/B0/C32/D0/S2 (9%) 4. H32/A0/B32/C2/D0/S0 (4.3%) 5. H19/A0/B8/C30/D0/S9 (3.9%) | R56: 6. H32/A0/B2/C32/D0/S0 (3.8%) 7. H21/A0/B10/C30/D2/S3 (3.2%) 8. H32/A0/B0/C32/D2/S0 (3.1%) 9. H31/A0/B32/C0/D3/S0 (2%) 10. H21/A0/B13/C32/D0/S0 (1.6%) | S56: 1. 烈咬陆鲨 2. 铝钢桥龙 3. 暴鲤龙 4. 巨金怪 5. 喷火龙 | T56: 6. 妖火红狐 7. 谜拟丘 8. 快龙 9. 甲贺忍蛙 10. 魔幻假面喵
A57: 56 | B57: 大狃拉 | C57: Sneasler | D57: 1. 近身战 (96.4%) 2. 克命爪 (94.4%) 3. 击掌奇袭 (47.6%) 4. 深渊突刺 (36.3%) 5. 急速折返 (25.1%) 6. 剑舞 (19.6%) 7. 杂技 (11.9%) 8. 暗影爪 (8.2%) 9. 岩崩 (8.1%) 10. 挑衅 (7.8%) | E57: 1. 白色香草 (39.2%) 2. 气势披带 (30.3%) 3. 文柚果 (10.2%) 4. 讲究围巾 (9.5%) 5. 生命宝珠 (4.4%) 6. 王者之证 (1%) 7. 电气球 (0.8%) 8. 先制之爪 (0.5%) 9. 毒针 (0.3%) 10. 贝壳之铃 (0.3%) | F57: 1. 轻装 (70.2%) 2. 毒手 (29.4%) 3. 压迫感 (0.4%) | G57: 1. 固执 +A -C (59.4%) 2. 爽朗 +S -C (34.8%) 3. 淘气 +B -C (2%) 4. 顽皮 +A -D (1.5%) 5. 怕寂寞 +A -B (0.7%) 6. 天真 +S -D (0.4%) 7. 慎重 +D -C (0.4%) 8. 急躁 +S -B (0.3%) 9. 坦率 (0.2%) 10. 温顺 +D -B (0.1%) | H57: 1. 烈咬陆鲨 2. 谜拟丘 3. 魔幻假面喵 4. 铝钢桥龙 5. 巨金怪 6. 暴鲤龙 7. 妖火红狐 8. 河马兽 9. 西狮海壬 10. 三首恶龙 | I57: 1. H2/A32/B0/C0/D0/S32 (51.3%) 2. H0/A32/B2/C0/D0/S32 (9.6%) 3. H0/A32/B0/C0/D2/S32 (5.8%) 4. H0/A32/B0/C0/D0/S32 (4.4%) 5. H4/A32/B0/C0/D0/S30 (1.5%) 6. H0/A32/B1/C0/D1/S32 (1.1%) 7. H29/A32/B0/C0/D0/S5 (1%) 8. H30/A10/B22/C0/D0/S4 (0.7%) 9. H1/A32/B0/C0/D0/S32 (0.7%) 10. H1/A32/B1/C0/D0/S32 (0.7%) | J57: 本期无显著变化 | K57: 1. 近身战 (96.4%) 2. 克命爪 (94.4%) 3. 击掌奇袭 (47.6%) 4. 深渊突刺 (36.3%) 5. 急速折返 (25.1%) | L57: 6. 剑舞 (19.6%) 7. 杂技 (11.9%) 8. 暗影爪 (8.2%) 9. 岩崩 (8.1%) 10. 挑衅 (7.8%) | M57: 1. 白色香草 (39.2%) 2. 气势披带 (30.3%) 3. 文柚果 (10.2%) 4. 讲究围巾 (9.5%) 5. 生命宝珠 (4.4%) | N57: 6. 王者之证 (1%) 7. 电气球 (0.8%) 8. 先制之爪 (0.5%) 9. 毒针 (0.3%) 10. 贝壳之铃 (0.3%) | O57: 1. 固执 +A -C (59.4%) 2. 爽朗 +S -C (34.8%) 3. 淘气 +B -C (2%) 4. 顽皮 +A -D (1.5%) 5. 怕寂寞 +A -B (0.7%) | P57: 6. 天真 +S -D (0.4%) 7. 慎重 +D -C (0.4%) 8. 急躁 +S -B (0.3%) 9. 坦率 (0.2%) 10. 温顺 +D -B (0.1%) | Q57: 1. H2/A32/B0/C0/D0/S32 (51.3%) 2. H0/A32/B2/C0/D0/S32 (9.6%) 3. H0/A32/B0/C0/D2/S32 (5.8%) 4. H0/A32/B0/C0/D0/S32 (4.4%) 5. H4/A32/B0/C0/D0/S30 (1.5%) | R57: 6. H0/A32/B1/C0/D1/S32 (1.1%) 7. H29/A32/B0/C0/D0/S5 (1%) 8. H30/A10/B22/C0/D0/S4 (0.7%) 9. H1/A32/B0/C0/D0/S32 (0.7%) 10. H1/A32/B1/C0/D0/S32 (0.7%) | S57: 1. 烈咬陆鲨 2. 谜拟丘 3. 魔幻假面喵 4. 铝钢桥龙 5. 巨金怪 | T57: 6. 暴鲤龙 7. 妖火红狐 8. 河马兽 9. 西狮海壬 10. 三首恶龙
A58: 57 | B58: 弃世猴 | C58: Annihilape | D58: 1. 愤怒之拳 (98.5%) 2. 吸取拳 (88.9%) 3. 健美 (80.9%) 4. 挑衅 (73.8%) 5. 隐形岩 (13.3%) 6. 冰冻拳 (6.9%) 7. 再来一次 (5.4%) 8. 投掷 (3.9%) 9. 岩石封锁 (3.9%) 10. 近身战 (3.4%) | E58: 1. 吃剩的东西 (49.5%) 2. 文柚果 (31.6%) 3. 电气球 (3.9%) 4. 木子果 (3.3%) 5. 气势披带 (2.8%) 6. 生命宝珠 (1.5%) 7. 零余果 (1.5%) 8. 讲究围巾 (1.1%) 9. 佛柑果 (0.6%) 10. 福禄果 (0.6%) | F58: 1. 不服输 (75%) 2. 干劲 (21.3%) 3. 精神力 (3.7%) | G58: 1. 固执 +A -C (45.6%) 2. 爽朗 +S -C (26.4%) 3. 慎重 +D -C (13.8%) 4. 淘气 +B -C (13.1%) 5. 勇敢 +A -S (0.3%) 6. 怕寂寞 +A -B (0.2%) 7. 胆小 +S -A (0.2%) 8. 顽皮 +A -D (0.1%) 9. 天真 +S -D (0.1%) 10. 乐天 +B -D (0.1%) | H58: 1. 烈咬陆鲨 2. 暴鲤龙 3. 巨金怪 4. 谜拟丘 5. 喷火龙 6. 九尾（阿罗拉的样子） 7. 妖火红狐 8. 铝钢桥龙 9. 魔幻假面喵 10. 甲贺忍蛙 | I58: 1. H32/A32/B2/C0/D0/S0 (7.8%) 2. H32/A2/B0/C0/D0/S32 (5.9%) 3. H24/A0/B12/C0/D0/S30 (4.8%) 4. H32/A32/B0/C0/D0/S2 (4.7%) 5. H32/A15/B1/C0/D18/S0 (3.8%) 6. H32/A5/B1/C0/D23/S5 (3.5%) 7. H2/A32/B0/C0/D0/S32 (2.8%) 8. H32/A0/B32/C0/D2/S0 (2.4%) 9. H32/A0/B2/C0/D32/S0 (2.2%) 10. H32/A2/B32/C0/D0/S0 (2.2%) | J58: 本期无显著变化 | K58: 1. 愤怒之拳 (98.5%) 2. 吸取拳 (88.9%) 3. 健美 (80.9%) 4. 挑衅 (73.8%) 5. 隐形岩 (13.3%) | L58: 6. 冰冻拳 (6.9%) 7. 再来一次 (5.4%) 8. 投掷 (3.9%) 9. 岩石封锁 (3.9%) 10. 近身战 (3.4%) | M58: 1. 吃剩的东西 (49.5%) 2. 文柚果 (31.6%) 3. 电气球 (3.9%) 4. 木子果 (3.3%) 5. 气势披带 (2.8%) | N58: 6. 生命宝珠 (1.5%) 7. 零余果 (1.5%) 8. 讲究围巾 (1.1%) 9. 佛柑果 (0.6%) 10. 福禄果 (0.6%) | O58: 1. 固执 +A -C (45.6%) 2. 爽朗 +S -C (26.4%) 3. 慎重 +D -C (13.8%) 4. 淘气 +B -C (13.1%) 5. 勇敢 +A -S (0.3%) | P58: 6. 怕寂寞 +A -B (0.2%) 7. 胆小 +S -A (0.2%) 8. 顽皮 +A -D (0.1%) 9. 天真 +S -D (0.1%) 10. 乐天 +B -D (0.1%) | Q58: 1. H32/A32/B2/C0/D0/S0 (7.8%) 2. H32/A2/B0/C0/D0/S32 (5.9%) 3. H24/A0/B12/C0/D0/S30 (4.8%) 4. H32/A32/B0/C0/D0/S2 (4.7%) 5. H32/A15/B1/C0/D18/S0 (3.8%) | R58: 6. H32/A5/B1/C0/D23/S5 (3.5%) 7. H2/A32/B0/C0/D0/S32 (2.8%) 8. H32/A0/B32/C0/D2/S0 (2.4%) 9. H32/A0/B2/C0/D32/S0 (2.2%) 10. H32/A2/B32/C0/D0/S0 (2.2%) | S58: 1. 烈咬陆鲨 2. 暴鲤龙 3. 巨金怪 4. 谜拟丘 5. 喷火龙 | T58: 6. 九尾（阿罗拉的样子） 7. 妖火红狐 8. 铝钢桥龙 9. 魔幻假面喵 10. 甲贺忍蛙
A59: 58 | B59: 象牙猪 | C59: Mamoswine | D59: 1. 地震 (99.6%) 2. 冰砾 (96.9%) 3. 冰锥 (50.3%) 4. 冰柱坠击 (33.5%) 5. 蛮干 (28.7%) 6. 隐形岩 (26.5%) 7. 岩石封锁 (24.7%) 8. 冷冻干燥 (7.6%) 9. 尖石攻击 (6.9%) 10. 岩崩 (4.8%) | E59: 1. 气势披带 (84%) 2. 生命宝珠 (4.4%) 3. 讲究围巾 (3.3%) 4. 文柚果 (2.6%) 5. 达人带 (1%) 6. 木子果 (1%) 7. 不融冰 (0.9%) 8. 先制之爪 (0.8%) 9. 莲蒲果 (0.7%) 10. 霹霹果 (0.3%) | F59: 1. 厚脂肪 (55.6%) 2. 迟钝 (42.8%) 3. 雪隐 (1.6%) | G59: 1. 固执 +A -C (73.9%) 2. 爽朗 +S -C (14.5%) 3. 顽皮 +A -D (5.8%) 4. 天真 +S -D (1.6%) 5. 淘气 +B -C (1.5%) 6. 怕寂寞 +A -B (1.3%) 7. 勇敢 +A -S (0.7%) 8. 慎重 +D -C (0.3%) 9. 马虎 +C -D (0.2%) 10. 急躁 +S -B (0.2%) | H59: 1. 谜拟丘 2. 西狮海壬 3. 巨金怪 4. 铝钢桥龙 5. 三首恶龙 6. 喷火龙 7. 魔幻假面喵 8. 暴鲤龙 9. 雷丘 10. 清洗洛托姆 | I59: 1. H2/A32/B0/C0/D0/S32 (49.1%) 2. H0/A32/B2/C0/D0/S32 (11.8%) 3. H0/A32/B0/C0/D2/S32 (8%) 4. H32/A32/B0/C0/D0/S2 (2.7%) 5. H0/A32/B0/C0/D0/S32 (2.5%) 6. H32/A32/B2/C0/D0/S0 (2.4%) 7. H0/A32/B0/C2/D0/S32 (2.1%) 8. H0/A32/B1/C0/D1/S32 (1.6%) 9. H32/A32/B0/C0/D2/S0 (1.5%) 10. H2/A32/B32/C0/D0/S0 (1.2%) | J59: 本期无显著变化 | K59: 1. 地震 (99.6%) 2. 冰砾 (96.9%) 3. 冰锥 (50.3%) 4. 冰柱坠击 (33.5%) 5. 蛮干 (28.7%) | L59: 6. 隐形岩 (26.5%) 7. 岩石封锁 (24.7%) 8. 冷冻干燥 (7.6%) 9. 尖石攻击 (6.9%) 10. 岩崩 (4.8%) | M59: 1. 气势披带 (84%) 2. 生命宝珠 (4.4%) 3. 讲究围巾 (3.3%) 4. 文柚果 (2.6%) 5. 达人带 (1%) | N59: 6. 木子果 (1%) 7. 不融冰 (0.9%) 8. 先制之爪 (0.8%) 9. 莲蒲果 (0.7%) 10. 霹霹果 (0.3%) | O59: 1. 固执 +A -C (73.9%) 2. 爽朗 +S -C (14.5%) 3. 顽皮 +A -D (5.8%) 4. 天真 +S -D (1.6%) 5. 淘气 +B -C (1.5%) | P59: 6. 怕寂寞 +A -B (1.3%) 7. 勇敢 +A -S (0.7%) 8. 慎重 +D -C (0.3%) 9. 马虎 +C -D (0.2%) 10. 急躁 +S -B (0.2%) | Q59: 1. H2/A32/B0/C0/D0/S32 (49.1%) 2. H0/A32/B2/C0/D0/S32 (11.8%) 3. H0/A32/B0/C0/D2/S32 (8%) 4. H32/A32/B0/C0/D0/S2 (2.7%) 5. H0/A32/B0/C0/D0/S32 (2.5%) | R59: 6. H32/A32/B2/C0/D0/S0 (2.4%) 7. H0/A32/B0/C2/D0/S32 (2.1%) 8. H0/A32/B1/C0/D1/S32 (1.6%) 9. H32/A32/B0/C0/D2/S0 (1.5%) 10. H2/A32/B32/C0/D0/S0 (1.2%) | S59: 1. 谜拟丘 2. 西狮海壬 3. 巨金怪 4. 铝钢桥龙 5. 三首恶龙 | T59: 6. 喷火龙 7. 魔幻假面喵 8. 暴鲤龙 9. 雷丘 10. 清洗洛托姆
A60: 59 | B60: 加热洛托姆 | C60: Rotom-Heat | D60: 1. 过热 (98.6%) 2. 伏特替换 (90.7%) 3. 磷火 (70.5%) 4. 十万伏特 (46.5%) 5. 戏法 (35%) 6. 分担痛楚 (14%) 7. 光墙 (10.1%) 8. 放电 (5.7%) 9. 诡计 (4.9%) 10. 移花接木 (4.7%) | E60: 1. 讲究围巾 (38%) 2. 文柚果 (26.5%) 3. 吃剩的东西 (23.6%) 4. 白色香草 (3.2%) 5. 生命宝珠 (1.3%) 6. 木炭 (1%) 7. 千香果 (0.9%) 8. 木子果 (0.9%) 9. 气势披带 (0.7%) 10. 零余果 (0.5%) | F60: 1. 飘浮 (100%) | G60: 1. 内敛 +C -A (47.9%) 2. 大胆 +B -A (21.2%) 3. 胆小 +S -A (20.4%) 4. 温和 +D -A (9.4%) 5. 悠闲 +B -S (0.5%) 6. 慢吞吞 +C -B (0.2%) 7. 自大 +D -S (0.2%) 8. 急躁 +S -B (0.1%) 9. 温顺 +D -B (0%) 10. 冷静 +C -S (0%) | H60: 1. 烈咬陆鲨 2. 巨金怪 3. 西狮海壬 4. 谜拟丘 5. 河马兽 6. 宝石海星 7. 三首恶龙 8. 暴鲤龙 9. 魔幻假面喵 10. 铝钢桥龙 | I60: 1. H2/A0/B0/C32/D0/S32 (25.1%) 2. H32/A0/B0/C5/D29/S0 (8.2%) 3. H32/A0/B32/C0/D2/S0 (5.7%) 4. H32/A0/B32/C2/D0/S0 (4.7%) 5. H32/A0/B0/C32/D0/S2 (4.6%) 6. H0/A0/B2/C32/D0/S32 (2.7%) 7. H0/A0/B0/C32/D2/S32 (2.1%) 8. H32/A0/B2/C32/D0/S0 (2.1%) 9. H32/A0/B32/C0/D0/S2 (1.8%) 10. H32/A0/B2/C0/D32/S0 (1.8%) | J60: 本期无显著变化 | K60: 1. 过热 (98.6%) 2. 伏特替换 (90.7%) 3. 磷火 (70.5%) 4. 十万伏特 (46.5%) 5. 戏法 (35%) | L60: 6. 分担痛楚 (14%) 7. 光墙 (10.1%) 8. 放电 (5.7%) 9. 诡计 (4.9%) 10. 移花接木 (4.7%) | M60: 1. 讲究围巾 (38%) 2. 文柚果 (26.5%) 3. 吃剩的东西 (23.6%) 4. 白色香草 (3.2%) 5. 生命宝珠 (1.3%) | N60: 6. 木炭 (1%) 7. 千香果 (0.9%) 8. 木子果 (0.9%) 9. 气势披带 (0.7%) 10. 零余果 (0.5%) | O60: 1. 内敛 +C -A (47.9%) 2. 大胆 +B -A (21.2%) 3. 胆小 +S -A (20.4%) 4. 温和 +D -A (9.4%) 5. 悠闲 +B -S (0.5%) | P60: 6. 慢吞吞 +C -B (0.2%) 7. 自大 +D -S (0.2%) 8. 急躁 +S -B (0.1%) 9. 温顺 +D -B (0%) 10. 冷静 +C -S (0%) | Q60: 1. H2/A0/B0/C32/D0/S32 (25.1%) 2. H32/A0/B0/C5/D29/S0 (8.2%) 3. H32/A0/B32/C0/D2/S0 (5.7%) 4. H32/A0/B32/C2/D0/S0 (4.7%) 5. H32/A0/B0/C32/D0/S2 (4.6%) | R60: 6. H0/A0/B2/C32/D0/S32 (2.7%) 7. H0/A0/B0/C32/D2/S32 (2.1%) 8. H32/A0/B2/C32/D0/S0 (2.1%) 9. H32/A0/B32/C0/D0/S2 (1.8%) 10. H32/A0/B2/C0/D32/S0 (1.8%) | S60: 1. 烈咬陆鲨 2. 巨金怪 3. 西狮海壬 4. 谜拟丘 5. 河马兽 | T60: 6. 宝石海星 7. 三首恶龙 8. 暴鲤龙 9. 魔幻假面喵 10. 铝钢桥龙
A61: 60 | B61: 呆壳兽 | C61: Slowbro | D61: 1. 偷懒 (88.4%) 2. 热水 (83.7%) 3. 铁壁 (66.3%) 4. 冰冻光束 (43.7%) 5. 扑击 (34.6%) 6. 冥想 (13.4%) 7. 喷射火焰 (11.9%) 8. 精神强念 (7.8%) 9. 戏法空间 (7.7%) 10. 瞬间失忆 (6.1%) | E61: 1. 呆壳兽进化石 (79.2%) 2. 文柚果 (7.8%) 3. 吃剩的东西 (4.6%) 4. 达人带 (3.5%) 5. 光粉 (1.3%) 6. 生命宝珠 (0.8%) 7. 先制之爪 (0.5%) 8. 木子果 (0.3%) 9. 博识眼镜 (0.2%) 10. 佛柑果 (0.2%) | F61: 1. 再生力 (94.4%) 2. 迟钝 (5.1%) 3. 我行我素 (0.5%) | G61: 1. 大胆 +B -A (71.6%) 2. 内敛 +C -A (11.7%) 3. 温和 +D -A (10.2%) 4. 悠闲 +B -S (3.2%) 5. 冷静 +C -S (1.5%) 6. 自大 +D -S (1.3%) 7. 淘气 +B -C (0.2%) 8. 胆小 +S -A (0.1%) 9. 固执 +A -C (0.1%) 10. 急躁 +S -B (0.1%) | H61: 1. 卡比兽 2. 超坏星 3. 皮可西 4. 大竺葵 5. 大剑鬼（洗翠的样子） 6. 烈咬陆鲨 7. 谜拟丘 8. 骨纹巨声鳄 9. 班基拉斯 10. 铝钢桥龙 | I61: 1. H32/A0/B32/C0/D2/S0 (40.3%) 2. H31/A0/B32/C0/D3/S0 (8%) 3. H32/A0/B32/C2/D0/S0 (6.5%) 4. H32/A0/B2/C0/D32/S0 (4.3%) 5. H32/A0/B0/C32/D2/S0 (2.8%) 6. H31/A0/B32/C3/D0/S0 (2%) 7. H32/A0/B0/C14/D20/S0 (1.9%) 8. H31/A0/B32/C1/D2/S0 (1.6%) 9. H32/A0/B32/C0/D0/S0 (1.6%) 10. H31/A0/B0/C16/D19/S0 (1.3%) | J61: 本期无显著变化 | K61: 1. 偷懒 (88.4%) 2. 热水 (83.7%) 3. 铁壁 (66.3%) 4. 冰冻光束 (43.7%) 5. 扑击 (34.6%) | L61: 6. 冥想 (13.4%) 7. 喷射火焰 (11.9%) 8. 精神强念 (7.8%) 9. 戏法空间 (7.7%) 10. 瞬间失忆 (6.1%) | M61: 1. 呆壳兽进化石 (79.2%) 2. 文柚果 (7.8%) 3. 吃剩的东西 (4.6%) 4. 达人带 (3.5%) 5. 光粉 (1.3%) | N61: 6. 生命宝珠 (0.8%) 7. 先制之爪 (0.5%) 8. 木子果 (0.3%) 9. 博识眼镜 (0.2%) 10. 佛柑果 (0.2%) | O61: 1. 大胆 +B -A (71.6%) 2. 内敛 +C -A (11.7%) 3. 温和 +D -A (10.2%) 4. 悠闲 +B -S (3.2%) 5. 冷静 +C -S (1.5%) | P61: 6. 自大 +D -S (1.3%) 7. 淘气 +B -C (0.2%) 8. 胆小 +S -A (0.1%) 9. 固执 +A -C (0.1%) 10. 急躁 +S -B (0.1%) | Q61: 1. H32/A0/B32/C0/D2/S0 (40.3%) 2. H31/A0/B32/C0/D3/S0 (8%) 3. H32/A0/B32/C2/D0/S0 (6.5%) 4. H32/A0/B2/C0/D32/S0 (4.3%) 5. H32/A0/B0/C32/D2/S0 (2.8%) | R61: 6. H31/A0/B32/C3/D0/S0 (2%) 7. H32/A0/B0/C14/D20/S0 (1.9%) 8. H31/A0/B32/C1/D2/S0 (1.6%) 9. H32/A0/B32/C0/D0/S0 (1.6%) 10. H31/A0/B0/C16/D19/S0 (1.3%) | S61: 1. 卡比兽 2. 超坏星 3. 皮可西 4. 大竺葵 5. 大剑鬼（洗翠的样子） | T61: 6. 烈咬陆鲨 7. 谜拟丘 8. 骨纹巨声鳄 9. 班基拉斯 10. 铝钢桥龙
A62: 61 | B62: 美纳斯 | C62: Milotic | D62: 1. 热水 (96.4%) 2. 自我再生 (96.1%) 3. 镜面反射 (67.2%) 4. 冰冻光束 (63.5%) 5. 黑雾 (33.5%) 6. 盘蜷 (4.7%) 7. 快速折返 (4.6%) 8. 魅诱之声 (4.6%) 9. 催眠术 (4%) 10. 冰冻之风 (3.7%) | E62: 1. 吃剩的东西 (66%) 2. 文柚果 (19.7%) 3. 木子果 (3.7%) 4. 烛木果 (1.8%) 5. 气势披带 (1.6%) 6. 光粉 (1.1%) 7. 神秘水滴 (1%) 8. 贝壳之铃 (0.9%) 9. 先制之爪 (0.7%) 10. 达人带 (0.6%) | F62: 1. 好胜 (68.3%) 2. 神奇鳞片 (19.9%) 3. 迷人之躯 (11.8%) | G62: 1. 大胆 +B -A (63.3%) 2. 温和 +D -A (24.6%) 3. 内敛 +C -A (7.7%) 4. 悠闲 +B -S (1.8%) 5. 自大 +D -S (1.1%) 6. 冷静 +C -S (0.4%) 7. 慎重 +D -C (0.3%) 8. 慢吞吞 +C -B (0.2%) 9. 温顺 +D -B (0.2%) 10. 胆小 +S -A (0.1%) | H62: 1. 烈咬陆鲨 2. 谜拟丘 3. 巨金怪 4. 三首恶龙 5. 魔幻假面喵 6. 耿鬼 7. 大嘴娃 8. 火焰鸡 9. 妖火红狐 10. 喷火龙 | I62: 1. H32/A0/B32/C0/D2/S0 (25.4%) 2. H32/A0/B32/C1/D1/S0 (6.1%) 3. H32/A0/B32/C2/D0/S0 (5%) 4. H31/A0/B32/C0/D3/S0 (4.9%) 5. H32/A0/B2/C0/D32/S0 (4.6%) 6. H32/A0/B0/C2/D32/S0 (3.4%) 7. H32/A0/B32/C0/D0/S2 (3.1%) 8. H32/A0/B27/C0/D0/S7 (2.3%) 9. H2/A0/B32/C0/D32/S0 (1.8%) 10. H32/A0/B32/C0/D0/S0 (1.6%) | J62: 本期无显著变化 | K62: 1. 热水 (96.4%) 2. 自我再生 (96.1%) 3. 镜面反射 (67.2%) 4. 冰冻光束 (63.5%) 5. 黑雾 (33.5%) | L62: 6. 盘蜷 (4.7%) 7. 快速折返 (4.6%) 8. 魅诱之声 (4.6%) 9. 催眠术 (4%) 10. 冰冻之风 (3.7%) | M62: 1. 吃剩的东西 (66%) 2. 文柚果 (19.7%) 3. 木子果 (3.7%) 4. 烛木果 (1.8%) 5. 气势披带 (1.6%) | N62: 6. 光粉 (1.1%) 7. 神秘水滴 (1%) 8. 贝壳之铃 (0.9%) 9. 先制之爪 (0.7%) 10. 达人带 (0.6%) | O62: 1. 大胆 +B -A (63.3%) 2. 温和 +D -A (24.6%) 3. 内敛 +C -A (7.7%) 4. 悠闲 +B -S (1.8%) 5. 自大 +D -S (1.1%) | P62: 6. 冷静 +C -S (0.4%) 7. 慎重 +D -C (0.3%) 8. 慢吞吞 +C -B (0.2%) 9. 温顺 +D -B (0.2%) 10. 胆小 +S -A (0.1%) | Q62: 1. H32/A0/B32/C0/D2/S0 (25.4%) 2. H32/A0/B32/C1/D1/S0 (6.1%) 3. H32/A0/B32/C2/D0/S0 (5%) 4. H31/A0/B32/C0/D3/S0 (4.9%) 5. H32/A0/B2/C0/D32/S0 (4.6%) | R62: 6. H32/A0/B0/C2/D32/S0 (3.4%) 7. H32/A0/B32/C0/D0/S2 (3.1%) 8. H32/A0/B27/C0/D0/S7 (2.3%) 9. H2/A0/B32/C0/D32/S0 (1.8%) 10. H32/A0/B32/C0/D0/S0 (1.6%) | S62: 1. 烈咬陆鲨 2. 谜拟丘 3. 巨金怪 4. 三首恶龙 5. 魔幻假面喵 | T62: 6. 耿鬼 7. 大嘴娃 8. 火焰鸡 9. 妖火红狐 10. 喷火龙
A63: 62 | B63: 蜥蜴王 | C63: Sceptile | D63: 1. 龙之波动 (88.3%) 2. 大地之力 (82.2%) 3. 飞叶风暴 (76.2%) 4. 断尾 (59.1%) 5. 能量球 (20.1%) 6. 替身 (17.4%) 7. 真空波 (15.2%) 8. 真气弹 (13.3%) 9. 蛮干 (4.9%) 10. 终极吸取 (3.9%) | E63: 1. 蜥蜴王进化石 (82.1%) 2. 气势披带 (5.3%) 3. 文柚果 (4.8%) 4. 白色香草 (2.5%) 5. 讲究围巾 (1.8%) 6. 橙橙果 (0.4%) 7. 吃剩的东西 (0.2%) 8. 生命宝珠 (0.2%) 9. 光粉 (0.1%) 10. 巧可果 (0.1%) | F63: 1. 茂盛 (81.9%) 2. 轻装 (18.1%) | G63: 1. 胆小 +S -A (85.1%) 2. 内敛 +C -A (8.9%) 3. 天真 +S -D (1.1%) 4. 大胆 +B -A (1%) 5. 爽朗 +S -C (0.8%) 6. 固执 +A -C (0.7%) 7. 急躁 +S -B (0.5%) 8. 马虎 +C -D (0.4%) 9. 慢吞吞 +C -B (0.3%) 10. 怕寂寞 +A -B (0.3%) | H63: 1. 烈咬陆鲨 2. 河马兽 3. 谜拟丘 4. 西狮海壬 5. 火焰鸡 6. 铝钢桥龙 7. 暴鲤龙 8. 苍炎刃鬼 9. 甲贺忍蛙 10. 骨纹巨声鳄 | I63: 1. H2/A0/B0/C32/D0/S32 (69%) 2. H0/A0/B2/C32/D0/S32 (8.4%) 3. H0/A0/B0/C32/D2/S32 (3.8%) 4. H1/A0/B1/C32/D0/S32 (3.1%) 5. H2/A0/B1/C32/D0/S31 (1.7%) 6. H4/A0/B0/C32/D0/S30 (1.2%) 7. H2/A32/B0/C0/D0/S32 (0.9%) 8. H0/A2/B0/C32/D0/S32 (0.9%) 9. H0/A0/B0/C32/D0/S32 (0.7%) 10. H3/A0/B0/C32/D0/S31 (0.6%) | J63: 本期无显著变化 | K63: 1. 龙之波动 (88.3%) 2. 大地之力 (82.2%) 3. 飞叶风暴 (76.2%) 4. 断尾 (59.1%) 5. 能量球 (20.1%) | L63: 6. 替身 (17.4%) 7. 真空波 (15.2%) 8. 真气弹 (13.3%) 9. 蛮干 (4.9%) 10. 终极吸取 (3.9%) | M63: 1. 蜥蜴王进化石 (82.1%) 2. 气势披带 (5.3%) 3. 文柚果 (4.8%) 4. 白色香草 (2.5%) 5. 讲究围巾 (1.8%) | N63: 6. 橙橙果 (0.4%) 7. 吃剩的东西 (0.2%) 8. 生命宝珠 (0.2%) 9. 光粉 (0.1%) 10. 巧可果 (0.1%) | O63: 1. 胆小 +S -A (85.1%) 2. 内敛 +C -A (8.9%) 3. 天真 +S -D (1.1%) 4. 大胆 +B -A (1%) 5. 爽朗 +S -C (0.8%) | P63: 6. 固执 +A -C (0.7%) 7. 急躁 +S -B (0.5%) 8. 马虎 +C -D (0.4%) 9. 慢吞吞 +C -B (0.3%) 10. 怕寂寞 +A -B (0.3%) | Q63: 1. H2/A0/B0/C32/D0/S32 (69%) 2. H0/A0/B2/C32/D0/S32 (8.4%) 3. H0/A0/B0/C32/D2/S32 (3.8%) 4. H1/A0/B1/C32/D0/S32 (3.1%) 5. H2/A0/B1/C32/D0/S31 (1.7%) | R63: 6. H4/A0/B0/C32/D0/S30 (1.2%) 7. H2/A32/B0/C0/D0/S32 (0.9%) 8. H0/A2/B0/C32/D0/S32 (0.9%) 9. H0/A0/B0/C32/D0/S32 (0.7%) 10. H3/A0/B0/C32/D0/S31 (0.6%) | S63: 1. 烈咬陆鲨 2. 河马兽 3. 谜拟丘 4. 西狮海壬 5. 火焰鸡 | T63: 6. 铝钢桥龙 7. 暴鲤龙 8. 苍炎刃鬼 9. 甲贺忍蛙 10. 骨纹巨声鳄
A64: 63 | B64: 索罗亚克（洗翠） | C64: Zoroark-Hisui | D64: 1. 冤冤相报 (64.7%) 2. 冰冻之风 (52.1%) 3. 喷射火焰 (37.4%) 4. 暗影球 (32.3%) 5. 真气弹 (30.6%) 6. 挑衅 (24.2%) 7. 影子偷袭 (22.7%) 8. 临别礼物 (14.8%) 9. 磷火 (14.5%) 10. 巨声 (14.1%) | E64: 1. 气势披带 (67.6%) 2. 讲究围巾 (12.5%) 3. 生命宝珠 (9.6%) 4. 光粉 (1.8%) 5. 达人带 (1.8%) 6. 博识眼镜 (1.3%) 7. 刺耳果 (0.9%) 8. 咒术之符 (0.7%) 9. 广角镜 (0.6%) 10. 文柚果 (0.6%) | F64: 1. 幻觉 (100%) | G64: 1. 胆小 +S -A (60.7%) 2. 内敛 +C -A (20%) 3. 天真 +S -D (11.1%) 4. 急躁 +S -B (3.8%) 5. 慢吞吞 +C -B (1.1%) 6. 马虎 +C -D (1.1%) 7. 爽朗 +S -C (0.6%) 8. 冷静 +C -S (0.4%) 9. 悠闲 +B -S (0.3%) 10. 大胆 +B -A (0.3%) | H64: 1. 烈咬陆鲨 2. 铝钢桥龙 3. 魔幻假面喵 4. 巨金怪 5. 谜拟丘 6. 火焰鸡 7. 暴鲤龙 8. 宝石海星 9. 姆克鹰 10. 雷丘 | I64: 1. H2/A0/B0/C32/D0/S32 (46.2%) 2. H1/A0/B1/C32/D0/S32 (13.1%) 3. H0/A2/B0/C32/D0/S32 (10.1%) 4. H0/A0/B2/C32/D0/S32 (6%) 5. H0/A0/B0/C32/D0/S32 (3.8%) 6. H0/A0/B0/C32/D2/S32 (3.6%) 7. H1/A0/B0/C32/D1/S32 (3.3%) 8. H1/A1/B0/C32/D0/S32 (1.3%) 9. H0/A0/B1/C32/D1/S32 (1.3%) 10. H1/A0/B0/C32/D0/S32 (1.2%) | J64: 本期无显著变化 | K64: 1. 冤冤相报 (64.7%) 2. 冰冻之风 (52.1%) 3. 喷射火焰 (37.4%) 4. 暗影球 (32.3%) 5. 真气弹 (30.6%) | L64: 6. 挑衅 (24.2%) 7. 影子偷袭 (22.7%) 8. 临别礼物 (14.8%) 9. 磷火 (14.5%) 10. 巨声 (14.1%) | M64: 1. 气势披带 (67.6%) 2. 讲究围巾 (12.5%) 3. 生命宝珠 (9.6%) 4. 光粉 (1.8%) 5. 达人带 (1.8%) | N64: 6. 博识眼镜 (1.3%) 7. 刺耳果 (0.9%) 8. 咒术之符 (0.7%) 9. 广角镜 (0.6%) 10. 文柚果 (0.6%) | O64: 1. 胆小 +S -A (60.7%) 2. 内敛 +C -A (20%) 3. 天真 +S -D (11.1%) 4. 急躁 +S -B (3.8%) 5. 慢吞吞 +C -B (1.1%) | P64: 6. 马虎 +C -D (1.1%) 7. 爽朗 +S -C (0.6%) 8. 冷静 +C -S (0.4%) 9. 悠闲 +B -S (0.3%) 10. 大胆 +B -A (0.3%) | Q64: 1. H2/A0/B0/C32/D0/S32 (46.2%) 2. H1/A0/B1/C32/D0/S32 (13.1%) 3. H0/A2/B0/C32/D0/S32 (10.1%) 4. H0/A0/B2/C32/D0/S32 (6%) 5. H0/A0/B0/C32/D0/S32 (3.8%) | R64: 6. H0/A0/B0/C32/D2/S32 (3.6%) 7. H1/A0/B0/C32/D1/S32 (3.3%) 8. H1/A1/B0/C32/D0/S32 (1.3%) 9. H0/A0/B1/C32/D1/S32 (1.3%) 10. H1/A0/B0/C32/D0/S32 (1.2%) | S64: 1. 烈咬陆鲨 2. 铝钢桥龙 3. 魔幻假面喵 4. 巨金怪 5. 谜拟丘 | T64: 6. 火焰鸡 7. 暴鲤龙 8. 宝石海星 9. 姆克鹰 10. 雷丘
... A66: 65 | B66: 黏美龙（洗翠） | C66: Goodra-Hisui | D66: 1. 流星群 (67.7%) 2. 喷射火焰 (56.1%) 3. 重磅冲撞 (47.4%) 4. 龙尾 (44.4%) 5. 加农光炮 (35%) 6. 十万伏特 (26.6%) 7. 闭关 (21.3%) 8. 扑击 (20.2%) 9. 冰冻光束 (13.5%) 10. 酸液炸弹 (11.3%) | E66: 1. 吃剩的东西 (66.6%) 2. 文柚果 (10.2%) 3. 零余果 (4.9%) 4. 腰木果 (3.5%) 5. 达人带 (3.1%) 6. 白色香草 (2.5%) 7. 生命宝珠 (1.6%) 8. 龙之牙 (1.6%) 9. 莲蒲果 (1%) 10. 木子果 (1%) | F66: 1. 黏滑 (56.6%) 2. 硬壳盔甲 (22%) 3. 食草 (21.4%) | G66: 1. 自大 +D -S (43.7%) 2. 内敛 +C -A (19.1%) 3. 温和 +D -A (14%) 4. 大胆 +B -A (12.8%) 5. 冷静 +C -S (3.8%) 6. 淘气 +B -C (1.7%) 7. 慎重 +D -C (1.5%) 8. 悠闲 +B -S (1.5%) 9. 固执 +A -C (0.6%) 10. 勇敢 +A -S (0.5%) | H66: 1. 河马兽 2. 大竺葵 3. 水箭龟 4. 超坏星 5. 赛富豪 6. 烈咬陆鲨 7. 暴鲤龙 8. 骨纹巨声鳄 9. 魔幻假面喵 10. 谜拟丘 | I66: 1. H22/A11/B0/C1/D32/S0 (31.4%) 2. H32/A0/B32/C0/D2/S0 (8.7%) 3. H32/A0/B2/C32/D0/S0 (5.4%) 4. H32/A0/B0/C32/D2/S0 (4.9%) 5. H32/A0/B0/C2/D32/S0 (2.5%) 6. H22/A0/B11/C1/D32/S0 (2.5%) 7. H32/A0/B2/C0/D32/S0 (2.3%) 8. H32/A0/B32/C0/D0/S2 (2.2%) 9. H2/A0/B0/C32/D32/S0 (2%) 10. H22/A12/B0/C0/D32/S0 (1.8%) | J66: 本期无显著变化 | K66: 1. 流星群 (67.7%) 2. 喷射火焰 (56.1%) 3. 重磅冲撞 (47.4%) 4. 龙尾 (44.4%) 5. 加农光炮 (35%) | L66: 6. 十万伏特 (26.6%) 7. 闭关 (21.3%) 8. 扑击 (20.2%) 9. 冰冻光束 (13.5%) 10. 酸液炸弹 (11.3%) | M66: 1. 吃剩的东西 (66.6%) 2. 文柚果 (10.2%) 3. 零余果 (4.9%) 4. 腰木果 (3.5%) 5. 达人带 (3.1%) | N66: 6. 白色香草 (2.5%) 7. 生命宝珠 (1.6%) 8. 龙之牙 (1.6%) 9. 莲蒲果 (1%) 10. 木子果 (1%) | O66: 1. 自大 +D -S (43.7%) 2. 内敛 +C -A (19.1%) 3. 温和 +D -A (14%) 4. 大胆 +B -A (12.8%) 5. 冷静 +C -S (3.8%) | P66: 6. 淘气 +B -C (1.7%) 7. 慎重 +D -C (1.5%) 8. 悠闲 +B -S (1.5%) 9. 固执 +A -C (0.6%) 10. 勇敢 +A -S (0.5%) | Q66: 1. H22/A11/B0/C1/D32/S0 (31.4%) 2. H32/A0/B32/C0/D2/S0 (8.7%) 3. H32/A0/B2/C32/D0/S0 (5.4%) 4. H32/A0/B0/C32/D2/S0 (4.9%) 5. H32/A0/B0/C2/D32/S0 (2.5%) | R66: 6. H22/A0/B11/C1/D32/S0 (2.5%) 7. H32/A0/B2/C0/D32/S0 (2.3%) 8. H32/A0/B32/C0/D0/S2 (2.2%) 9. H2/A0/B0/C32/D32/S0 (2%) 10. H22/A12/B0/C0/D32/S0 (1.8%) | S66: 1. 河马兽 2. 大竺葵 3. 水箭龟 4. 超坏星 5. 赛富豪 | T66: 6. 烈咬陆鲨 7. 暴鲤龙 8. 骨纹巨声鳄 9. 魔幻假面喵 10. 谜拟丘
A67: 66 | B67: 百变怪 | C67: Ditto | D67: 1. 变身 (100%) | E67: 1. 讲究围巾 (78.7%) 2. 先制之爪 (8.9%) 3. 气势披带 (8.1%) 4. 光粉 (1.5%) 5. 生命宝珠 (0.9%) 6. 文柚果 (0.7%) 7. 吃剩的东西 (0.4%) 8. 木子果 (0.2%) 9. 达人带 (0.2%) 10. 气势头带 (0.1%) | F67: 1. 变身者 (99.6%) 2. 柔软 (0.4%) | G67: 1. 悠闲 +B -S (26.5%) 2. 自大 +D -S (8.8%) 3. 胆小 +S -A (8.6%) 4. 天真 +S -D (7.2%) 5. 勇敢 +A -S (6.8%) 6. 认真 (5.8%) 7. 冷静 +C -S (4.3%) 8. 爽朗 +S -C (3.9%) 9. 急躁 +S -B (3.1%) 10. 温顺 +D -B (2.7%) | H67: 1. 烈咬陆鲨 2. 谜拟丘 3. 铝钢桥龙 4. 巨金怪 5. 西狮海壬 6. 喷火龙 7. 快龙 8. 雷丘 9. 月亮伊布 10. 暴鲤龙 | I67: 1. H32/A0/B0/C0/D0/S0 (16.7%) 2. H32/A0/B32/C0/D2/S0 (12%) 3. H32/A2/B32/C0/D0/S0 (9.7%) 4. H32/A0/B2/C0/D32/S0 (6.7%) 5. H32/A0/B2/C0/D0/S32 (5.6%) 6. H32/A0/B0/C0/D0/S32 (5.1%) 7. H32/A2/B0/C0/D0/S32 (3.8%) 8. H32/A0/B0/C2/D0/S32 (2.8%) 9. H32/A0/B0/C0/D2/S32 (2.6%) 10. H32/A32/B2/C0/D0/S0 (2.3%) | J67: 本期无显著变化 | K67: 1. 变身 (100%) | M67: 1. 讲究围巾 (78.7%) 2. 先制之爪 (8.9%) 3. 气势披带 (8.1%) 4. 光粉 (1.5%) 5. 生命宝珠 (0.9%) | N67: 6. 文柚果 (0.7%) 7. 吃剩的东西 (0.4%) 8. 木子果 (0.2%) 9. 达人带 (0.2%) 10. 气势头带 (0.1%) | O67: 1. 悠闲 +B -S (26.5%) 2. 自大 +D -S (8.8%) 3. 胆小 +S -A (8.6%) 4. 天真 +S -D (7.2%) 5. 勇敢 +A -S (6.8%) | P67: 6. 认真 (5.8%) 7. 冷静 +C -S (4.3%) 8. 爽朗 +S -C (3.9%) 9. 急躁 +S -B (3.1%) 10. 温顺 +D -B (2.7%) | Q67: 1. H32/A0/B0/C0/D0/S0 (16.7%) 2. H32/A0/B32/C0/D2/S0 (12%) 3. H32/A2/B32/C0/D0/S0 (9.7%) 4. H32/A0/B2/C0/D32/S0 (6.7%) 5. H32/A0/B2/C0/D0/S32 (5.6%) | R67: 6. H32/A0/B0/C0/D0/S32 (5.1%) 7. H32/A2/B0/C0/D0/S32 (3.8%) 8. H32/A0/B0/C2/D0/S32 (2.8%) 9. H32/A0/B0/C0/D2/S32 (2.6%) 10. H32/A32/B2/C0/D0/S0 (2.3%) | S67: 1. 烈咬陆鲨 2. 谜拟丘 3. 铝钢桥龙 4. 巨金怪 5. 西狮海壬 | T67: 6. 喷火龙 7. 快龙 8. 雷丘 9. 月亮伊布 10. 暴鲤龙
A68: 67 | B68: 滴蛛霸 | C68: Araquanid | D68: 1. 黏黏网 (89.6%) 2. 水流裂破 (80.3%) 3. 镜面反射 (73.9%) 4. 汲取 (30.5%) 5. 猛扑 (20.8%) 6. 冲浪 (16.6%) 7. 蛮干 (14.3%) 8. 冰冻之风 (12.5%) 9. 冰冻光束 (8.5%) 10. 紧束 (8.4%) | E68: 1. 文柚果 (45.5%) 2. 神秘水滴 (15.5%) 3. 气势披带 (11.5%) 4. 吃剩的东西 (8.8%) 5. 烛木果 (4.2%) 6. 生命宝珠 (3.8%) 7. 先制之爪 (2.5%) 8. 木子果 (2.3%) 9. 心灵香草 (1.4%) 10. 零余果 (0.8%) | F68: 1. 水泡 (98.9%) 2. 储水 (1.1%) | G68: 1. 固执 +A -C (38.5%) 2. 内敛 +C -A (13.9%) 3. 淘气 +B -C (13.7%) 4. 慎重 +D -C (10.5%) 5. 爽朗 +S -C (6.3%) 6. 勇敢 +A -S (5.2%) 7. 悠闲 +B -S (3.7%) 8. 大胆 +B -A (2.5%) 9. 冷静 +C -S (1.8%) 10. 自大 +D -S (1.3%) | H68: 1. 烈咬陆鲨 2. 谜拟丘 3. 雷丘 4. 巨金怪 5. 河马兽 6. 巨钳螳螂 7. 魔幻假面喵 8. 暴鲤龙 9. 喷火龙 10. 铝钢桥龙 | I68: 1. H32/A32/B2/C0/D0/S0 (24%) 2. H32/A0/B32/C0/D2/S0 (6.9%) 3. H32/A32/B0/C0/D2/S0 (5.1%) 4. H16/A18/B0/C0/D0/S32 (4.1%) 5. H32/A0/B2/C32/D0/S0 (3.4%) 6. H32/A2/B32/C0/D0/S0 (2.9%) 7. H28/A0/B0/C32/D0/S6 (2.5%) 8. H32/A0/B0/C32/D2/S0 (2.4%) 9. H32/A0/B28/C0/D6/S0 (2%) 10. H28/A32/B0/C0/D0/S6 (1.9%) | J68: 本期无显著变化 | K68: 1. 黏黏网 (89.6%) 2. 水流裂破 (80.3%) 3. 镜面反射 (73.9%) 4. 汲取 (30.5%) 5. 猛扑 (20.8%) | L68: 6. 冲浪 (16.6%) 7. 蛮干 (14.3%) 8. 冰冻之风 (12.5%) 9. 冰冻光束 (8.5%) 10. 紧束 (8.4%) | M68: 1. 文柚果 (45.5%) 2. 神秘水滴 (15.5%) 3. 气势披带 (11.5%) 4. 吃剩的东西 (8.8%) 5. 烛木果 (4.2%) | N68: 6. 生命宝珠 (3.8%) 7. 先制之爪 (2.5%) 8. 木子果 (2.3%) 9. 心灵香草 (1.4%) 10. 零余果 (0.8%) | O68: 1. 固执 +A -C (38.5%) 2. 内敛 +C -A (13.9%) 3. 淘气 +B -C (13.7%) 4. 慎重 +D -C (10.5%) 5. 爽朗 +S -C (6.3%) | P68: 6. 勇敢 +A -S (5.2%) 7. 悠闲 +B -S (3.7%) 8. 大胆 +B -A (2.5%) 9. 冷静 +C -S (1.8%) 10. 自大 +D -S (1.3%) | Q68: 1. H32/A32/B2/C0/D0/S0 (24%) 2. H32/A0/B32/C0/D2/S0 (6.9%) 3. H32/A32/B0/C0/D2/S0 (5.1%) 4. H16/A18/B0/C0/D0/S32 (4.1%) 5. H32/A0/B2/C32/D0/S0 (3.4%) | R68: 6. H32/A2/B32/C0/D0/S0 (2.9%) 7. H28/A0/B0/C32/D0/S6 (2.5%) 8. H32/A0/B0/C32/D2/S0 (2.4%) 9. H32/A0/B28/C0/D6/S0 (2%) 10. H28/A32/B0/C0/D0/S6 (1.9%) | S68: 1. 烈咬陆鲨 2. 谜拟丘 3. 雷丘 4. 巨金怪 5. 河马兽 | T68: 6. 巨钳螳螂 7. 魔幻假面喵 8. 暴鲤龙 9. 喷火龙 10. 铝钢桥龙
A69: 68 | B69: 一家鼠 | C69: Maushold | D69: 1. 鼠数儿 (96.7%) 2. 大扫除 (91.8%) 3. 再来一次 (78.4%) 4. 咬住 (56.8%) 5. 接棒 (20%) 6. 种子机关枪 (15%) 7. 泥巴射击 (5.5%) 8. 电磁波 (5.5%) 9. 挑衅 (4.7%) 10. 咬碎 (3.8%) | E69: 1. 广角镜 (82.1%) 2. 王者之证 (8.7%) 3. 文柚果 (5.2%) 4. 气势披带 (1.4%) 5. 生命宝珠 (0.7%) 6. 焦点镜 (0.4%) 7. 丝绸围巾 (0.4%) 8. 莲蒲果 (0.2%) 9. 吃剩的东西 (0.2%) 10. 讲究围巾 (0.1%) | F69: 1. 技术高手 (94.4%) 2. 颊囊 (5%) 3. 友情防守 (0.5%) | G69: 1. 爽朗 +S -C (80.1%) 2. 固执 +A -C (13.5%) 3. 淘气 +B -C (3.8%) 4. 天真 +S -D (0.6%) 5. 慎重 +D -C (0.6%) 6. 顽皮 +A -D (0.4%) 7. 急躁 +S -B (0.3%) 8. 温和 +D -A (0.2%) 9. 胆小 +S -A (0.2%) 10. 大胆 +B -A (0.2%) | H69: 1. 烈咬陆鲨 2. 谜拟丘 3. 喷火龙 4. 暴鲤龙 5. 巨金怪 6. 雷丘 7. 魔幻假面喵 8. 铝钢桥龙 9. 火焰鸡 10. 甲贺忍蛙 | I69: 1. H2/A32/B0/C0/D0/S32 (59.1%) 2. H0/A32/B2/C0/D0/S32 (9.1%) 3. H0/A32/B0/C0/D2/S32 (5.5%) 4. H10/A19/B0/C0/D10/S27 (4.1%) 5. H0/A32/B0/C0/D0/S32 (1.9%) 6. H32/A0/B32/C0/D2/S0 (1.1%) 7. H32/A0/B32/C0/D0/S2 (1%) 8. H32/A32/B2/C0/D0/S0 (1%) 9. H1/A32/B0/C0/D0/S32 (1%) 10. H32/A0/B2/C0/D0/S32 (0.8%) | J69: 本期无显著变化 | K69: 1. 鼠数儿 (96.7%) 2. 大扫除 (91.8%) 3. 再来一次 (78.4%) 4. 咬住 (56.8%) 5. 接棒 (20%) | L69: 6. 种子机关枪 (15%) 7. 泥巴射击 (5.5%) 8. 电磁波 (5.5%) 9. 挑衅 (4.7%) 10. 咬碎 (3.8%) | M69: 1. 广角镜 (82.1%) 2. 王者之证 (8.7%) 3. 文柚果 (5.2%) 4. 气势披带 (1.4%) 5. 生命宝珠 (0.7%) | N69: 6. 焦点镜 (0.4%) 7. 丝绸围巾 (0.4%) 8. 莲蒲果 (0.2%) 9. 吃剩的东西 (0.2%) 10. 讲究围巾 (0.1%) | O69: 1. 爽朗 +S -C (80.1%) 2. 固执 +A -C (13.5%) 3. 淘气 +B -C (3.8%) 4. 天真 +S -D (0.6%) 5. 慎重 +D -C (0.6%) | P69: 6. 顽皮 +A -D (0.4%) 7. 急躁 +S -B (0.3%) 8. 温和 +D -A (0.2%) 9. 胆小 +S -A (0.2%) 10. 大胆 +B -A (0.2%) | Q69: 1. H2/A32/B0/C0/D0/S32 (59.1%) 2. H0/A32/B2/C0/D0/S32 (9.1%) 3. H0/A32/B0/C0/D2/S32 (5.5%) 4. H10/A19/B0/C0/D10/S27 (4.1%) 5. H0/A32/B0/C0/D0/S32 (1.9%) | R69: 6. H32/A0/B32/C0/D2/S0 (1.1%) 7. H32/A0/B32/C0/D0/S2 (1%) 8. H32/A32/B2/C0/D0/S0 (1%) 9. H1/A32/B0/C0/D0/S32 (1%) 10. H32/A0/B2/C0/D0/S32 (0.8%) | S69: 1. 烈咬陆鲨 2. 谜拟丘 3. 喷火龙 4. 暴鲤龙 5. 巨金怪 | T69: 6. 雷丘 7. 魔幻假面喵 8. 铝钢桥龙 9. 火焰鸡 10. 甲贺忍蛙
