Workbook

Sheet 検索
A1: ポケモン検索（シングル / ダブル 対照） | AB1: ガブリアス
A2: 名前を入力 → | B2: ガブリアス | AB2: ミミッキュ
AB3: ブリジュラス
A4: 項目 | B4: シングル | I4: ダブル | AB4: メタグロス
A5: 順位 | B5: =IFERROR(INDEX('シングル'!A:A,MATCH($B$2,'シングル'!$B:$B,0)),"—") | I5: =IFERROR(INDEX('ダブル'!A:A,MATCH($B$2,'ダブル'!$B:$B,0)),"—") | AB5: カバルドン
A6: 英語名 | B6: =IFERROR(INDEX('シングル'!C:C,MATCH($B$2,'シングル'!$B:$B,0)),"—") | I6: =IFERROR(INDEX('ダブル'!C:C,MATCH($B$2,'ダブル'!$B:$B,0)),"—") | AB6: アシレーヌ
A7: わざ | B7: =IFERROR(INDEX('シングル'!K:K,MATCH($B$2,'シングル'!$B:$B,0)),"—") | E7: =IFERROR(INDEX('シングル'!L:L,MATCH($B$2,'シングル'!$B:$B,0)),"—") | I7: =IFERROR(INDEX('ダブル'!K:K,MATCH($B$2,'ダブル'!$B:$B,0)),"—") | L7: =IFERROR(INDEX('ダブル'!L:L,MATCH($B$2,'ダブル'!$B:$B,0)),"—") | AB7: マスカーニャ
A8: もちもの | B8: =IFERROR(INDEX('シングル'!M:M,MATCH($B$2,'シングル'!$B:$B,0)),"—") | E8: =IFERROR(INDEX('シングル'!N:N,MATCH($B$2,'シングル'!$B:$B,0)),"—") | I8: =IFERROR(INDEX('ダブル'!M:M,MATCH($B$2,'ダブル'!$B:$B,0)),"—") | L8: =IFERROR(INDEX('ダブル'!N:N,MATCH($B$2,'ダブル'!$B:$B,0)),"—") | AB8: ギャラドス
A9: とくせい | B9: =IFERROR(INDEX('シングル'!F:F,MATCH($B$2,'シングル'!$B:$B,0)),"—") | I9: =IFERROR(INDEX('ダブル'!F:F,MATCH($B$2,'ダブル'!$B:$B,0)),"—") | AB9: バシャーモ
A10: せいかく | B10: =IFERROR(INDEX('シングル'!O:O,MATCH($B$2,'シングル'!$B:$B,0)),"—") | E10: =IFERROR(INDEX('シングル'!P:P,MATCH($B$2,'シングル'!$B:$B,0)),"—") | I10: =IFERROR(INDEX('ダブル'!O:O,MATCH($B$2,'ダブル'!$B:$B,0)),"—") | L10: =IFERROR(INDEX('ダブル'!P:P,MATCH($B$2,'ダブル'!$B:$B,0)),"—") | AB10: リザードン
A11: 努力値 | B11: =IFERROR(INDEX('シングル'!Q:Q,MATCH($B$2,'シングル'!$B:$B,0)),"—") | E11: =IFERROR(INDEX('シングル'!R:R,MATCH($B$2,'シングル'!$B:$B,0)),"—") | I11: =IFERROR(INDEX('ダブル'!Q:Q,MATCH($B$2,'ダブル'!$B:$B,0)),"—") | L11: =IFERROR(INDEX('ダブル'!R:R,MATCH($B$2,'ダブル'!$B:$B,0)),"—") | AB11: マフォクシー
A12: パートナー | B12: =IFERROR(INDEX('シングル'!S:S,MATCH($B$2,'シングル'!$B:$B,0)),"—") | E12: =IFERROR(INDEX('シングル'!T:T,MATCH($B$2,'シングル'!$B:$B,0)),"—") | I12: =IFERROR(INDEX('ダブル'!S:S,MATCH($B$2,'ダブル'!$B:$B,0)),"—") | L12: =IFERROR(INDEX('ダブル'!T:T,MATCH($B$2,'ダブル'!$B:$B,0)),"—") | AB12: ゲッコウガ
A13: 今回の変化 | B13: =IFERROR(INDEX('シングル'!J:J,MATCH($B$2,'シングル'!$B:$B,0)),"—") | I13: =IFERROR(INDEX('ダブル'!J:J,MATCH($B$2,'ダブル'!$B:$B,0)),"—") | AB13: サザンドラ
AB14: アーマーガア
AB15: アローラキュウコン
AB16: カイリュー
AB17: ゲンガー
AB18: キラフロル
AB19: イダイトウ(オス)
AB20: ライチュウ
AB21: ヒスイダイケンキ
AB22: ウォッシュロトム
AB23: ハッサム
AB24: ラウドボーン
AB25: スターミー
... AB235: ミルホッグ

Sheet シングル
A1: 順位 | B1: 日本語名 | C1: 英語名 | D1: わざ | E1: もちもの | F1: とくせい | G1: せいかく | H1: パートナー | I1: 努力値 | J1: 今回の変化 | K1: わざ·1 | L1: わざ·2 | M1: もちもの·1 | N1: もちもの·2 | O1: せいかく·1 | P1: せいかく·2 | Q1: 努力値·1 | R1: 努力値·2 | S1: パートナー·1 | T1: パートナー·2
A2: 1 | B2: ガブリアス | C2: Garchomp | D2: 1. じしん (99.6%) 2. ステルスロック (48.4%) 3. スケイルショット (39.6%) 4. げきりん (34.9%) 5. がんせきふうじ (29.4%) 6. つるぎのまい (28.7%) 7. ドラゴンテール (28.6%) 8. まきびし (19.1%) 9. いわなだれ (17.3%) 10. どくづき (13.1%) | E2: 1. きあいのタスキ (36.9%) 2. オボンのみ (24%) 3. こだわりスカーフ (22.6%) 4. ラムのみ (9.6%) 5. いのちのたま (2.9%) 6. ガブリアスナイト (0.7%) 7. たべのこし (0.7%) 8. ハバンのみ (0.6%) 9. ヤチェのみ (0.4%) 10. ロゼルのみ (0.2%) | F2: 1. さめはだ (99.5%) 2. すながくれ (0.5%) | G2: 1. ようき +S -C (48.3%) 2. いじっぱり +A -C (29.3%) 3. わんぱく +B -C (19.4%) 4. しんちょう +D -C (1.6%) 5. むじゃき +S -D (0.4%) 6. ずぶとい +B -A (0.3%) 7. やんちゃ +A -D (0.2%) 8. せっかち +S -B (0.2%) 9. ひかえめ +C -A (0.1%) 10. ゆうかん +A -S (0.1%) | H2: 1. ミミッキュ 2. アシレーヌ 3. メタグロス 4. ブリジュラス 5. マスカーニャ 6. ギャラドス 7. リザードン 8. マフォクシー 9. バシャーモ 10. ゲッコウガ | I2: 1. H2/A32/B0/C0/D0/S32 (47.9%) 2. H0/A32/B2/C0/D0/S32 (9.7%) 3. H0/A32/B1/C0/D1/S32 (4.7%) 4. H32/A0/B32/C0/D0/S2 (4%) 5. H32/A0/B32/C0/D2/S0 (3.3%) 6. H0/A32/B0/C0/D2/S32 (2.7%) 7. H32/A0/B30/C0/D0/S4 (2%) 8. H0/A30/B4/C0/D0/S32 (1.4%) 9. H32/A0/B15/C0/D3/S16 (1.3%) 10. H32/A2/B32/C0/D0/S0 (1.1%) | J2: わざ/ほのおのキバ 13.2→0.0% (-13.2) わざ/どくづき 0.0→13.1% (+13.1) | K2: 1. じしん (99.6%) 2. ステルスロック (48.4%) 3. スケイルショット (39.6%) 4. げきりん (34.9%) 5. がんせきふうじ (29.4%) | L2: 6. つるぎのまい (28.7%) 7. ドラゴンテール (28.6%) 8. まきびし (19.1%) 9. いわなだれ (17.3%) 10. どくづき (13.1%) | M2: 1. きあいのタスキ (36.9%) 2. オボンのみ (24%) 3. こだわりスカーフ (22.6%) 4. ラムのみ (9.6%) 5. いのちのたま (2.9%) | N2: 6. ガブリアスナイト (0.7%) 7. たべのこし (0.7%) 8. ハバンのみ (0.6%) 9. ヤチェのみ (0.4%) 10. ロゼルのみ (0.2%) | O2: 1. ようき +S -C (48.3%) 2. いじっぱり +A -C (29.3%) 3. わんぱく +B -C (19.4%) 4. しんちょう +D -C (1.6%) 5. むじゃき +S -D (0.4%) | P2: 6. ずぶとい +B -A (0.3%) 7. やんちゃ +A -D (0.2%) 8. せっかち +S -B (0.2%) 9. ひかえめ +C -A (0.1%) 10. ゆうかん +A -S (0.1%) | Q2: 1. H2/A32/B0/C0/D0/S32 (47.9%) 2. H0/A32/B2/C0/D0/S32 (9.7%) 3. H0/A32/B1/C0/D1/S32 (4.7%) 4. H32/A0/B32/C0/D0/S2 (4%) 5. H32/A0/B32/C0/D2/S0 (3.3%) | R2: 6. H0/A32/B0/C0/D2/S32 (2.7%) 7. H32/A0/B30/C0/D0/S4 (2%) 8. H0/A30/B4/C0/D0/S32 (1.4%) 9. H32/A0/B15/C0/D3/S16 (1.3%) 10. H32/A2/B32/C0/D0/S0 (1.1%) | S2: 1. ミミッキュ 2. アシレーヌ 3. メタグロス 4. ブリジュラス 5. マスカーニャ | T2: 6. ギャラドス 7. リザードン 8. マフォクシー 9. バシャーモ 10. ゲッコウガ
A3: 2 | B3: ミミッキュ | C3: Mimikyu | D3: 1. じゃれつく (98.4%) 2. かげうち (97.9%) 3. つるぎのまい (85.4%) 4. シャドークロー (69.9%) 5. のろい (13.8%) 6. ウッドハンマー (11.5%) 7. トリックルーム (7.8%) 8. ドレインパンチ (7.7%) 9. おにび (1.5%) 10. みちづれ (1.5%) | E3: 1. いのちのたま (85.2%) 2. ピントレンズ (5.4%) 3. ラムのみ (3.2%) 4. のろいのおふだ (2%) 5. ようせいのハネ (0.8%) 6. たべのこし (0.6%) 7. こうかくレンズ (0.6%) 8. ひかりのこな (0.4%) 9. メンタルハーブ (0.4%) 10. オボンのみ (0.3%) | F3: 1. ばけのかわ (100%) | G3: 1. いじっぱり +A -C (82.8%) 2. ようき +S -C (12.8%) 3. ゆうかん +A -S (2.6%) 4. わんぱく +B -C (0.4%) 5. のんき +B -S (0.2%) 6. しんちょう +D -C (0.2%) 7. さみしがり +A -B (0.2%) 8. やんちゃ +A -D (0.1%) 9. おくびょう +S -A (0.1%) 10. なまいき +D -S (0.1%) | H3: 1. ガブリアス 2. メタグロス 3. ブリジュラス 4. カバルドン 5. アシレーヌ 6. ゲッコウガ 7. リザードン 8. ギャラドス 9. マフォクシー 10. マスカーニャ | I3: 1. H1/A32/B1/C0/D0/S32 (24.6%) 2. H2/A32/B0/C0/D0/S32 (20.6%) 3. H29/A32/B5/C0/D0/S0 (5.8%) 4. H0/A32/B2/C0/D0/S32 (3.5%) 5. H32/A32/B2/C0/D0/S0 (3.4%) 6. H29/A26/B11/C0/D0/S0 (2.4%) 7. H1/A32/B0/C0/D1/S32 (2.1%) 8. H29/A30/B7/C0/D0/S0 (1.7%) 9. H28/A30/B7/C0/D0/S1 (1.7%) 10. H0/A32/B0/C0/D2/S32 (1.5%) | J3: 今回は大きな変化なし | K3: 1. じゃれつく (98.4%) 2. かげうち (97.9%) 3. つるぎのまい (85.4%) 4. シャドークロー (69.9%) 5. のろい (13.8%) | L3: 6. ウッドハンマー (11.5%) 7. トリックルーム (7.8%) 8. ドレインパンチ (7.7%) 9. おにび (1.5%) 10. みちづれ (1.5%) | M3: 1. いのちのたま (85.2%) 2. ピントレンズ (5.4%) 3. ラムのみ (3.2%) 4. のろいのおふだ (2%) 5. ようせいのハネ (0.8%) | N3: 6. たべのこし (0.6%) 7. こうかくレンズ (0.6%) 8. ひかりのこな (0.4%) 9. メンタルハーブ (0.4%) 10. オボンのみ (0.3%) | O3: 1. いじっぱり +A -C (82.8%) 2. ようき +S -C (12.8%) 3. ゆうかん +A -S (2.6%) 4. わんぱく +B -C (0.4%) 5. のんき +B -S (0.2%) | P3: 6. しんちょう +D -C (0.2%) 7. さみしがり +A -B (0.2%) 8. やんちゃ +A -D (0.1%) 9. おくびょう +S -A (0.1%) 10. なまいき +D -S (0.1%) | Q3: 1. H1/A32/B1/C0/D0/S32 (24.6%) 2. H2/A32/B0/C0/D0/S32 (20.6%) 3. H29/A32/B5/C0/D0/S0 (5.8%) 4. H0/A32/B2/C0/D0/S32 (3.5%) 5. H32/A32/B2/C0/D0/S0 (3.4%) | R3: 6. H29/A26/B11/C0/D0/S0 (2.4%) 7. H1/A32/B0/C0/D1/S32 (2.1%) 8. H29/A30/B7/C0/D0/S0 (1.7%) 9. H28/A30/B7/C0/D0/S1 (1.7%) 10. H0/A32/B0/C0/D2/S32 (1.5%) | S3: 1. ガブリアス 2. メタグロス 3. ブリジュラス 4. カバルドン 5. アシレーヌ | T3: 6. ゲッコウガ 7. リザードン 8. ギャラドス 9. マフォクシー 10. マスカーニャ
A4: 3 | B4: ブリジュラス | C4: Archaludon | D4: 1. ラスターカノン (73.8%) 2. りゅうせいぐん (73%) 3. １０まんボルト (62.6%) 4. ステルスロック (38.1%) 5. ミラーコート (21%) 6. はどうだん (18.1%) 7. ほえる (16.8%) 8. あくのはどう (16.4%) 9. エレクトロビーム (15.8%) 10. ドラゴンテール (14.9%) | E4: 1. オボンのみ (31.7%) 2. しろいハーブ (20.5%) 3. たべのこし (20.4%) 4. こだわりスカーフ (12.9%) 5. ピントレンズ (6.1%) 6. シュカのみ (2.1%) 7. りゅうのキバ (0.9%) 8. たつじんのおび (0.9%) 9. カゴのみ (0.8%) 10. ヨプのみ (0.6%) | F4: 1. じきゅうりょく (67.7%) 2. がんじょう (32.3%) 3. すじがねいり (0.1%) | G4: 1. ひかえめ +C -A (43.3%) 2. ずぶとい +B -A (17.5%) 3. おくびょう +S -A (16.6%) 4. おだやか +D -A (14.9%) 5. のんき +B -S (1.7%) 6. わんぱく +B -C (1.7%) 7. しんちょう +D -C (1.5%) 8. なまいき +D -S (1%) 9. うっかりや +C -D (0.6%) 10. れいせい +C -S (0.6%) | H4: 1. ミミッキュ 2. ガブリアス 3. メタグロス 4. カバルドン 5. アシレーヌ 6. ギャラドス 7. マスカーニャ 8. バシャーモ 9. マフォクシー 10. ゲッコウガ | I4: 1. H2/A0/B0/C32/D0/S32 (23.3%) 2. H32/A0/B2/C0/D32/S0 (9.2%) 3. H32/A0/B0/C0/D32/S2 (5.1%) 4. H0/A0/B1/C32/D1/S32 (4.3%) 5. H0/A0/B2/C32/D0/S32 (2.7%) 6. H32/A0/B0/C32/D0/S2 (2.4%) 7. H32/A0/B2/C32/D0/S0 (2.4%) 8. H32/A0/B0/C32/D2/S0 (2.2%) 9. H32/A0/B32/C0/D2/S0 (1.7%) 10. H0/A0/B0/C32/D2/S32 (1.6%) | J4: 今回は大きな変化なし | K4: 1. ラスターカノン (73.8%) 2. りゅうせいぐん (73%) 3. １０まんボルト (62.6%) 4. ステルスロック (38.1%) 5. ミラーコート (21%) | L4: 6. はどうだん (18.1%) 7. ほえる (16.8%) 8. あくのはどう (16.4%) 9. エレクトロビーム (15.8%) 10. ドラゴンテール (14.9%) | M4: 1. オボンのみ (31.7%) 2. しろいハーブ (20.5%) 3. たべのこし (20.4%) 4. こだわりスカーフ (12.9%) 5. ピントレンズ (6.1%) | N4: 6. シュカのみ (2.1%) 7. りゅうのキバ (0.9%) 8. たつじんのおび (0.9%) 9. カゴのみ (0.8%) 10. ヨプのみ (0.6%) | O4: 1. ひかえめ +C -A (43.3%) 2. ずぶとい +B -A (17.5%) 3. おくびょう +S -A (16.6%) 4. おだやか +D -A (14.9%) 5. のんき +B -S (1.7%) | P4: 6. わんぱく +B -C (1.7%) 7. しんちょう +D -C (1.5%) 8. なまいき +D -S (1%) 9. うっかりや +C -D (0.6%) 10. れいせい +C -S (0.6%) | Q4: 1. H2/A0/B0/C32/D0/S32 (23.3%) 2. H32/A0/B2/C0/D32/S0 (9.2%) 3. H32/A0/B0/C0/D32/S2 (5.1%) 4. H0/A0/B1/C32/D1/S32 (4.3%) 5. H0/A0/B2/C32/D0/S32 (2.7%) | R4: 6. H32/A0/B0/C32/D0/S2 (2.4%) 7. H32/A0/B2/C32/D0/S0 (2.4%) 8. H32/A0/B0/C32/D2/S0 (2.2%) 9. H32/A0/B32/C0/D2/S0 (1.7%) 10. H0/A0/B0/C32/D2/S32 (1.6%) | S4: 1. ミミッキュ 2. ガブリアス 3. メタグロス 4. カバルドン 5. アシレーヌ | T4: 6. ギャラドス 7. マスカーニャ 8. バシャーモ 9. マフォクシー 10. ゲッコウガ
A5: 4 | B5: メタグロス | C5: Metagross | D5: 1. サイコファング (94.9%) 2. バレットパンチ (91.4%) 3. じしん (52.6%) 4. れいとうパンチ (46.8%) 5. かみなりパンチ (33.6%) 6. ボディプレス (17.8%) 7. てっぺき (17.3%) 8. アームハンマー (13%) 9. アイアンヘッド (8.1%) 10. コメットパンチ (6.3%) | E5: 1. メタグロスナイト (99%) 2. いのちのたま (0.1%) 3. オボンのみ (0.1%) 4. たべのこし (0.1%) 5. こだわりスカーフ (0.1%) 6. シュカのみ (0.1%) 7. ラムのみ (0.1%) 8. ひかりのねんど (0.1%) 9. たつじんのおび (0.1%) 10. リザードナイトＹ (0%) | F5: 1. クリアボディ (99.5%) 2. ライトメタル (0.5%) | G5: 1. いじっぱり +A -C (47.3%) 2. ようき +S -C (38.5%) 3. わんぱく +B -C (12.5%) 4. しんちょう +D -C (0.4%) 5. むじゃき +S -D (0.3%) 6. ゆうかん +A -S (0.2%) 7. さみしがり +A -B (0.2%) 8. やんちゃ +A -D (0.1%) 9. なまいき +D -S (0.1%) 10. ずぶとい +B -A (0.1%) | H5: 1. アシレーヌ 2. ミミッキュ 3. ガブリアス 4. サザンドラ 5. カバルドン 6. ブリジュラス 7. マスカーニャ 8. リザードン 9. カイリュー 10. ゲッコウガ | I5: 1. H2/A32/B0/C0/D0/S32 (25.1%) 2. H20/A25/B1/C0/D1/S19 (4.9%) 3. H10/A25/B0/C8/D0/S23 (4%) 4. H26/A32/B0/C0/D0/S8 (3.8%) 5. H12/A22/B0/C0/D0/S32 (3.2%) 6. H16/A25/B0/C0/D0/S25 (2.8%) 7. H32/A0/B32/C0/D0/S2 (2.3%) 8. H22/A32/B3/C0/D0/S9 (2%) 9. H32/A32/B0/C0/D0/S2 (1.8%) 10. H9/A32/B0/C0/D0/S25 (1.7%) | J5: 今回は大きな変化なし | K5: 1. サイコファング (94.9%) 2. バレットパンチ (91.4%) 3. じしん (52.6%) 4. れいとうパンチ (46.8%) 5. かみなりパンチ (33.6%) | L5: 6. ボディプレス (17.8%) 7. てっぺき (17.3%) 8. アームハンマー (13%) 9. アイアンヘッド (8.1%) 10. コメットパンチ (6.3%) | M5: 1. メタグロスナイト (99%) 2. いのちのたま (0.1%) 3. オボンのみ (0.1%) 4. たべのこし (0.1%) 5. こだわりスカーフ (0.1%) | N5: 6. シュカのみ (0.1%) 7. ラムのみ (0.1%) 8. ひかりのねんど (0.1%) 9. たつじんのおび (0.1%) 10. リザードナイトＹ (0%) | O5: 1. いじっぱり +A -C (47.3%) 2. ようき +S -C (38.5%) 3. わんぱく +B -C (12.5%) 4. しんちょう +D -C (0.4%) 5. むじゃき +S -D (0.3%) | P5: 6. ゆうかん +A -S (0.2%) 7. さみしがり +A -B (0.2%) 8. やんちゃ +A -D (0.1%) 9. なまいき +D -S (0.1%) 10. ずぶとい +B -A (0.1%) | Q5: 1. H2/A32/B0/C0/D0/S32 (25.1%) 2. H20/A25/B1/C0/D1/S19 (4.9%) 3. H10/A25/B0/C8/D0/S23 (4%) 4. H26/A32/B0/C0/D0/S8 (3.8%) 5. H12/A22/B0/C0/D0/S32 (3.2%) | R5: 6. H16/A25/B0/C0/D0/S25 (2.8%) 7. H32/A0/B32/C0/D0/S2 (2.3%) 8. H22/A32/B3/C0/D0/S9 (2%) 9. H32/A32/B0/C0/D0/S2 (1.8%) 10. H9/A32/B0/C0/D0/S25 (1.7%) | S5: 1. アシレーヌ 2. ミミッキュ 3. ガブリアス 4. サザンドラ 5. カバルドン | T5: 6. ブリジュラス 7. マスカーニャ 8. リザードン 9. カイリュー 10. ゲッコウガ
A6: 5 | B6: カバルドン | C6: Hippowdon | D6: 1. じしん (98.6%) 2. あくび (95%) 3. ステルスロック (74.8%) 4. なまける (66.3%) 5. ふきとばし (40.1%) 6. まもる (17.4%) 7. ほえる (3.3%) 8. がんせきふうじ (1%) 9. こおりのキバ (0.7%) 10. じわれ (0.6%) | E6: 1. オボンのみ (57.4%) 2. たべのこし (40.6%) 3. さらさらいわ (0.5%) 4. メンタルハーブ (0.3%) 5. ラムのみ (0.2%) 6. リンドのみ (0.2%) 7. いのちのたま (0.1%) 8. ひかりのこな (0.1%) 9. せんせいのツメ (0.1%) 10. きあいのタスキ (0.1%) | F6: 1. すなおこし (99.9%) 2. すなのちから (0.1%) | G6: 1. わんぱく +B -C (74.5%) 2. しんちょう +D -C (13.5%) 3. のんき +B -S (8.3%) 4. なまいき +D -S (1.4%) 5. ずぶとい +B -A (1%) 6. いじっぱり +A -C (0.7%) 7. おだやか +D -A (0.2%) 8. ゆうかん +A -S (0.2%) 9. さみしがり +A -B (0.1%) 10. やんちゃ +A -D (0%) | H6: 1. ミミッキュ 2. メタグロス 3. アシレーヌ 4. マスカーニャ 5. ブリジュラス 6. ギャラドス 7. サザンドラ 8. カイリュー 9. ガブリアス 10. リザードン | I6: 1. H32/A0/B32/C0/D2/S0 (23.9%) 2. H32/A0/B2/C0/D32/S0 (17.4%) 3. H32/A0/B22/C0/D12/S0 (8.8%) 4. H32/A0/B22/C0/D10/S2 (5.2%) 5. H32/A0/B12/C0/D22/S0 (4.2%) 6. H32/A0/B15/C0/D19/S0 (4.1%) 7. H32/A0/B18/C0/D16/S0 (2.8%) 8. H32/A0/B20/C0/D14/S0 (2.3%) 9. H32/A0/B32/C0/D0/S2 (2%) 10. H32/A0/B6/C0/D28/S0 (1.7%) | J6: 今回は大きな変化なし | K6: 1. じしん (98.6%) 2. あくび (95%) 3. ステルスロック (74.8%) 4. なまける (66.3%) 5. ふきとばし (40.1%) | L6: 6. まもる (17.4%) 7. ほえる (3.3%) 8. がんせきふうじ (1%) 9. こおりのキバ (0.7%) 10. じわれ (0.6%) | M6: 1. オボンのみ (57.4%) 2. たべのこし (40.6%) 3. さらさらいわ (0.5%) 4. メンタルハーブ (0.3%) 5. ラムのみ (0.2%) | N6: 6. リンドのみ (0.2%) 7. いのちのたま (0.1%) 8. ひかりのこな (0.1%) 9. せんせいのツメ (0.1%) 10. きあいのタスキ (0.1%) | O6: 1. わんぱく +B -C (74.5%) 2. しんちょう +D -C (13.5%) 3. のんき +B -S (8.3%) 4. なまいき +D -S (1.4%) 5. ずぶとい +B -A (1%) | P6: 6. いじっぱり +A -C (0.7%) 7. おだやか +D -A (0.2%) 8. ゆうかん +A -S (0.2%) 9. さみしがり +A -B (0.1%) 10. やんちゃ +A -D (0%) | Q6: 1. H32/A0/B32/C0/D2/S0 (23.9%) 2. H32/A0/B2/C0/D32/S0 (17.4%) 3. H32/A0/B22/C0/D12/S0 (8.8%) 4. H32/A0/B22/C0/D10/S2 (5.2%) 5. H32/A0/B12/C0/D22/S0 (4.2%) | R6: 6. H32/A0/B15/C0/D19/S0 (4.1%) 7. H32/A0/B18/C0/D16/S0 (2.8%) 8. H32/A0/B20/C0/D14/S0 (2.3%) 9. H32/A0/B32/C0/D0/S2 (2%) 10. H32/A0/B6/C0/D28/S0 (1.7%) | S6: 1. ミミッキュ 2. メタグロス 3. アシレーヌ 4. マスカーニャ 5. ブリジュラス | T6: 6. ギャラドス 7. サザンドラ 8. カイリュー 9. ガブリアス 10. リザードン
A7: 6 | B7: アシレーヌ | C7: Primarina | D7: 1. ムーンフォース (98.4%) 2. うたかたのアリア (87.6%) 3. アクアジェット (75%) 4. アンコール (43.1%) 5. めいそう (23.2%) 6. クイックターン (21.7%) 7. なみのり (10.1%) 8. れいとうビーム (6.6%) 9. ミストフィールド (5.7%) 10. エナジーボール (5.4%) | E7: 1. オボンのみ (50.2%) 2. たべのこし (22.7%) 3. しんぴのしずく (9.9%) 4. きあいのタスキ (4.7%) 5. カゴのみ (3.3%) 6. ラムのみ (2.8%) 7. ソクノのみ (1.7%) 8. ようせいのハネ (1.5%) 9. いのちのたま (1%) 10. せんせいのツメ (0.4%) | F7: 1. げきりゅう (96.3%) 2. うるおいボイス (3.7%) | G7: 1. ひかえめ +C -A (63.4%) 2. れいせい +C -S (16%) 3. ずぶとい +B -A (12.3%) 4. のんき +B -S (3.7%) 5. おだやか +D -A (2.6%) 6. おくびょう +S -A (0.8%) 7. なまいき +D -S (0.4%) 8. おっとり +C -B (0.4%) 9. うっかりや +C -D (0.2%) 10. むじゃき +S -D (0%) | H7: 1. ガブリアス 2. メタグロス 3. ミミッキュ 4. カバルドン 5. サザンドラ 6. マスカーニャ 7. ブリジュラス 8. リザードン 9. マフォクシー 10. カイリュー | I7: 1. H32/A0/B0/C32/D0/S2 (7.5%) 2. H32/A0/B20/C14/D0/S0 (6.4%) 3. H32/A0/B29/C4/D1/S0 (4.4%) 4. H32/A0/B2/C32/D0/S0 (4.3%) 5. H32/A0/B32/C2/D0/S0 (3.7%) 6. H2/A0/B0/C32/D0/S32 (3.4%) 7. H32/A0/B0/C32/D2/S0 (3.1%) 8. H32/A0/B32/C0/D2/S0 (2.2%) 9. H32/A0/B30/C4/D0/S0 (2.1%) 10. H32/A0/B0/C24/D0/S10 (2%) | J7: 今回は大きな変化なし | K7: 1. ムーンフォース (98.4%) 2. うたかたのアリア (87.6%) 3. アクアジェット (75%) 4. アンコール (43.1%) 5. めいそう (23.2%) | L7: 6. クイックターン (21.7%) 7. なみのり (10.1%) 8. れいとうビーム (6.6%) 9. ミストフィールド (5.7%) 10. エナジーボール (5.4%) | M7: 1. オボンのみ (50.2%) 2. たべのこし (22.7%) 3. しんぴのしずく (9.9%) 4. きあいのタスキ (4.7%) 5. カゴのみ (3.3%) | N7: 6. ラムのみ (2.8%) 7. ソクノのみ (1.7%) 8. ようせいのハネ (1.5%) 9. いのちのたま (1%) 10. せんせいのツメ (0.4%) | O7: 1. ひかえめ +C -A (63.4%) 2. れいせい +C -S (16%) 3. ずぶとい +B -A (12.3%) 4. のんき +B -S (3.7%) 5. おだやか +D -A (2.6%) | P7: 6. おくびょう +S -A (0.8%) 7. なまいき +D -S (0.4%) 8. おっとり +C -B (0.4%) 9. うっかりや +C -D (0.2%) 10. むじゃき +S -D (0%) | Q7: 1. H32/A0/B0/C32/D0/S2 (7.5%) 2. H32/A0/B20/C14/D0/S0 (6.4%) 3. H32/A0/B29/C4/D1/S0 (4.4%) 4. H32/A0/B2/C32/D0/S0 (4.3%) 5. H32/A0/B32/C2/D0/S0 (3.7%) | R7: 6. H2/A0/B0/C32/D0/S32 (3.4%) 7. H32/A0/B0/C32/D2/S0 (3.1%) 8. H32/A0/B32/C0/D2/S0 (2.2%) 9. H32/A0/B30/C4/D0/S0 (2.1%) 10. H32/A0/B0/C24/D0/S10 (2%) | S7: 1. ガブリアス 2. メタグロス 3. ミミッキュ 4. カバルドン 5. サザンドラ | T7: 6. マスカーニャ 7. ブリジュラス 8. リザードン 9. マフォクシー 10. カイリュー
A8: 7 | B8: マスカーニャ | C8: Meowscarada | D8: 1. トリックフラワー (96.9%) 2. トリプルアクセル (84.3%) 3. とんぼがえり (72.2%) 4. はたきおとす (62.1%) 5. ふいうち (17.2%) 6. かみなりパンチ (16.9%) 7. イカサマ (7.2%) 8. じゃれつく (6.6%) 9. パワージェム (5.9%) 10. どくびし (5.7%) | E8: 1. こだわりスカーフ (74.7%) 2. きあいのタスキ (17.3%) 3. いのちのたま (4.7%) 4. たつじんのおび (1.3%) 5. でんきだま (0.3%) 6. こうかくレンズ (0.2%) 7. ラムのみ (0.2%) 8. ちからのハチマキ (0.2%) 9. たべのこし (0.2%) 10. せんせいのツメ (0.1%) | F8: 1. へんげんじざい (93.1%) 2. しんりょく (6.9%) | G8: 1. ようき +S -C (57.9%) 2. いじっぱり +A -C (34%) 3. むじゃき +S -D (4.2%) 4. うっかりや +C -D (1.3%) 5. やんちゃ +A -D (0.8%) 6. せっかち +S -B (0.6%) 7. おくびょう +S -A (0.4%) 8. ひかえめ +C -A (0.4%) 9. さみしがり +A -B (0.3%) 10. おっとり +C -B (0.1%) | H8: 1. ガブリアス 2. カバルドン 3. アシレーヌ 4. ミミッキュ 5. ブリジュラス 6. メタグロス 7. マフォクシー 8. リザードン 9. バシャーモ 10. ギャラドス | I8: 1. H2/A32/B0/C0/D0/S32 (59.8%) 2. H0/A32/B2/C0/D0/S32 (9.6%) 3. H0/A32/B1/C0/D1/S32 (3.9%) 4. H0/A32/B0/C0/D2/S32 (3.8%) 5. H4/A30/B20/C0/D0/S12 (1.8%) 6. H0/A32/B0/C0/D0/S32 (1.4%) 7. H0/A30/B0/C11/D0/S25 (1.2%) 8. H4/A25/B23/C0/D0/S14 (1%) 9. H8/A30/B14/C0/D0/S14 (0.8%) 10. H0/A2/B0/C32/D0/S32 (0.8%) | J8: 今回は大きな変化なし | K8: 1. トリックフラワー (96.9%) 2. トリプルアクセル (84.3%) 3. とんぼがえり (72.2%) 4. はたきおとす (62.1%) 5. ふいうち (17.2%) | L8: 6. かみなりパンチ (16.9%) 7. イカサマ (7.2%) 8. じゃれつく (6.6%) 9. パワージェム (5.9%) 10. どくびし (5.7%) | M8: 1. こだわりスカーフ (74.7%) 2. きあいのタスキ (17.3%) 3. いのちのたま (4.7%) 4. たつじんのおび (1.3%) 5. でんきだま (0.3%) | N8: 6. こうかくレンズ (0.2%) 7. ラムのみ (0.2%) 8. ちからのハチマキ (0.2%) 9. たべのこし (0.2%) 10. せんせいのツメ (0.1%) | O8: 1. ようき +S -C (57.9%) 2. いじっぱり +A -C (34%) 3. むじゃき +S -D (4.2%) 4. うっかりや +C -D (1.3%) 5. やんちゃ +A -D (0.8%) | P8: 6. せっかち +S -B (0.6%) 7. おくびょう +S -A (0.4%) 8. ひかえめ +C -A (0.4%) 9. さみしがり +A -B (0.3%) 10. おっとり +C -B (0.1%) | Q8: 1. H2/A32/B0/C0/D0/S32 (59.8%) 2. H0/A32/B2/C0/D0/S32 (9.6%) 3. H0/A32/B1/C0/D1/S32 (3.9%) 4. H0/A32/B0/C0/D2/S32 (3.8%) 5. H4/A30/B20/C0/D0/S12 (1.8%) | R8: 6. H0/A32/B0/C0/D0/S32 (1.4%) 7. H0/A30/B0/C11/D0/S25 (1.2%) 8. H4/A25/B23/C0/D0/S14 (1%) 9. H8/A30/B14/C0/D0/S14 (0.8%) 10. H0/A2/B0/C32/D0/S32 (0.8%) | S8: 1. ガブリアス 2. カバルドン 3. アシレーヌ 4. ミミッキュ 5. ブリジュラス | T8: 6. メタグロス 7. マフォクシー 8. リザードン 9. バシャーモ 10. ギャラドス
A9: 8 | B9: ギャラドス | C9: Gyarados | D9: 1. たきのぼり (84.9%) 2. りゅうのまい (84.1%) 3. じしん (81.1%) 4. こおりのキバ (52%) 5. パワーウィップ (38.5%) 6. ちょうはつ (23.9%) 7. かみくだく (13.5%) 8. ゆきなだれ (11%) 9. やけっぱち (2.3%) 10. みがわり (2%) | E9: 1. ギャラドスナイト (80.1%) 2. たべのこし (10.8%) 3. オボンのみ (3.9%) 4. ラムのみ (2.2%) 5. たつじんのおび (0.9%) 6. ソクノのみ (0.5%) 7. いのちのたま (0.4%) 8. カゴのみ (0.3%) 9. きあいのタスキ (0.2%) 10. こだわりスカーフ (0.2%) | F9: 1. いかく (99.3%) 2. じしんかじょう (0.7%) | G9: 1. ようき +S -C (53.4%) 2. いじっぱり +A -C (40.1%) 3. わんぱく +B -C (5.5%) 4. しんちょう +D -C (0.6%) 5. やんちゃ +A -D (0.1%) 6. むじゃき +S -D (0%) 7. おくびょう +S -A (0%) 8. ゆうかん +A -S (0%) 9. のんき +B -S (0%) 10. なまいき +D -S (0%) | H9: 1. ガブリアス 2. ミミッキュ 3. ブリジュラス 4. カバルドン 5. バシャーモ 6. キュウコン（アローラのすがた） 7. マフォクシー 8. マスカーニャ 9. メタグロス 10. キラフロル | I9: 1. H1/A32/B1/C0/D0/S32 (25.7%) 2. H2/A32/B0/C0/D0/S32 (18.9%) 3. H1/A32/B0/C0/D1/S32 (2.9%) 4. H7/A32/B1/C0/D0/S26 (2%) 5. H0/A32/B2/C0/D0/S32 (1.9%) 6. H13/A32/B0/C0/D0/S21 (1.9%) 7. H31/A11/B21/C0/D1/S2 (1.7%) 8. H5/A26/B5/C0/D0/S30 (1.6%) 9. H3/A32/B1/C0/D0/S30 (1.4%) 10. H3/A32/B0/C0/D0/S31 (1.3%) | J9: 今回は大きな変化なし | K9: 1. たきのぼり (84.9%) 2. りゅうのまい (84.1%) 3. じしん (81.1%) 4. こおりのキバ (52%) 5. パワーウィップ (38.5%) | L9: 6. ちょうはつ (23.9%) 7. かみくだく (13.5%) 8. ゆきなだれ (11%) 9. やけっぱち (2.3%) 10. みがわり (2%) | M9: 1. ギャラドスナイト (80.1%) 2. たべのこし (10.8%) 3. オボンのみ (3.9%) 4. ラムのみ (2.2%) 5. たつじんのおび (0.9%) | N9: 6. ソクノのみ (0.5%) 7. いのちのたま (0.4%) 8. カゴのみ (0.3%) 9. きあいのタスキ (0.2%) 10. こだわりスカーフ (0.2%) | O9: 1. ようき +S -C (53.4%) 2. いじっぱり +A -C (40.1%) 3. わんぱく +B -C (5.5%) 4. しんちょう +D -C (0.6%) 5. やんちゃ +A -D (0.1%) | P9: 6. むじゃき +S -D (0%) 7. おくびょう +S -A (0%) 8. ゆうかん +A -S (0%) 9. のんき +B -S (0%) 10. なまいき +D -S (0%) | Q9: 1. H1/A32/B1/C0/D0/S32 (25.7%) 2. H2/A32/B0/C0/D0/S32 (18.9%) 3. H1/A32/B0/C0/D1/S32 (2.9%) 4. H7/A32/B1/C0/D0/S26 (2%) 5. H0/A32/B2/C0/D0/S32 (1.9%) | R9: 6. H13/A32/B0/C0/D0/S21 (1.9%) 7. H31/A11/B21/C0/D1/S2 (1.7%) 8. H5/A26/B5/C0/D0/S30 (1.6%) 9. H3/A32/B1/C0/D0/S30 (1.4%) 10. H3/A32/B0/C0/D0/S31 (1.3%) | S9: 1. ガブリアス 2. ミミッキュ 3. ブリジュラス 4. カバルドン 5. バシャーモ | T9: 6. キュウコン（アローラのすがた） 7. マフォクシー 8. マスカーニャ 9. メタグロス 10. キラフロル
A10: 9 | B10: バシャーモ | C10: Blaziken | D10: 1. フレアドライブ (85%) 2. インファイト (66.2%) 3. かみなりパンチ (48.1%) 4. つるぎのまい (47.3%) 5. まもる (40.5%) 6. みきり (31.8%) 7. とびひざげり (23.2%) 8. バトンタッチ (9.6%) 9. じしん (6.6%) 10. オーバーヒート (6%) | E10: 1. バシャーモナイト (73.8%) 2. きあいのタスキ (14.9%) 3. いのちのたま (7.4%) 4. オボンのみ (1.5%) 5. たべのこし (0.5%) 6. シュカのみ (0.3%) 7. ピントレンズ (0.2%) 8. しろいハーブ (0.2%) 9. メンタルハーブ (0.2%) 10. ラムのみ (0.1%) | F10: 1. かそく (98.5%) 2. もうか (1.5%) | G10: 1. いじっぱり +A -C (72.5%) 2. ようき +S -C (15.9%) 3. やんちゃ +A -D (4.7%) 4. わんぱく +B -C (1.6%) 5. うっかりや +C -D (1.4%) 6. むじゃき +S -D (1.2%) 7. おくびょう +S -A (0.6%) 8. ひかえめ +C -A (0.6%) 9. さみしがり +A -B (0.4%) 10. しんちょう +D -C (0.4%) | H10: 1. ガブリアス 2. ミミッキュ 3. ブリジュラス 4. ギャラドス 5. マスカーニャ 6. カバルドン 7. アシレーヌ 8. キュウコン（アローラのすがた） 9. メタグロス 10. ゲッコウガ | I10: 1. H2/A32/B0/C0/D0/S32 (46.8%) 2. H16/A32/B0/C0/D0/S18 (6.5%) 3. H10/A32/B0/C0/D0/S24 (4.2%) 4. H0/A32/B2/C0/D0/S32 (3.5%) 5. H0/A32/B0/C5/D0/S29 (2.3%) 6. H0/A32/B1/C0/D1/S32 (2.2%) 7. H0/A32/B0/C0/D0/S32 (2%) 8. H0/A32/B0/C0/D2/S32 (1.8%) 9. H20/A25/B3/C0/D0/S18 (1.4%) 10. H0/A2/B0/C32/D0/S32 (1.3%) | J10: 今回は大きな変化なし | K10: 1. フレアドライブ (85%) 2. インファイト (66.2%) 3. かみなりパンチ (48.1%) 4. つるぎのまい (47.3%) 5. まもる (40.5%) | L10: 6. みきり (31.8%) 7. とびひざげり (23.2%) 8. バトンタッチ (9.6%) 9. じしん (6.6%) 10. オーバーヒート (6%) | M10: 1. バシャーモナイト (73.8%) 2. きあいのタスキ (14.9%) 3. いのちのたま (7.4%) 4. オボンのみ (1.5%) 5. たべのこし (0.5%) | N10: 6. シュカのみ (0.3%) 7. ピントレンズ (0.2%) 8. しろいハーブ (0.2%) 9. メンタルハーブ (0.2%) 10. ラムのみ (0.1%) | O10: 1. いじっぱり +A -C (72.5%) 2. ようき +S -C (15.9%) 3. やんちゃ +A -D (4.7%) 4. わんぱく +B -C (1.6%) 5. うっかりや +C -D (1.4%) | P10: 6. むじゃき +S -D (1.2%) 7. おくびょう +S -A (0.6%) 8. ひかえめ +C -A (0.6%) 9. さみしがり +A -B (0.4%) 10. しんちょう +D -C (0.4%) | Q10: 1. H2/A32/B0/C0/D0/S32 (46.8%) 2. H16/A32/B0/C0/D0/S18 (6.5%) 3. H10/A32/B0/C0/D0/S24 (4.2%) 4. H0/A32/B2/C0/D0/S32 (3.5%) 5. H0/A32/B0/C5/D0/S29 (2.3%) | R10: 6. H0/A32/B1/C0/D1/S32 (2.2%) 7. H0/A32/B0/C0/D0/S32 (2%) 8. H0/A32/B0/C0/D2/S32 (1.8%) 9. H20/A25/B3/C0/D0/S18 (1.4%) 10. H0/A2/B0/C32/D0/S32 (1.3%) | S10: 1. ガブリアス 2. ミミッキュ 3. ブリジュラス 4. ギャラドス 5. マスカーニャ | T10: 6. カバルドン 7. アシレーヌ 8. キュウコン（アローラのすがた） 9. メタグロス 10. ゲッコウガ
A11: 10 | B11: リザードン | C11: Charizard | D11: 1. ソーラービーム (62.6%) 2. かえんほうしゃ (41.6%) 3. エアスラッシュ (41.1%) 4. フレアドライブ (34.2%) 5. ニトロチャージ (29.1%) 6. オーバーヒート (24.7%) 7. りゅうのまい (21.6%) 8. ウェザーボール (19.8%) 9. はねやすめ (19.5%) 10. ドラゴンクロー (17.9%) | E11: 1. リザードナイトＹ (64.2%) 2. リザードナイトＸ (34.8%) 3. ライチュウナイトＹ (0.1%) 4. こだわりスカーフ (0.1%) 5. ラムのみ (0.1%) 6. たつじんのおび (0%) 7. せんせいのツメ (0%) 8. いのちのたま (0%) 9. しろいハーブ (0%) 10. たべのこし (0%) | F11: 1. もうか (87.7%) 2. サンパワー (12.3%) | G11: 1. ひかえめ +C -A (38.7%) 2. おくびょう +S -A (24.9%) 3. いじっぱり +A -C (21.5%) 4. ようき +S -C (13.4%) 5. ずぶとい +B -A (0.4%) 6. わんぱく +B -C (0.2%) 7. すなお (0.2%) 8. おだやか +D -A (0.1%) 9. むじゃき +S -D (0.1%) 10. おっとり +C -B (0.1%) | H11: 1. ガブリアス 2. ミミッキュ 3. アシレーヌ 4. メタグロス 5. ブリジュラス 6. カバルドン 7. マスカーニャ 8. サザンドラ 9. ゲッコウガ 10. アーマーガア | I11: 1. H2/A0/B0/C32/D0/S32 (27.9%) 2. H2/A32/B0/C0/D0/S32 (15.5%) 3. H4/A30/B0/C0/D0/S32 (6.2%) 4. H12/A0/B20/C16/D0/S18 (3.6%) 5. H0/A0/B2/C32/D0/S32 (3.1%) 6. H6/A0/B9/C29/D0/S22 (2.5%) 7. H14/A0/B12/C21/D0/S19 (2.2%) 8. H0/A32/B2/C0/D0/S32 (1.6%) 9. H0/A0/B0/C32/D2/S32 (1.4%) 10. H12/A0/B20/C14/D0/S20 (1.3%) | J11: わざ/げきりん 22.7→0.0% (-22.7) わざ/ドラゴンクロー 0.0→17.9% (+17.9) | K11: 1. ソーラービーム (62.6%) 2. かえんほうしゃ (41.6%) 3. エアスラッシュ (41.1%) 4. フレアドライブ (34.2%) 5. ニトロチャージ (29.1%) | L11: 6. オーバーヒート (24.7%) 7. りゅうのまい (21.6%) 8. ウェザーボール (19.8%) 9. はねやすめ (19.5%) 10. ドラゴンクロー (17.9%) | M11: 1. リザードナイトＹ (64.2%) 2. リザードナイトＸ (34.8%) 3. ライチュウナイトＹ (0.1%) 4. こだわりスカーフ (0.1%) 5. ラムのみ (0.1%) | N11: 6. たつじんのおび (0%) 7. せんせいのツメ (0%) 8. いのちのたま (0%) 9. しろいハーブ (0%) 10. たべのこし (0%) | O11: 1. ひかえめ +C -A (38.7%) 2. おくびょう +S -A (24.9%) 3. いじっぱり +A -C (21.5%) 4. ようき +S -C (13.4%) 5. ずぶとい +B -A (0.4%) | P11: 6. わんぱく +B -C (0.2%) 7. すなお (0.2%) 8. おだやか +D -A (0.1%) 9. むじゃき +S -D (0.1%) 10. おっとり +C -B (0.1%) | Q11: 1. H2/A0/B0/C32/D0/S32 (27.9%) 2. H2/A32/B0/C0/D0/S32 (15.5%) 3. H4/A30/B0/C0/D0/S32 (6.2%) 4. H12/A0/B20/C16/D0/S18 (3.6%) 5. H0/A0/B2/C32/D0/S32 (3.1%) | R11: 6. H6/A0/B9/C29/D0/S22 (2.5%) 7. H14/A0/B12/C21/D0/S19 (2.2%) 8. H0/A32/B2/C0/D0/S32 (1.6%) 9. H0/A0/B0/C32/D2/S32 (1.4%) 10. H12/A0/B20/C14/D0/S20 (1.3%) | S11: 1. ガブリアス 2. ミミッキュ 3. アシレーヌ 4. メタグロス 5. ブリジュラス | T11: 6. カバルドン 7. マスカーニャ 8. サザンドラ 9. ゲッコウガ 10. アーマーガア
A12: 11 | B12: マフォクシー | C12: Delphox | D12: 1. かえんほうしゃ (84.8%) 2. マジカルシャイン (63.4%) 3. サイコキネシス (56.5%) 4. みがわり (44.3%) 5. サイコショック (39.9%) 6. わるだくみ (37.8%) 7. アンコール (17.5%) 8. マジカルフレイム (10%) 9. くさむすび (9.3%) 10. シャドーボール (8.8%) | E12: 1. マフォクシナイト (99.2%) 2. こだわりスカーフ (0.3%) 3. きあいのタスキ (0.1%) 4. いのちのたま (0%) 5. バシャーモナイト (0%) 6. ひかりのねんど (0%) 7. まがったスプーン (0%) 8. ライチュウナイトＹ (0%) 9. ムクホークナイト (0%) 10. ルカリオナイト (0%) | F12: 1. もうか (91.5%) 2. マジシャン (8.5%) | G12: 1. おくびょう +S -A (80.1%) 2. ひかえめ +C -A (18.9%) 3. ずぶとい +B -A (0.3%) 4. おっとり +C -B (0.3%) 5. せっかち +S -B (0.2%) 6. おだやか +D -A (0.1%) 7. おとなしい +D -B (0%) 8. れいせい +C -S (0%) 9. きまぐれ (0%) 10. むじゃき +S -D (0%) | H12: 1. ガブリアス 2. ミミッキュ 3. マスカーニャ 4. ブリジュラス 5. アシレーヌ 6. ギャラドス 7. カバルドン 8. メタグロス 9. キュウコン（アローラのすがた） 10. ハッサム | I12: 1. H2/A0/B0/C32/D0/S32 (20.5%) 2. H1/A0/B1/C32/D0/S32 (10.1%) 3. H5/A0/B0/C32/D0/S29 (9%) 4. H1/A0/B4/C32/D0/S29 (7.5%) 5. H1/A0/B0/C32/D1/S32 (3.5%) 6. H0/A0/B2/C32/D0/S32 (3.2%) 7. H9/A0/B8/C19/D0/S30 (2.6%) 8. H9/A0/B1/C27/D0/S29 (1.8%) 9. H25/A0/B0/C12/D0/S29 (1.7%) 10. H0/A0/B0/C32/D2/S32 (1.7%) | J12: 今回は大きな変化なし | K12: 1. かえんほうしゃ (84.8%) 2. マジカルシャイン (63.4%) 3. サイコキネシス (56.5%) 4. みがわり (44.3%) 5. サイコショック (39.9%) | L12: 6. わるだくみ (37.8%) 7. アンコール (17.5%) 8. マジカルフレイム (10%) 9. くさむすび (9.3%) 10. シャドーボール (8.8%) | M12: 1. マフォクシナイト (99.2%) 2. こだわりスカーフ (0.3%) 3. きあいのタスキ (0.1%) 4. いのちのたま (0%) 5. バシャーモナイト (0%) | N12: 6. ひかりのねんど (0%) 7. まがったスプーン (0%) 8. ライチュウナイトＹ (0%) 9. ムクホークナイト (0%) 10. ルカリオナイト (0%) | O12: 1. おくびょう +S -A (80.1%) 2. ひかえめ +C -A (18.9%) 3. ずぶとい +B -A (0.3%) 4. おっとり +C -B (0.3%) 5. せっかち +S -B (0.2%) | P12: 6. おだやか +D -A (0.1%) 7. おとなしい +D -B (0%) 8. れいせい +C -S (0%) 9. きまぐれ (0%) 10. むじゃき +S -D (0%) | Q12: 1. H2/A0/B0/C32/D0/S32 (20.5%) 2. H1/A0/B1/C32/D0/S32 (10.1%) 3. H5/A0/B0/C32/D0/S29 (9%) 4. H1/A0/B4/C32/D0/S29 (7.5%) 5. H1/A0/B0/C32/D1/S32 (3.5%) | R12: 6. H0/A0/B2/C32/D0/S32 (3.2%) 7. H9/A0/B8/C19/D0/S30 (2.6%) 8. H9/A0/B1/C27/D0/S29 (1.8%) 9. H25/A0/B0/C12/D0/S29 (1.7%) 10. H0/A0/B0/C32/D2/S32 (1.7%) | S12: 1. ガブリアス 2. ミミッキュ 3. マスカーニャ 4. ブリジュラス 5. アシレーヌ | T12: 6. ギャラドス 7. カバルドン 8. メタグロス 9. キュウコン（アローラのすがた） 10. ハッサム
A13: 12 | B13: ゲッコウガ | C13: Greninja | D13: 1. あくのはどう (86.9%) 2. れいとうビーム (84.4%) 3. みずしゅりけん (68.3%) 4. ヘドロウェーブ (68.3%) 5. なみのり (46.8%) 6. くさむすび (7.9%) 7. ハイドロポンプ (6.6%) 8. マッドショット (4.6%) 9. どくびし (4.5%) 10. とんぼがえり (2.4%) | E13: 1. ゲッコウガナイト (46.9%) 2. きあいのタスキ (44.3%) 3. いのちのたま (4.1%) 4. こだわりスカーフ (3.5%) 5. たつじんのおび (0.6%) 6. でんきだま (0.2%) 7. しんぴのしずく (0.1%) 8. おうじゃのしるし (0.1%) 9. きあいのハチマキ (0%) 10. ひかりのこな (0%) | F13: 1. へんげんじざい (67.7%) 2. げきりゅう (32.3%) | G13: 1. おくびょう +S -A (52%) 2. ひかえめ +C -A (42.8%) 3. むじゃき +S -D (2.5%) 4. うっかりや +C -D (0.8%) 5. せっかち +S -B (0.7%) 6. おっとり +C -B (0.5%) 7. ようき +S -C (0.3%) 8. やんちゃ +A -D (0.2%) 9. いじっぱり +A -C (0.1%) 10. なまいき +D -S (0%) | H13: 1. ミミッキュ 2. ガブリアス 3. ブリジュラス 4. カバルドン 5. メタグロス 6. バシャーモ 7. マスカーニャ 8. リザードン 9. カイリュー 10. クチート | I13: 1. H2/A0/B0/C32/D0/S32 (59%) 2. H0/A0/B2/C32/D0/S32 (8.4%) 3. H6/A0/B1/C32/D0/S27 (4.3%) 4. H0/A0/B1/C32/D1/S32 (2.8%) 5. H0/A0/B0/C32/D2/S32 (2.7%) 6. H2/A0/B1/C32/D0/S31 (2.4%) 7. H8/A0/B0/C32/D0/S26 (2.1%) 8. H6/A0/B0/C32/D0/S28 (1.5%) 9. H16/A0/B0/C28/D1/S21 (1.5%) 10. H0/A2/B0/C32/D0/S32 (1.4%) | J13: 今回は大きな変化なし | K13: 1. あくのはどう (86.9%) 2. れいとうビーム (84.4%) 3. みずしゅりけん (68.3%) 4. ヘドロウェーブ (68.3%) 5. なみのり (46.8%) | L13: 6. くさむすび (7.9%) 7. ハイドロポンプ (6.6%) 8. マッドショット (4.6%) 9. どくびし (4.5%) 10. とんぼがえり (2.4%) | M13: 1. ゲッコウガナイト (46.9%) 2. きあいのタスキ (44.3%) 3. いのちのたま (4.1%) 4. こだわりスカーフ (3.5%) 5. たつじんのおび (0.6%) | N13: 6. でんきだま (0.2%) 7. しんぴのしずく (0.1%) 8. おうじゃのしるし (0.1%) 9. きあいのハチマキ (0%) 10. ひかりのこな (0%) | O13: 1. おくびょう +S -A (52%) 2. ひかえめ +C -A (42.8%) 3. むじゃき +S -D (2.5%) 4. うっかりや +C -D (0.8%) 5. せっかち +S -B (0.7%) | P13: 6. おっとり +C -B (0.5%) 7. ようき +S -C (0.3%) 8. やんちゃ +A -D (0.2%) 9. いじっぱり +A -C (0.1%) 10. なまいき +D -S (0%) | Q13: 1. H2/A0/B0/C32/D0/S32 (59%) 2. H0/A0/B2/C32/D0/S32 (8.4%) 3. H6/A0/B1/C32/D0/S27 (4.3%) 4. H0/A0/B1/C32/D1/S32 (2.8%) 5. H0/A0/B0/C32/D2/S32 (2.7%) | R13: 6. H2/A0/B1/C32/D0/S31 (2.4%) 7. H8/A0/B0/C32/D0/S26 (2.1%) 8. H6/A0/B0/C32/D0/S28 (1.5%) 9. H16/A0/B0/C28/D1/S21 (1.5%) 10. H0/A2/B0/C32/D0/S32 (1.4%) | S13: 1. ミミッキュ 2. ガブリアス 3. ブリジュラス 4. カバルドン 5. メタグロス | T13: 6. バシャーモ 7. マスカーニャ 8. リザードン 9. カイリュー 10. クチート
... A62: 61 | B62: ミロカロス | C62: Milotic | D62: 1. じこさいせい (96.9%) 2. ねっとう (96.6%) 3. ミラーコート (67.5%) 4. れいとうビーム (64.5%) 5. くろいきり (36.9%) 6. みわくのボイス (4.8%) 7. とぐろをまく (4.5%) 8. さいみんじゅつ (4.1%) 9. こごえるかぜ (3.4%) 10. クイックターン (2.9%) | E62: 1. たべのこし (65.8%) 2. オボンのみ (18.2%) 3. ラムのみ (3%) 4. ソクノのみ (2.6%) 5. きあいのタスキ (1.4%) 6. たつじんのおび (1.1%) 7. かいがらのすず (1%) 8. ひかりのこな (1%) 9. リンドのみ (0.9%) 10. しんぴのしずく (0.8%) | F62: 1. かちき (71.4%) 2. ふしぎなうろこ (19.2%) 3. メロメロボディ (9.4%) | G62: 1. ずぶとい +B -A (62.8%) 2. おだやか +D -A (26.7%) 3. ひかえめ +C -A (6.8%) 4. のんき +B -S (1.8%) 5. なまいき +D -S (0.8%) 6. れいせい +C -S (0.4%) 7. ようき +S -C (0.3%) 8. おっとり +C -B (0.1%) 9. わんぱく +B -C (0.1%) 10. しんちょう +D -C (0.1%) | H62: 1. ガブリアス 2. ミミッキュ 3. メタグロス 4. サザンドラ 5. マスカーニャ 6. ゲンガー 7. クチート 8. バシャーモ 9. マフォクシー 10. リザードン | I62: 1. H32/A0/B32/C0/D2/S0 (25.5%) 2. H32/A0/B32/C1/D1/S0 (6.2%) 3. H31/A0/B32/C0/D3/S0 (5.5%) 4. H32/A0/B32/C2/D0/S0 (5.5%) 5. H32/A0/B0/C2/D32/S0 (4.8%) 6. H32/A0/B2/C0/D32/S0 (3.6%) 7. H32/A0/B32/C0/D0/S2 (3.1%) 8. H2/A0/B32/C0/D32/S0 (2.9%) 9. H32/A0/B15/C19/D0/S0 (1.9%) 10. H32/A0/B2/C32/D0/S0 (1.7%) | J62: 今回は大きな変化なし | K62: 1. じこさいせい (96.9%) 2. ねっとう (96.6%) 3. ミラーコート (67.5%) 4. れいとうビーム (64.5%) 5. くろいきり (36.9%) | L62: 6. みわくのボイス (4.8%) 7. とぐろをまく (4.5%) 8. さいみんじゅつ (4.1%) 9. こごえるかぜ (3.4%) 10. クイックターン (2.9%) | M62: 1. たべのこし (65.8%) 2. オボンのみ (18.2%) 3. ラムのみ (3%) 4. ソクノのみ (2.6%) 5. きあいのタスキ (1.4%) | N62: 6. たつじんのおび (1.1%) 7. かいがらのすず (1%) 8. ひかりのこな (1%) 9. リンドのみ (0.9%) 10. しんぴのしずく (0.8%) | O62: 1. ずぶとい +B -A (62.8%) 2. おだやか +D -A (26.7%) 3. ひかえめ +C -A (6.8%) 4. のんき +B -S (1.8%) 5. なまいき +D -S (0.8%) | P62: 6. れいせい +C -S (0.4%) 7. ようき +S -C (0.3%) 8. おっとり +C -B (0.1%) 9. わんぱく +B -C (0.1%) 10. しんちょう +D -C (0.1%) | Q62: 1. H32/A0/B32/C0/D2/S0 (25.5%) 2. H32/A0/B32/C1/D1/S0 (6.2%) 3. H31/A0/B32/C0/D3/S0 (5.5%) 4. H32/A0/B32/C2/D0/S0 (5.5%) 5. H32/A0/B0/C2/D32/S0 (4.8%) | R62: 6. H32/A0/B2/C0/D32/S0 (3.6%) 7. H32/A0/B32/C0/D0/S2 (3.1%) 8. H2/A0/B32/C0/D32/S0 (2.9%) 9. H32/A0/B15/C19/D0/S0 (1.9%) 10. H32/A0/B2/C32/D0/S0 (1.7%) | S62: 1. ガブリアス 2. ミミッキュ 3. メタグロス 4. サザンドラ 5. マスカーニャ | T62: 6. ゲンガー 7. クチート 8. バシャーモ 9. マフォクシー 10. リザードン
A63: 62 | B63: メタモン | C63: Ditto | D63: 1. へんしん (100%) | E63: 1. こだわりスカーフ (79.5%) 2. せんせいのツメ (8.7%) 3. きあいのタスキ (8%) 4. ひかりのこな (1.5%) 5. いのちのたま (0.8%) 6. オボンのみ (0.7%) 7. たべのこし (0.4%) 8. きあいのハチマキ (0.1%) 9. たつじんのおび (0.1%) 10. ラムのみ (0%) | F63: 1. かわりもの (99.6%) 2. じゅうなん (0.4%) | G63: 1. のんき +B -S (27.1%) 2. おくびょう +S -A (9.3%) 3. なまいき +D -S (7.7%) 4. まじめ (7.4%) 5. むじゃき +S -D (6.6%) 6. ゆうかん +A -S (5.8%) 7. ようき +S -C (4.8%) 8. れいせい +C -S (4.2%) 9. せっかち +S -B (3.2%) 10. おだやか +D -A (3%) | H63: 1. ガブリアス 2. ミミッキュ 3. ブリジュラス 4. メタグロス 5. アシレーヌ 6. リザードン 7. カイリュー 8. ライチュウ 9. ブラッキー 10. ギャラドス | I63: 1. H32/A0/B0/C0/D0/S0 (20.4%) 2. H32/A0/B32/C0/D2/S0 (12.4%) 3. H32/A0/B2/C0/D32/S0 (8.1%) 4. H32/A2/B32/C0/D0/S0 (7.7%) 5. H32/A0/B2/C0/D0/S32 (7.3%) 6. H32/A0/B0/C0/D0/S32 (5.2%) 7. H32/A2/B0/C0/D0/S32 (4.4%) 8. H32/A0/B0/C0/D2/S32 (3.1%) 9. H32/A0/B32/C0/D0/S0 (2.6%) 10. H32/A0/B0/C2/D0/S32 (2.5%) | J63: 今回は大きな変化なし | K63: 1. へんしん (100%) | M63: 1. こだわりスカーフ (79.5%) 2. せんせいのツメ (8.7%) 3. きあいのタスキ (8%) 4. ひかりのこな (1.5%) 5. いのちのたま (0.8%) | N63: 6. オボンのみ (0.7%) 7. たべのこし (0.4%) 8. きあいのハチマキ (0.1%) 9. たつじんのおび (0.1%) 10. ラムのみ (0%) | O63: 1. のんき +B -S (27.1%) 2. おくびょう +S -A (9.3%) 3. なまいき +D -S (7.7%) 4. まじめ (7.4%) 5. むじゃき +S -D (6.6%) | P63: 6. ゆうかん +A -S (5.8%) 7. ようき +S -C (4.8%) 8. れいせい +C -S (4.2%) 9. せっかち +S -B (3.2%) 10. おだやか +D -A (3%) | Q63: 1. H32/A0/B0/C0/D0/S0 (20.4%) 2. H32/A0/B32/C0/D2/S0 (12.4%) 3. H32/A0/B2/C0/D32/S0 (8.1%) 4. H32/A2/B32/C0/D0/S0 (7.7%) 5. H32/A0/B2/C0/D0/S32 (7.3%) | R63: 6. H32/A0/B0/C0/D0/S32 (5.2%) 7. H32/A2/B0/C0/D0/S32 (4.4%) 8. H32/A0/B0/C0/D2/S32 (3.1%) 9. H32/A0/B32/C0/D0/S0 (2.6%) 10. H32/A0/B0/C2/D0/S32 (2.5%) | S63: 1. ガブリアス 2. ミミッキュ 3. ブリジュラス 4. メタグロス 5. アシレーヌ | T63: 6. リザードン 7. カイリュー 8. ライチュウ 9. ブラッキー 10. ギャラドス
A64: 63 | B64: マリルリ | C64: Azumarill | D64: 1. じゃれつく (93.4%) 2. アクアジェット (93.2%) 3. アクアブレイク (62.3%) 4. はらだいこ (55.5%) 5. ばかぢから (29.8%) 6. はたきおとす (15.5%) 7. かわらわり (11.6%) 8. ほろびのうた (5.9%) 9. アイススピナー (5.5%) 10. アンコール (5%) | E64: 1. オボンのみ (70.2%) 2. いのちのたま (8.1%) 3. ラムのみ (7%) 4. しんぴのしずく (3.6%) 5. たべのこし (3.4%) 6. ソクノのみ (2.4%) 7. たつじんのおび (1.8%) 8. カゴのみ (1.2%) 9. きあいのタスキ (0.9%) 10. せんせいのツメ (0.4%) | F64: 1. ちからもち (94.2%) 2. そうしょく (5.7%) 3. あついしぼう (0.2%) | G64: 1. いじっぱり +A -C (91.1%) 2. ゆうかん +A -S (1.7%) 3. ずぶとい +B -A (1.7%) 4. なまいき +D -S (1.4%) 5. わんぱく +B -C (0.8%) 6. ようき +S -C (0.7%) 7. のんき +B -S (0.7%) 8. しんちょう +D -C (0.6%) 9. れいせい +C -S (0.6%) 10. おだやか +D -A (0.5%) | H64: 1. ガブリアス 2. リザードン 3. ライチュウ 4. サザンドラ 5. メタグロス 6. ゲンガー 7. マスカーニャ 8. ミミッキュ 9. マフォクシー 10. ブリジュラス | I64: 1. H32/A32/B0/C0/D0/S2 (15.7%) 2. H31/A32/B0/C0/D0/S3 (12.2%) 3. H31/A32/B3/C0/D0/S0 (6.4%) 4. H32/A32/B2/C0/D0/S0 (5.3%) 5. H32/A32/B0/C0/D2/S0 (4.1%) 6. H32/A32/B1/C0/D1/S0 (3.3%) 7. H29/A32/B3/C0/D2/S0 (2.8%) 8. H15/A32/B0/C0/D0/S19 (2.3%) 9. H31/A32/B0/C0/D3/S0 (2.1%) 10. H32/A0/B32/C0/D2/S0 (2%) | J64: 今回は大きな変化なし | K64: 1. じゃれつく (93.4%) 2. アクアジェット (93.2%) 3. アクアブレイク (62.3%) 4. はらだいこ (55.5%) 5. ばかぢから (29.8%) | L64: 6. はたきおとす (15.5%) 7. かわらわり (11.6%) 8. ほろびのうた (5.9%) 9. アイススピナー (5.5%) 10. アンコール (5%) | M64: 1. オボンのみ (70.2%) 2. いのちのたま (8.1%) 3. ラムのみ (7%) 4. しんぴのしずく (3.6%) 5. たべのこし (3.4%) | N64: 6. ソクノのみ (2.4%) 7. たつじんのおび (1.8%) 8. カゴのみ (1.2%) 9. きあいのタスキ (0.9%) 10. せんせいのツメ (0.4%) | O64: 1. いじっぱり +A -C (91.1%) 2. ゆうかん +A -S (1.7%) 3. ずぶとい +B -A (1.7%) 4. なまいき +D -S (1.4%) 5. わんぱく +B -C (0.8%) | P64: 6. ようき +S -C (0.7%) 7. のんき +B -S (0.7%) 8. しんちょう +D -C (0.6%) 9. れいせい +C -S (0.6%) 10. おだやか +D -A (0.5%) | Q64: 1. H32/A32/B0/C0/D0/S2 (15.7%) 2. H31/A32/B0/C0/D0/S3 (12.2%) 3. H31/A32/B3/C0/D0/S0 (6.4%) 4. H32/A32/B2/C0/D0/S0 (5.3%) 5. H32/A32/B0/C0/D2/S0 (4.1%) | R64: 6. H32/A32/B1/C0/D1/S0 (3.3%) 7. H29/A32/B3/C0/D2/S0 (2.8%) 8. H15/A32/B0/C0/D0/S19 (2.3%) 9. H31/A32/B0/C0/D3/S0 (2.1%) 10. H32/A0/B32/C0/D2/S0 (2%) | S64: 1. ガブリアス 2. リザードン 3. ライチュウ 4. サザンドラ 5. メタグロス | T64: 6. ゲンガー 7. マスカーニャ 8. ミミッキュ 9. マフォクシー 10. ブリジュラス
A65: 64 | B65: ジュカイン | C65: Sceptile | D65: 1. りゅうのはどう (88.9%) 2. だいちのちから (83.1%) 3. リーフストーム (77.9%) 4. しっぽきり (56.2%) 5. エナジーボール (18.6%) 6. みがわり (17.9%) 7. しんくうは (17.3%) 8. きあいだま (12.4%) 9. がむしゃら (5.9%) 10. ギガドレイン (3.3%) | E65: 1. ジュカインナイト (84.4%) 2. きあいのタスキ (5.8%) 3. オボンのみ (4.2%) 4. しろいハーブ (1.4%) 5. こだわりスカーフ (1.3%) 6. たべのこし (0.4%) 7. オレンのみ (0.3%) 8. でんきだま (0.1%) 9. ひかりのこな (0.1%) 10. いのちのたま (0.1%) | F65: 1. しんりょく (83.8%) 2. かるわざ (16.2%) | G65: 1. おくびょう +S -A (84.6%) 2. ひかえめ +C -A (10%) 3. ずぶとい +B -A (1.3%) 4. むじゃき +S -D (1.1%) 5. いじっぱり +A -C (0.8%) 6. せっかち +S -B (0.4%) 7. さみしがり +A -B (0.4%) 8. おっとり +C -B (0.3%) 9. ようき +S -C (0.3%) 10. のんき +B -S (0.3%) | H65: 1. ガブリアス 2. カバルドン 3. ミミッキュ 4. アシレーヌ 5. バシャーモ 6. ブリジュラス 7. ギャラドス 8. ソウブレイズ 9. ゲッコウガ 10. ラウドボーン | I65: 1. H2/A0/B0/C32/D0/S32 (70.3%) 2. H0/A0/B2/C32/D0/S32 (8.1%) 3. H0/A0/B0/C32/D2/S32 (3.7%) 4. H4/A0/B0/C32/D0/S30 (1.5%) 5. H1/A0/B1/C32/D0/S32 (1.4%) 6. H1/A0/B2/C31/D0/S32 (1.2%) 7. H3/A0/B0/C32/D0/S31 (1%) 8. H0/A2/B0/C32/D0/S32 (1%) 9. H2/A0/B1/C32/D0/S31 (0.9%) 10. H19/A0/B0/C32/D0/S15 (0.9%) | J65: 今回は大きな変化なし | K65: 1. りゅうのはどう (88.9%) 2. だいちのちから (83.1%) 3. リーフストーム (77.9%) 4. しっぽきり (56.2%) 5. エナジーボール (18.6%) | L65: 6. みがわり (17.9%) 7. しんくうは (17.3%) 8. きあいだま (12.4%) 9. がむしゃら (5.9%) 10. ギガドレイン (3.3%) | M65: 1. ジュカインナイト (84.4%) 2. きあいのタスキ (5.8%) 3. オボンのみ (4.2%) 4. しろいハーブ (1.4%) 5. こだわりスカーフ (1.3%) | N65: 6. たべのこし (0.4%) 7. オレンのみ (0.3%) 8. でんきだま (0.1%) 9. ひかりのこな (0.1%) 10. いのちのたま (0.1%) | O65: 1. おくびょう +S -A (84.6%) 2. ひかえめ +C -A (10%) 3. ずぶとい +B -A (1.3%) 4. むじゃき +S -D (1.1%) 5. いじっぱり +A -C (0.8%) | P65: 6. せっかち +S -B (0.4%) 7. さみしがり +A -B (0.4%) 8. おっとり +C -B (0.3%) 9. ようき +S -C (0.3%) 10. のんき +B -S (0.3%) | Q65: 1. H2/A0/B0/C32/D0/S32 (70.3%) 2. H0/A0/B2/C32/D0/S32 (8.1%) 3. H0/A0/B0/C32/D2/S32 (3.7%) 4. H4/A0/B0/C32/D0/S30 (1.5%) 5. H1/A0/B1/C32/D0/S32 (1.4%) | R65: 6. H1/A0/B2/C31/D0/S32 (1.2%) 7. H3/A0/B0/C32/D0/S31 (1%) 8. H0/A2/B0/C32/D0/S32 (1%) 9. H2/A0/B1/C32/D0/S31 (0.9%) 10. H19/A0/B0/C32/D0/S15 (0.9%) | S65: 1. ガブリアス 2. カバルドン 3. ミミッキュ 4. アシレーヌ 5. バシャーモ | T65: 6. ブリジュラス 7. ギャラドス 8. ソウブレイズ 9. ゲッコウガ 10. ラウドボーン
A66: 65 | B66: ヒスイゾロアーク | C66: Zoroark-Hisui | D66: 1. うらみつらみ (61.8%) 2. こごえるかぜ (57.1%) 3. かえんほうしゃ (35.5%) 4. シャドーボール (34.2%) 5. きあいだま (33.5%) 6. ちょうはつ (23.3%) 7. かげうち (22.7%) 8. はかいこうせん (14.6%) 9. ハイパーボイス (13.4%) 10. おきみやげ (12.9%) | E66: 1. きあいのタスキ (69.5%) 2. こだわりスカーフ (13.2%) 3. いのちのたま (6.6%) 4. たつじんのおび (2.8%) 5. ものしりメガネ (1.8%) 6. ひかりのこな (1%) 7. ナモのみ (0.9%) 8. オボンのみ (0.6%) 9. のろいのおふだ (0.6%) 10. ラムのみ (0.6%) | F66: 1. イリュージョン (100%) | G66: 1. おくびょう +S -A (58.3%) 2. ひかえめ +C -A (22.4%) 3. むじゃき +S -D (11%) 4. せっかち +S -B (4.2%) 5. うっかりや +C -D (1.3%) 6. のんき +B -S (0.7%) 7. ようき +S -C (0.5%) 8. おっとり +C -B (0.4%) 9. なまいき +D -S (0.4%) 10. れいせい +C -S (0.4%) | H66: 1. ガブリアス 2. ブリジュラス 3. マスカーニャ 4. メタグロス 5. ミミッキュ 6. バシャーモ 7. ギャラドス 8. スターミー 9. ムクホーク 10. ライチュウ | I66: 1. H2/A0/B0/C32/D0/S32 (46.2%) 2. H1/A0/B1/C32/D0/S32 (13.5%) 3. H0/A2/B0/C32/D0/S32 (10.6%) 4. H0/A0/B2/C32/D0/S32 (4.3%) 5. H0/A0/B0/C32/D0/S32 (4.1%) 6. H1/A0/B0/C32/D1/S32 (3.4%) 7. H0/A0/B0/C32/D2/S32 (2%) 8. H1/A0/B0/C32/D0/S32 (1.8%) 9. H1/A1/B0/C32/D0/S32 (1.5%) 10. H0/A0/B1/C32/D1/S32 (0.8%) | J66: 今回は大きな変化なし | K66: 1. うらみつらみ (61.8%) 2. こごえるかぜ (57.1%) 3. かえんほうしゃ (35.5%) 4. シャドーボール (34.2%) 5. きあいだま (33.5%) | L66: 6. ちょうはつ (23.3%) 7. かげうち (22.7%) 8. はかいこうせん (14.6%) 9. ハイパーボイス (13.4%) 10. おきみやげ (12.9%) | M66: 1. きあいのタスキ (69.5%) 2. こだわりスカーフ (13.2%) 3. いのちのたま (6.6%) 4. たつじんのおび (2.8%) 5. ものしりメガネ (1.8%) | N66: 6. ひかりのこな (1%) 7. ナモのみ (0.9%) 8. オボンのみ (0.6%) 9. のろいのおふだ (0.6%) 10. ラムのみ (0.6%) | O66: 1. おくびょう +S -A (58.3%) 2. ひかえめ +C -A (22.4%) 3. むじゃき +S -D (11%) 4. せっかち +S -B (4.2%) 5. うっかりや +C -D (1.3%) | P66: 6. のんき +B -S (0.7%) 7. ようき +S -C (0.5%) 8. おっとり +C -B (0.4%) 9. なまいき +D -S (0.4%) 10. れいせい +C -S (0.4%) | Q66: 1. H2/A0/B0/C32/D0/S32 (46.2%) 2. H1/A0/B1/C32/D0/S32 (13.5%) 3. H0/A2/B0/C32/D0/S32 (10.6%) 4. H0/A0/B2/C32/D0/S32 (4.3%) 5. H0/A0/B0/C32/D0/S32 (4.1%) | R66: 6. H1/A0/B0/C32/D1/S32 (3.4%) 7. H0/A0/B0/C32/D2/S32 (2%) 8. H1/A0/B0/C32/D0/S32 (1.8%) 9. H1/A1/B0/C32/D0/S32 (1.5%) 10. H0/A0/B1/C32/D1/S32 (0.8%) | S66: 1. ガブリアス 2. ブリジュラス 3. マスカーニャ 4. メタグロス 5. ミミッキュ | T66: 6. バシャーモ 7. ギャラドス 8. スターミー 9. ムクホーク 10. ライチュウ
A67: 66 | B67: エルレイド | C67: Gallade | D67: 1. せいなるつるぎ (95.4%) 2. サイコカッター (83.1%) 3. リーフブレード (73.8%) 4. かげうち (54.6%) 5. つじぎり (13.8%) 6. トリプルアクセル (12.1%) 7. シャドークロー (11.7%) 8. みちづれ (6%) 9. アクアカッター (5.9%) 10. れいとうパンチ (5%) | E67: 1. きあいのタスキ (41.8%) 2. こだわりスカーフ (18.2%) 3. ピントレンズ (13.1%) 4. ラムのみ (9%) 5. エルレイドナイト (7.6%) 6. いのちのたま (4.6%) 7. たつじんのおび (2%) 8. オボンのみ (1%) 9. ちからのハチマキ (0.9%) 10. せんせいのツメ (0.5%) | F67: 1. きれあじ (96.6%) 2. せいぎのこころ (2.9%) 3. ふくつのこころ (0.5%) | G67: 1. いじっぱり +A -C (63.2%) 2. ようき +S -C (34.1%) 3. しんちょう +D -C (1%) 4. なまいき +D -S (0.8%) 5. ゆうかん +A -S (0.6%) 6. わんぱく +B -C (0.2%) 7. さみしがり +A -B (0%) 8. のんき +B -S (0%) | H67: 1. ガブリアス 2. マスカーニャ 3. ミミッキュ 4. アシレーヌ 5. リザードン 6. ブリジュラス 7. ゲッコウガ 8. マフォクシー 9. ギャラドス 10. バシャーモ | I67: 1. H2/A32/B0/C0/D0/S32 (48.1%) 2. H0/A32/B2/C0/D0/S32 (8.8%) 3. H32/A32/B2/C0/D0/S0 (4.8%) 4. H0/A32/B0/C0/D2/S32 (3.8%) 5. H28/A32/B0/C0/D0/S6 (3.6%) 6. H2/A32/B32/C0/D0/S0 (1.9%) 7. H2/A32/B0/C0/D32/S0 (1.9%) 8. H0/A32/B0/C0/D0/S32 (1.6%) 9. H0/A26/B8/C0/D0/S32 (1%) 10. H18/A32/B16/C0/D0/S0 (1%) | J67: 今回は大きな変化なし | K67: 1. せいなるつるぎ (95.4%) 2. サイコカッター (83.1%) 3. リーフブレード (73.8%) 4. かげうち (54.6%) 5. つじぎり (13.8%) | L67: 6. トリプルアクセル (12.1%) 7. シャドークロー (11.7%) 8. みちづれ (6%) 9. アクアカッター (5.9%) 10. れいとうパンチ (5%) | M67: 1. きあいのタスキ (41.8%) 2. こだわりスカーフ (18.2%) 3. ピントレンズ (13.1%) 4. ラムのみ (9%) 5. エルレイドナイト (7.6%) | N67: 6. いのちのたま (4.6%) 7. たつじんのおび (2%) 8. オボンのみ (1%) 9. ちからのハチマキ (0.9%) 10. せんせいのツメ (0.5%) | O67: 1. いじっぱり +A -C (63.2%) 2. ようき +S -C (34.1%) 3. しんちょう +D -C (1%) 4. なまいき +D -S (0.8%) | P67: 5. ゆうかん +A -S (0.6%) 6. わんぱく +B -C (0.2%) 7. さみしがり +A -B (0%) 8. のんき +B -S (0%) | Q67: 1. H2/A32/B0/C0/D0/S32 (48.1%) 2. H0/A32/B2/C0/D0/S32 (8.8%) 3. H32/A32/B2/C0/D0/S0 (4.8%) 4. H0/A32/B0/C0/D2/S32 (3.8%) 5. H28/A32/B0/C0/D0/S6 (3.6%) | R67: 6. H2/A32/B32/C0/D0/S0 (1.9%) 7. H2/A32/B0/C0/D32/S0 (1.9%) 8. H0/A32/B0/C0/D0/S32 (1.6%) 9. H0/A26/B8/C0/D0/S32 (1%) 10. H18/A32/B16/C0/D0/S0 (1%) | S67: 1. ガブリアス 2. マスカーニャ 3. ミミッキュ 4. アシレーヌ 5. リザードン | T67: 6. ブリジュラス 7. ゲッコウガ 8. マフォクシー 9. ギャラドス 10. バシャーモ
A68: 67 | B68: ヒスイヌメルゴン | C68: Goodra-Hisui | D68: 1. りゅうせいぐん (63.8%) 2. かえんほうしゃ (50.6%) 3. ヘビーボンバー (43.2%) 4. ラスターカノン (38.5%) 5. ドラゴンテール (37.6%) 6. １０まんボルト (27.9%) 7. たてこもる (22.2%) 8. ボディプレス (21.2%) 9. れいとうビーム (15.1%) 10. アシッドボム (13.7%) | E68: 1. たべのこし (64.1%) 2. オボンのみ (11.5%) 3. カゴのみ (5.1%) 4. シュカのみ (4.9%) 5. たつじんのおび (3.5%) 6. りゅうのキバ (2.8%) 7. しろいハーブ (2.3%) 8. いのちのたま (1.7%) 9. きあいのタスキ (1%) 10. ものしりメガネ (0.7%) | F68: 1. ぬめぬめ (48.6%) 2. そうしょく (25.9%) 3. シェルアーマー (25.5%) | G68: 1. なまいき +D -S (37.3%) 2. ひかえめ +C -A (20.7%) 3. おだやか +D -A (14.7%) 4. ずぶとい +B -A (13%) 5. れいせい +C -S (5.7%) 6. わんぱく +B -C (2.9%) 7. のんき +B -S (1.9%) 8. しんちょう +D -C (1.6%) 9. いじっぱり +A -C (1.3%) 10. まじめ (0.5%) | H68: 1. カバルドン 2. メガニウム 3. カメックス 4. ドヒドイデ 5. サーフゴー 6. ガブリアス 7. ギャラドス 8. ラウドボーン 9. マスカーニャ 10. ミミッキュ | I68: 1. H22/A11/B0/C1/D32/S0 (25.7%) 2. H32/A0/B32/C0/D2/S0 (10.4%) 3. H32/A0/B2/C32/D0/S0 (7.1%) 4. H32/A0/B0/C32/D2/S0 (7.1%) 5. H32/A0/B32/C0/D0/S2 (2.9%) 6. H32/A0/B0/C32/D0/S2 (2.7%) 7. H22/A11/B1/C0/D32/S0 (2.3%) 8. H2/A0/B0/C32/D32/S0 (1.9%) 9. H22/A0/B11/C1/D32/S0 (1.7%) 10. H22/A12/B0/C0/D32/S0 (1.6%) | J68: 今回は大きな変化なし | K68: 1. りゅうせいぐん (63.8%) 2. かえんほうしゃ (50.6%) 3. ヘビーボンバー (43.2%) 4. ラスターカノン (38.5%) 5. ドラゴンテール (37.6%) | L68: 6. １０まんボルト (27.9%) 7. たてこもる (22.2%) 8. ボディプレス (21.2%) 9. れいとうビーム (15.1%) 10. アシッドボム (13.7%) | M68: 1. たべのこし (64.1%) 2. オボンのみ (11.5%) 3. カゴのみ (5.1%) 4. シュカのみ (4.9%) 5. たつじんのおび (3.5%) | N68: 6. りゅうのキバ (2.8%) 7. しろいハーブ (2.3%) 8. いのちのたま (1.7%) 9. きあいのタスキ (1%) 10. ものしりメガネ (0.7%) | O68: 1. なまいき +D -S (37.3%) 2. ひかえめ +C -A (20.7%) 3. おだやか +D -A (14.7%) 4. ずぶとい +B -A (13%) 5. れいせい +C -S (5.7%) | P68: 6. わんぱく +B -C (2.9%) 7. のんき +B -S (1.9%) 8. しんちょう +D -C (1.6%) 9. いじっぱり +A -C (1.3%) 10. まじめ (0.5%) | Q68: 1. H22/A11/B0/C1/D32/S0 (25.7%) 2. H32/A0/B32/C0/D2/S0 (10.4%) 3. H32/A0/B2/C32/D0/S0 (7.1%) 4. H32/A0/B0/C32/D2/S0 (7.1%) 5. H32/A0/B32/C0/D0/S2 (2.9%) | R68: 6. H32/A0/B0/C32/D0/S2 (2.7%) 7. H22/A11/B1/C0/D32/S0 (2.3%) 8. H2/A0/B0/C32/D32/S0 (1.9%) 9. H22/A0/B11/C1/D32/S0 (1.7%) 10. H22/A12/B0/C0/D32/S0 (1.6%) | S68: 1. カバルドン 2. メガニウム 3. カメックス 4. ドヒドイデ 5. サーフゴー | T68: 6. ガブリアス 7. ギャラドス 8. ラウドボーン 9. マスカーニャ 10. ミミッキュ
A69: 68 | B69: オニシズクモ | C69: Araquanid | D69: 1. ねばねばネット (89.3%) 2. アクアブレイク (78.3%) 3. ミラーコート (70.6%) 4. きゅうけつ (26.8%) 5. とびかかる (20.4%) 6. なみのり (18.8%) 7. こごえるかぜ (13.9%) 8. がむしゃら (12.4%) 9. れいとうビーム (10.7%) 10. とびつく (9.8%) | E69: 1. オボンのみ (44.7%) 2. しんぴのしずく (14.2%) 3. きあいのタスキ (12%) 4. たべのこし (10.2%) 5. ソクノのみ (5.3%) 6. いのちのたま (3.6%) 7. ラムのみ (2.6%) 8. せんせいのツメ (2.1%) 9. メンタルハーブ (1.2%) 10. カゴのみ (0.8%) | F69: 1. すいほう (99.1%) 2. ちょすい (0.9%) | G69: 1. いじっぱり +A -C (38.5%) 2. ひかえめ +C -A (14.8%) 3. わんぱく +B -C (10.8%) 4. しんちょう +D -C (8%) 5. ようき +S -C (6.7%) 6. のんき +B -S (5.7%) 7. ゆうかん +A -S (4.5%) 8. れいせい +C -S (2.9%) 9. ずぶとい +B -A (2.8%) 10. おだやか +D -A (1.8%) | H69: 1. ガブリアス 2. ミミッキュ 3. ライチュウ 4. メタグロス 5. カバルドン 6. ハッサム 7. マスカーニャ 8. ギャラドス 9. リザードン 10. ブリジュラス | I69: 1. H32/A32/B2/C0/D0/S0 (22.9%) 2. H32/A0/B32/C0/D2/S0 (7%) 3. H16/A18/B0/C0/D0/S32 (4.9%) 4. H32/A0/B2/C32/D0/S0 (4.5%) 5. H32/A32/B0/C0/D2/S0 (3.9%) 6. H32/A0/B0/C32/D2/S0 (3.6%) 7. H28/A0/B0/C32/D0/S6 (3.3%) 8. H28/A32/B0/C0/D0/S6 (2.4%) 9. H32/A2/B32/C0/D0/S0 (2.3%) 10. H32/A0/B28/C0/D6/S0 (2.1%) | J69: 今回は大きな変化なし | K69: 1. ねばねばネット (89.3%) 2. アクアブレイク (78.3%) 3. ミラーコート (70.6%) 4. きゅうけつ (26.8%) 5. とびかかる (20.4%) | L69: 6. なみのり (18.8%) 7. こごえるかぜ (13.9%) 8. がむしゃら (12.4%) 9. れいとうビーム (10.7%) 10. とびつく (9.8%) | M69: 1. オボンのみ (44.7%) 2. しんぴのしずく (14.2%) 3. きあいのタスキ (12%) 4. たべのこし (10.2%) 5. ソクノのみ (5.3%) | N69: 6. いのちのたま (3.6%) 7. ラムのみ (2.6%) 8. せんせいのツメ (2.1%) 9. メンタルハーブ (1.2%) 10. カゴのみ (0.8%) | O69: 1. いじっぱり +A -C (38.5%) 2. ひかえめ +C -A (14.8%) 3. わんぱく +B -C (10.8%) 4. しんちょう +D -C (8%) 5. ようき +S -C (6.7%) | P69: 6. のんき +B -S (5.7%) 7. ゆうかん +A -S (4.5%) 8. れいせい +C -S (2.9%) 9. ずぶとい +B -A (2.8%) 10. おだやか +D -A (1.8%) | Q69: 1. H32/A32/B2/C0/D0/S0 (22.9%) 2. H32/A0/B32/C0/D2/S0 (7%) 3. H16/A18/B0/C0/D0/S32 (4.9%) 4. H32/A0/B2/C32/D0/S0 (4.5%) 5. H32/A32/B0/C0/D2/S0 (3.9%) | R69: 6. H32/A0/B0/C32/D2/S0 (3.6%) 7. H28/A0/B0/C32/D0/S6 (3.3%) 8. H28/A32/B0/C0/D0/S6 (2.4%) 9. H32/A2/B32/C0/D0/S0 (2.3%) 10. H32/A0/B28/C0/D6/S0 (2.1%) | S69: 1. ガブリアス 2. ミミッキュ 3. ライチュウ 4. メタグロス 5. カバルドン | T69: 6. ハッサム 7. マスカーニャ 8. ギャラドス 9. リザードン 10. ブリジュラス
A70: 69 | B70: ビビヨン | C70: Vivillon | D70: 1. ねむりごな (98.3%) 2. ぼうふう (97.5%) 3. ちょうのまい (96.9%) 4. みがわり (91.5%) 5. むしのさざめき (4.9%) 6. おいかぜ (2.1%) 7. いかりのこな (1.7%) 8. まもる (1.5%) 9. かふんだんご (1.5%) 10. ギガドレイン (1.4%) | E70: 1. たべのこし (86.5%) 2. きあいのタスキ (7.5%) 3. こうかくレンズ (1%) 4. ひかりのこな (0.8%) 5. せんせいのツメ (0.8%) 6. ものしりメガネ (0.8%) 7. こだわりスカーフ (0.2%) 8. オボンのみ (0.2%) 9. いのちのたま (0.1%) 10. ラムのみ (0.1%) | F70: 1. ふくがん (97.7%) 2. フレンドガード (2.3%) 3. りんぷん (0%) | G70: 1. おくびょう +S -A (97.6%) 2. ひかえめ +C -A (1.6%) 3. まじめ (0.3%) 4. おだやか +D -A (0.2%) 5. れいせい +C -S (0.2%) 6. ずぶとい +B -A (0.1%) 7. せっかち +S -B (0%) | H70: 1. ミミッキュ 2. ブリジュラス 3. ゲッコウガ 4. クエスパトラ 5. ミミロップ 6. バシャーモ 7. ガブリアス 8. メタグロス 9. ギャラドス 10. イダイトウ | I70: 1. H6/A0/B28/C0/D0/S32 (41%) 2. H2/A0/B0/C32/D0/S32 (21.9%) 3. H6/A0/B0/C28/D0/S32 (12.8%) 4. H0/A0/B2/C32/D0/S32 (3.2%) 5. H32/A0/B0/C2/D0/S32 (2.3%) 6. H32/A0/B1/C0/D1/S32 (1.8%) 7. H0/A0/B0/C32/D0/S32 (1.8%) 8. H32/A0/B0/C0/D2/S32 (1.6%) 9. H18/A0/B0/C16/D0/S32 (1.4%) 10. H32/A0/B2/C0/D0/S32 (1.4%) | J70: 今回は大きな変化なし | K70: 1. ねむりごな (98.3%) 2. ぼうふう (97.5%) 3. ちょうのまい (96.9%) 4. みがわり (91.5%) 5. むしのさざめき (4.9%) | L70: 6. おいかぜ (2.1%) 7. いかりのこな (1.7%) 8. まもる (1.5%) 9. かふんだんご (1.5%) 10. ギガドレイン (1.4%) | M70: 1. たべのこし (86.5%) 2. きあいのタスキ (7.5%) 3. こうかくレンズ (1%) 4. ひかりのこな (0.8%) 5. せんせいのツメ (0.8%) | N70: 6. ものしりメガネ (0.8%) 7. こだわりスカーフ (0.2%) 8. オボンのみ (0.2%) 9. いのちのたま (0.1%) 10. ラムのみ (0.1%) | O70: 1. おくびょう +S -A (97.6%) 2. ひかえめ +C -A (1.6%) 3. まじめ (0.3%) 4. おだやか +D -A (0.2%) | P70: 5. れいせい +C -S (0.2%) 6. ずぶとい +B -A (0.1%) 7. せっかち +S -B (0%) | Q70: 1. H6/A0/B28/C0/D0/S32 (41%) 2. H2/A0/B0/C32/D0/S32 (21.9%) 3. H6/A0/B0/C28/D0/S32 (12.8%) 4. H0/A0/B2/C32/D0/S32 (3.2%) 5. H32/A0/B0/C2/D0/S32 (2.3%) | R70: 6. H32/A0/B1/C0/D1/S32 (1.8%) 7. H0/A0/B0/C32/D0/S32 (1.8%) 8. H32/A0/B0/C0/D2/S32 (1.6%) 9. H18/A0/B0/C16/D0/S32 (1.4%) 10. H32/A0/B2/C0/D0/S32 (1.4%) | S70: 1. ミミッキュ 2. ブリジュラス 3. ゲッコウガ 4. クエスパトラ 5. ミミロップ | T70: 6. バシャーモ 7. ガブリアス 8. メタグロス 9. ギャラドス 10. イダイトウ
A71: 70 | B71: ヤミラミ | C71: Sableye | D71: 1. おにび (71.9%) 2. イカサマ (61.1%) 3. アンコール (59%) 4. じこさいせい (48.2%) 5. ひかりのかべ (38.8%) 6. リフレクター (34.4%) 7. かなしばり (12.2%) 8. めいそう (11.5%) 9. ちょうはつ (9%) 10. メタルバースト (7.3%) | E71: 1. ひかりのねんど (34.4%) 2. ヤミラミナイト (34%) 3. たべのこし (13.7%) 4. きあいのタスキ (5%) 5. ロゼルのみ (3.9%) 6. オボンのみ (2.8%) 7. こうかくレンズ (2.6%) 8. くろいてっきゅう (1%) 9. ひかりのこな (0.7%) 10. しめったいわ (0.2%) | F71: 1. いたずらごころ (99.6%) 2. するどいめ (0.2%) 3. あとだし (0.1%) | G71: 1. ずぶとい +B -A (38.5%) 2. わんぱく +B -C (25.5%) 3. おだやか +D -A (13.7%) 4. しんちょう +D -C (9.3%) 5. のんき +B -S (6.6%) 6. なまいき +D -S (3.2%) 7. いじっぱり +A -C (1.4%) 8. ゆうかん +A -S (0.7%) 9. さみしがり +A -B (0.3%) 10. ひかえめ +C -A (0.2%) | H71: 1. ガブリアス 2. バシャーモ 3. ギャラドス 4. メタグロス 5. ブリジュラス 6. ミミッキュ 7. アシレーヌ 8. ゲッコウガ 9. マスカーニャ 10. ムクホーク | I71: 1. H32/A0/B32/C0/D2/S0 (35.4%) 2. H32/A0/B2/C0/D32/S0 (15.1%) 3. H32/A0/B25/C0/D9/S0 (9.3%) 4. H32/A0/B18/C0/D16/S0 (4.9%) 5. H32/A0/B32/C0/D0/S0 (3.5%) 6. H32/A0/B7/C0/D27/S0 (2.9%) 7. H32/A0/B15/C0/D19/S0 (2.5%) 8. H32/A0/B9/C0/D25/S0 (2.3%) 9. H32/A0/B16/C0/D18/S0 (2%) 10. H32/A0/B32/C0/D0/S2 (2%) | J71: 今回は大きな変化なし | K71: 1. おにび (71.9%) 2. イカサマ (61.1%) 3. アンコール (59%) 4. じこさいせい (48.2%) 5. ひかりのかべ (38.8%) | L71: 6. リフレクター (34.4%) 7. かなしばり (12.2%) 8. めいそう (11.5%) 9. ちょうはつ (9%) 10. メタルバースト (7.3%) | M71: 1. ひかりのねんど (34.4%) 2. ヤミラミナイト (34%) 3. たべのこし (13.7%) 4. きあいのタスキ (5%) 5. ロゼルのみ (3.9%) | N71: 6. オボンのみ (2.8%) 7. こうかくレンズ (2.6%) 8. くろいてっきゅう (1%) 9. ひかりのこな (0.7%) 10. しめったいわ (0.2%) | O71: 1. ずぶとい +B -A (38.5%) 2. わんぱく +B -C (25.5%) 3. おだやか +D -A (13.7%) 4. しんちょう +D -C (9.3%) 5. のんき +B -S (6.6%) | P71: 6. なまいき +D -S (3.2%) 7. いじっぱり +A -C (1.4%) 8. ゆうかん +A -S (0.7%) 9. さみしがり +A -B (0.3%) 10. ひかえめ +C -A (0.2%) | Q71: 1. H32/A0/B32/C0/D2/S0 (35.4%) 2. H32/A0/B2/C0/D32/S0 (15.1%) 3. H32/A0/B25/C0/D9/S0 (9.3%) 4. H32/A0/B18/C0/D16/S0 (4.9%) 5. H32/A0/B32/C0/D0/S0 (3.5%) | R71: 6. H32/A0/B7/C0/D27/S0 (2.9%) 7. H32/A0/B15/C0/D19/S0 (2.5%) 8. H32/A0/B9/C0/D25/S0 (2.3%) 9. H32/A0/B16/C0/D18/S0 (2%) 10. H32/A0/B32/C0/D0/S2 (2%) | S71: 1. ガブリアス 2. バシャーモ 3. ギャラドス 4. メタグロス 5. ブリジュラス | T71: 6. ミミッキュ 7. アシレーヌ 8. ゲッコウガ 9. マスカーニャ 10. ムクホーク
A72: 71 | B72: エアームド | C72: Skarmory | D72: 1. はねやすめ (63.1%) 2. ステルスロック (45.6%) 3. ブレイブバード (36.9%) 4. ふきとばし (36.7%) 5. ボディプレス (36.3%) 6. つるぎのまい (30.8%) 7. ドリルライナー (28.9%) 8. アイアンヘッド (28.9%) 9. てっぺき (27.8%) 10. まきびし (19.4%) | E72: 1. エアームドナイト (35.8%) 2. オボンのみ (28.5%) 3. たべのこし (19.7%) 4. メンタルハーブ (4.3%) 5. ラムのみ (4%) 6. ひかりのこな (2.5%) 7. いのちのたま (1.6%) 8. ソクノのみ (0.8%) 9. メタルコート (0.6%) 10. くろおび (0.5%) | F72: 1. がんじょう (72.1%) 2. くだけるよろい (26.9%) 3. するどいめ (0.9%) | G72: 1. わんぱく +B -C (45.8%) 2. ようき +S -C (22.4%) 3. いじっぱり +A -C (13.3%) 4. しんちょう +D -C (8.5%) 5. ずぶとい +B -A (7.2%) 6. のんき +B -S (1.3%) 7. おだやか +D -A (0.8%) 8. おくびょう +S -A (0.2%) 9. まじめ (0.2%) 10. ゆうかん +A -S (0.2%) | H72: 1. ガブリアス 2. ドラミドロ 3. ブリジュラス 4. マフォクシー 5. ミミッキュ 6. マスカーニャ 7. バシャーモ 8. アシレーヌ 9. ラウドボーン 10. ブラッキー | I72: 1. H32/A0/B32/C0/D2/S0 (21.6%) 2. H32/A0/B32/C0/D0/S2 (8%) 3. H2/A32/B0/C0/D0/S32 (5.3%) 4. H32/A0/B2/C0/D32/S0 (4.8%) 5. H31/A0/B32/C0/D3/S0 (3.3%) 6. H1/A32/B1/C0/D0/S32 (2.6%) 7. H32/A0/B32/C0/D1/S1 (2.2%) 8. H5/A32/B4/C0/D0/S25 (2.2%) 9. H32/A2/B32/C0/D0/S0 (1.9%) 10. H19/A32/B0/C0/D0/S15 (1.9%) | J72: 今回は大きな変化なし | K72: 1. はねやすめ (63.1%) 2. ステルスロック (45.6%) 3. ブレイブバード (36.9%) 4. ふきとばし (36.7%) 5. ボディプレス (36.3%) | L72: 6. つるぎのまい (30.8%) 7. ドリルライナー (28.9%) 8. アイアンヘッド (28.9%) 9. てっぺき (27.8%) 10. まきびし (19.4%) | M72: 1. エアームドナイト (35.8%) 2. オボンのみ (28.5%) 3. たべのこし (19.7%) 4. メンタルハーブ (4.3%) 5. ラムのみ (4%) | N72: 6. ひかりのこな (2.5%) 7. いのちのたま (1.6%) 8. ソクノのみ (0.8%) 9. メタルコート (0.6%) 10. くろおび (0.5%) | O72: 1. わんぱく +B -C (45.8%) 2. ようき +S -C (22.4%) 3. いじっぱり +A -C (13.3%) 4. しんちょう +D -C (8.5%) 5. ずぶとい +B -A (7.2%) | P72: 6. のんき +B -S (1.3%) 7. おだやか +D -A (0.8%) 8. おくびょう +S -A (0.2%) 9. まじめ (0.2%) 10. ゆうかん +A -S (0.2%) | Q72: 1. H32/A0/B32/C0/D2/S0 (21.6%) 2. H32/A0/B32/C0/D0/S2 (8%) 3. H2/A32/B0/C0/D0/S32 (5.3%) 4. H32/A0/B2/C0/D32/S0 (4.8%) 5. H31/A0/B32/C0/D3/S0 (3.3%) | R72: 6. H1/A32/B1/C0/D0/S32 (2.6%) 7. H32/A0/B32/C0/D1/S1 (2.2%) 8. H5/A32/B4/C0/D0/S25 (2.2%) 9. H32/A2/B32/C0/D0/S0 (1.9%) 10. H19/A32/B0/C0/D0/S15 (1.9%) | S72: 1. ガブリアス 2. ドラミドロ 3. ブリジュラス 4. マフォクシー 5. ミミッキュ | T72: 6. マスカーニャ 7. バシャーモ 8. アシレーヌ 9. ラウドボーン 10. ブラッキー
A73: 72 | B73: ジュペッタ | C73: Banette | D73: 1. みちづれ (99.4%) 2. ポルターガイスト (96.2%) 3. かげうち (72.1%) 4. アンコール (67.1%) 5. ちょうはつ (23%) 6. おにび (12.5%) 7. ダストシュート (9.3%) 8. ふいうち (4.5%) 9. つるぎのまい (2.9%) 10. のろい (2.7%) | E73: 1. ジュペッタナイト (99.9%) 2. こだわりスカーフ (0%) | F73: 1. おみとおし (90.1%) 2. ふみん (6.7%) 3. のろわれボディ (3.1%) | G73: 1. いじっぱり +A -C (73.7%) 2. ゆうかん +A -S (20.8%) 3. しんちょう +D -C (1.5%) 4. やんちゃ +A -D (1.4%) 5. ずぶとい +B -A (1.1%) 6. ようき +S -C (1%) 7. わんぱく +B -C (0.5%) 8. なまいき +D -S (0.1%) | H73: 1. ミミッキュ 2. ブリジュラス 3. イダイトウ 4. アシレーヌ 5. ガブリアス 6. マスカーニャ 7. ゲッコウガ 8. ドドゲザン 9. アーマーガア 10. ムクホーク | I73: 1. H32/A32/B2/C0/D0/S0 (32.5%) 2. H32/A32/B0/C0/D2/S0 (12.6%) 3. H32/A32/B0/C0/D0/S2 (10.8%) 4. H30/A25/B0/C0/D4/S7 (5.3%) 5. H32/A32/B1/C0/D1/S0 (3%) 6. H32/A25/B0/C0/D8/S1 (1.6%) 7. H20/A15/B0/C0/D31/S0 (1.5%) 8. H32/A28/B6/C0/D0/S0 (1.5%) 9. H30/A32/B0/C0/D0/S4 (1.4%) 10. H32/A0/B32/C0/D0/S0 (1.3%) | J73: 今回は大きな変化なし | K73: 1. みちづれ (99.4%) 2. ポルターガイスト (96.2%) 3. かげうち (72.1%) 4. アンコール (67.1%) 5. ちょうはつ (23%) | L73: 6. おにび (12.5%) 7. ダストシュート (9.3%) 8. ふいうち (4.5%) 9. つるぎのまい (2.9%) 10. のろい (2.7%) | M73: 1. ジュペッタナイト (99.9%) | N73: 2. こだわりスカーフ (0%) | O73: 1. いじっぱり +A -C (73.7%) 2. ゆうかん +A -S (20.8%) 3. しんちょう +D -C (1.5%) 4. やんちゃ +A -D (1.4%) | P73: 5. ずぶとい +B -A (1.1%) 6. ようき +S -C (1%) 7. わんぱく +B -C (0.5%) 8. なまいき +D -S (0.1%) | Q73: 1. H32/A32/B2/C0/D0/S0 (32.5%) 2. H32/A32/B0/C0/D2/S0 (12.6%) 3. H32/A32/B0/C0/D0/S2 (10.8%) 4. H30/A25/B0/C0/D4/S7 (5.3%) 5. H32/A32/B1/C0/D1/S0 (3%) | R73: 6. H32/A25/B0/C0/D8/S1 (1.6%) 7. H20/A15/B0/C0/D31/S0 (1.5%) 8. H32/A28/B6/C0/D0/S0 (1.5%) 9. H30/A32/B0/C0/D0/S4 (1.4%) 10. H32/A0/B32/C0/D0/S0 (1.3%) | S73: 1. ミミッキュ 2. ブリジュラス 3. イダイトウ 4. アシレーヌ 5. ガブリアス | T73: 6. マスカーニャ 7. ゲッコウガ 8. ドドゲザン 9. アーマーガア 10. ムクホーク
A74: 73 | B74: サーナイト | C74: Gardevoir | D74: 1. しんくうは (69.3%) 2. ハイパーボイス (58.4%) 3. １０まんボルト (43.1%) 4. ムーンフォース (37.3%) 5. サイコキネシス (30.1%) 6. サイコショック (26.2%) 7. マジカルフレイム (23.8%) 8. サイコノイズ (18.4%) 9. めいそう (15.1%) 10. シャドーボール (12.2%) | E74: 1. サーナイトナイト (65.1%) 2. きあいのタスキ (19.1%) 3. こだわりスカーフ (6.9%) 4. いのちのたま (2.2%) 5. こうかくレンズ (1.8%) 6. ものしりメガネ (1.4%) 7. ビアーのみ (0.5%) 8. リリバのみ (0.5%) 9. かいがらのすず (0.5%) 10. オボンのみ (0.5%) | F74: 1. トレース (96.2%) 2. シンクロ (3.3%) 3. テレパシー (0.4%) | G74: 1. ひかえめ +C -A (63.1%) 2. おくびょう +S -A (27.9%) 3. ずぶとい +B -A (3.1%) 4. おだやか +D -A (2.3%) 5. れいせい +C -S (2.2%) 6. おっとり +C -B (1%) 7. のんき +B -S (0.2%) 8. がんばりや (0.1%) 9. わんぱく +B -C (0.1%) | H74: 1. ガブリアス 2. マスカーニャ 3. ミミッキュ 4. ブリジュラス 5. ギャラドス 6. ドドゲザン 7. バシャーモ 8. ゲッコウガ 9. メタグロス 10. ソウブレイズ | I74: 1. H2/A0/B0/C32/D0/S32 (25.2%) 2. H32/A0/B11/C5/D0/S18 (8.7%) 3. H0/A0/B2/C32/D0/S32 (6.8%) 4. H32/A0/B2/C32/D0/S0 (4.6%) 5. H32/A0/B0/C32/D0/S2 (3.5%) 6. H29/A0/B1/C18/D0/S18 (3.3%) 7. H0/A0/B0/C32/D2/S32 (2.8%) 8. H0/A0/B9/C25/D0/S32 (1.9%) 9. H2/A0/B32/C0/D0/S32 (1.8%) 10. H32/A0/B0/C32/D2/S0 (1.8%) | J74: 今回は大きな変化なし | K74: 1. しんくうは (69.3%) 2. ハイパーボイス (58.4%) 3. １０まんボルト (43.1%) 4. ムーンフォース (37.3%) 5. サイコキネシス (30.1%) | L74: 6. サイコショック (26.2%) 7. マジカルフレイム (23.8%) 8. サイコノイズ (18.4%) 9. めいそう (15.1%) 10. シャドーボール (12.2%) | M74: 1. サーナイトナイト (65.1%) 2. きあいのタスキ (19.1%) 3. こだわりスカーフ (6.9%) 4. いのちのたま (2.2%) 5. こうかくレンズ (1.8%) | N74: 6. ものしりメガネ (1.4%) 7. ビアーのみ (0.5%) 8. リリバのみ (0.5%) 9. かいがらのすず (0.5%) 10. オボンのみ (0.5%) | O74: 1. ひかえめ +C -A (63.1%) 2. おくびょう +S -A (27.9%) 3. ずぶとい +B -A (3.1%) 4. おだやか +D -A (2.3%) 5. れいせい +C -S (2.2%) | P74: 6. おっとり +C -B (1%) 7. のんき +B -S (0.2%) 8. がんばりや (0.1%) 9. わんぱく +B -C (0.1%) | Q74: 1. H2/A0/B0/C32/D0/S32 (25.2%) 2. H32/A0/B11/C5/D0/S18 (8.7%) 3. H0/A0/B2/C32/D0/S32 (6.8%) 4. H32/A0/B2/C32/D0/S0 (4.6%) 5. H32/A0/B0/C32/D0/S2 (3.5%) | R74: 6. H29/A0/B1/C18/D0/S18 (3.3%) 7. H0/A0/B0/C32/D2/S32 (2.8%) 8. H0/A0/B9/C25/D0/S32 (1.9%) 9. H2/A0/B32/C0/D0/S32 (1.8%) 10. H32/A0/B0/C32/D2/S0 (1.8%) | S74: 1. ガブリアス 2. マスカーニャ 3. ミミッキュ 4. ブリジュラス 5. ギャラドス | T74: 6. ドドゲザン 7. バシャーモ 8. ゲッコウガ 9. メタグロス 10. ソウブレイズ
A75: 74 | B75: イッカネズミ | C75: Maushold | D75: 1. ネズミざん (95.7%) 2. おかたづけ (91.4%) 3. アンコール (81.4%) 4. かみつく (59.6%) 5. バトンタッチ (22.1%) 6. タネマシンガン (11.6%) 7. マッドショット (7.4%) 8. でんじは (7.4%) 9. ちょうはつ (4.8%) 10. いかりのまえば (4%) | E75: 1. こうかくレンズ (80.2%) 2. オボンのみ (7.6%) 3. おうじゃのしるし (7.6%) 4. きあいのタスキ (1.6%) 5. いのちのたま (0.9%) 6. シルクのスカーフ (0.5%) 7. ピントレンズ (0.4%) 8. せんせいのツメ (0.3%) 9. しろいハーブ (0.3%) 10. かいがらのすず (0.1%) | F75: 1. テクニシャン (91.5%) 2. ほおぶくろ (7.6%) 3. フレンドガード (0.9%) | G75: 1. ようき +S -C (80.3%) 2. いじっぱり +A -C (12.9%) 3. わんぱく +B -C (4%) 4. しんちょう +D -C (0.7%) 5. おくびょう +S -A (0.5%) 6. むじゃき +S -D (0.4%) 7. おだやか +D -A (0.3%) 8. さみしがり +A -B (0.2%) 9. せっかち +S -B (0.2%) 10. ずぶとい +B -A (0.2%) | H75: 1. ガブリアス 2. ミミッキュ 3. リザードン 4. ギャラドス 5. メタグロス 6. ライチュウ 7. マスカーニャ 8. ブリジュラス 9. バシャーモ 10. ゲッコウガ | I75: 1. H2/A32/B0/C0/D0/S32 (56.9%) 2. H0/A32/B2/C0/D0/S32 (6.2%) 3. H10/A19/B0/C0/D10/S27 (6.2%) 4. H0/A32/B0/C0/D2/S32 (6%) 5. H0/A32/B0/C0/D0/S32 (2.3%) 6. H31/A0/B30/C0/D5/S0 (2.2%) 7. H1/A32/B0/C0/D0/S32 (1.5%) 8. H32/A0/B32/C0/D0/S2 (1.3%) 9. H32/A32/B2/C0/D0/S0 (1.3%) 10. H0/A21/B13/C0/D0/S32 (1.1%) | J75: 今回は大きな変化なし | K75: 1. ネズミざん (95.7%) 2. おかたづけ (91.4%) 3. アンコール (81.4%) 4. かみつく (59.6%) 5. バトンタッチ (22.1%) | L75: 6. タネマシンガン (11.6%) 7. マッドショット (7.4%) 8. でんじは (7.4%) 9. ちょうはつ (4.8%) 10. いかりのまえば (4%) | M75: 1. こうかくレンズ (80.2%) 2. オボンのみ (7.6%) 3. おうじゃのしるし (7.6%) 4. きあいのタスキ (1.6%) 5. いのちのたま (0.9%) | N75: 6. シルクのスカーフ (0.5%) 7. ピントレンズ (0.4%) 8. せんせいのツメ (0.3%) 9. しろいハーブ (0.3%) 10. かいがらのすず (0.1%) | O75: 1. ようき +S -C (80.3%) 2. いじっぱり +A -C (12.9%) 3. わんぱく +B -C (4%) 4. しんちょう +D -C (0.7%) 5. おくびょう +S -A (0.5%) | P75: 6. むじゃき +S -D (0.4%) 7. おだやか +D -A (0.3%) 8. さみしがり +A -B (0.2%) 9. せっかち +S -B (0.2%) 10. ずぶとい +B -A (0.2%) | Q75: 1. H2/A32/B0/C0/D0/S32 (56.9%) 2. H0/A32/B2/C0/D0/S32 (6.2%) 3. H10/A19/B0/C0/D10/S27 (6.2%) 4. H0/A32/B0/C0/D2/S32 (6%) 5. H0/A32/B0/C0/D0/S32 (2.3%) | R75: 6. H31/A0/B30/C0/D5/S0 (2.2%) 7. H1/A32/B0/C0/D0/S32 (1.5%) 8. H32/A0/B32/C0/D0/S2 (1.3%) 9. H32/A32/B2/C0/D0/S0 (1.3%) 10. H0/A21/B13/C0/D0/S32 (1.1%) | S75: 1. ガブリアス 2. ミミッキュ 3. リザードン 4. ギャラドス 5. メタグロス | T75: 6. ライチュウ 7. マスカーニャ 8. ブリジュラス 9. バシャーモ 10. ゲッコウガ
... A224: 223 | B224: ポワルン | C224: Castform | D224: 1. ウェザーボール (78.3%) 2. ぼうふう (78.3%) 3. かみなり (65.2%) 4. ふぶき (59.4%) 5. みらいよち (17.4%) 6. ねっとう (17.4%) 7. すなあらし (13%) 8. ドわすれ (11.6%) 9. ガードスワップ (11.6%) 10. りんしょう (11.6%) | E224: 1. こだわりスカーフ (59.4%) 2. ライチュウナイトＹ (11.6%) 3. きあいのタスキ (5.8%) | F224: 1. てんきや (100%) | G224: 1. ひかえめ +C -A (59.4%) 2. おくびょう +S -A (23.2%) 3. まじめ (15.9%) 4. れいせい +C -S (1.4%) | H224: 1. バンギラス 2. バシャーモ 3. メガニウム 4. ムクホーク 5. ドリュウズ 6. ミミッキュ 7. ギャラドス 8. ハラバリー 9. ブリジュラス 10. ラフレシア | I224: 1. H2/A0/B0/C32/D0/S32 (82.6%) 2. H6/A7/B6/C7/D6/S7 (11.6%) 3. H1/A2/B3/C4/D5/S6 (4.3%) 4. H0/A0/B2/C32/D32/S0 (1.4%) | J224: 今回は大きな変化なし | K224: 1. ウェザーボール (78.3%) 2. ぼうふう (78.3%) 3. かみなり (65.2%) 4. ふぶき (59.4%) 5. みらいよち (17.4%) | L224: 6. ねっとう (17.4%) 7. すなあらし (13%) 8. ドわすれ (11.6%) 9. ガードスワップ (11.6%) 10. りんしょう (11.6%) | M224: 1. こだわりスカーフ (59.4%) 2. ライチュウナイトＹ (11.6%) | N224: 3. きあいのタスキ (5.8%) | O224: 1. ひかえめ +C -A (59.4%) 2. おくびょう +S -A (23.2%) | P224: 3. まじめ (15.9%) 4. れいせい +C -S (1.4%) | Q224: 1. H2/A0/B0/C32/D0/S32 (82.6%) 2. H6/A7/B6/C7/D6/S7 (11.6%) | R224: 3. H1/A2/B3/C4/D5/S6 (4.3%) 4. H0/A0/B2/C32/D32/S0 (1.4%) | S224: 1. バンギラス 2. バシャーモ 3. メガニウム 4. ムクホーク 5. ドリュウズ | T224: 6. ミミッキュ 7. ギャラドス 8. ハラバリー 9. ブリジュラス 10. ラフレシア
A225: 224 | B225: ルガルガン(夜) | C225: Lycanroc-Midnight | D225: 1. ストーンエッジ (100%) 2. ふいうち (90.9%) 3. カウンター (90.9%) 4. つるぎのまい (76.4%) 5. インファイト (14.5%) 6. かわらわり (9.1%) 7. はたきおとす (9.1%) 8. ほのおのキバ (9.1%) | E225: 1. きあいのタスキ (100%) | F225: 1. ノーガード (100%) | G225: 1. ようき +S -C (98.2%) 2. いじっぱり +A -C (1.8%) | H225: 1. リザードン 2. キュウコン（アローラのすがた） 3. カビゴン 4. ワルビアル 5. ミミッキュ 6. ギャラドス 7. ブリジュラス 8. フラエッテ（えいえんのはな） 9. マスカーニャ 10. ミロカロス | I225: 1. H2/A32/B0/C0/D0/S32 (89.1%) 2. H0/A32/B0/C0/D2/S32 (9.1%) 3. H0/A32/B2/C0/D0/S32 (1.8%) | J225: 今回は大きな変化なし | K225: 1. ストーンエッジ (100%) 2. ふいうち (90.9%) 3. カウンター (90.9%) 4. つるぎのまい (76.4%) | L225: 5. インファイト (14.5%) 6. かわらわり (9.1%) 7. はたきおとす (9.1%) 8. ほのおのキバ (9.1%) | M225: 1. きあいのタスキ (100%) | O225: 1. ようき +S -C (98.2%) | P225: 2. いじっぱり +A -C (1.8%) | Q225: 1. H2/A32/B0/C0/D0/S32 (89.1%) 2. H0/A32/B0/C0/D2/S32 (9.1%) | R225: 3. H0/A32/B2/C0/D0/S32 (1.8%) | S225: 1. リザードン 2. キュウコン（アローラのすがた） 3. カビゴン 4. ワルビアル 5. ミミッキュ | T225: 6. ギャラドス 7. ブリジュラス 8. フラエッテ（えいえんのはな） 9. マスカーニャ 10. ミロカロス
